[32mINFO    [0m integration.ha_tests.test_upgrade_from_stable:test_upgrade_from_stable.py:99 starting continuous writes to the database
[33mWARNING [0m juju.model:model.py:1564 relate is deprecated and will be removed. Use integrate instead.
[32mINFO    [0m pytest_operator.plugin:plugin.py:862 Model status:

Model  Controller          Cloud/Region        Version  SLA          Timestamp
test   microk8s-localhost  microk8s/localhost  3.4.4    unsupported  02:10:28Z

App                  Version  Status  Scale  Charm                Channel      Rev  Address        Exposed  Message
postgresql-k8s       14.11    active      3  postgresql-k8s       14/stable    281  10.152.183.77  no       
postgresql-test-app           active      1  postgresql-test-app  latest/edge  239  10.152.183.74  no       

Unit                    Workload  Agent  Address     Ports  Message
postgresql-k8s/0*       active    idle   10.1.53.12         Primary
postgresql-k8s/1        active    idle   10.1.53.14         
postgresql-k8s/2        active    idle   10.1.53.13         
postgresql-test-app/0*  active    idle   10.1.53.8          

[32mINFO    [0m pytest_operator.plugin:plugin.py:868 Juju error logs:

controller-0: 01:58:41 ERROR juju.worker.caasapplicationprovisioner.runner exited "postgresql-k8s": more than 20 retries ensuring scale: setting scale to 3 for "postgresql-k8s": statefulset "postgresql-k8s" not found
unit-postgresql-test-app-0: 02:05:24 ERROR unit.postgresql-test-app/0.juju-log Uncaught exception while in charm code:
Traceback (most recent call last):
  File "/var/lib/juju/agents/unit-postgresql-test-app-0/charm/./src/charm.py", line 538, in <module>
    main(ApplicationCharm)
  File "/var/lib/juju/agents/unit-postgresql-test-app-0/charm/venv/ops/main.py", line 553, in main
    manager.run()
  File "/var/lib/juju/agents/unit-postgresql-test-app-0/charm/venv/ops/main.py", line 529, in run
    self._emit()
  File "/var/lib/juju/agents/unit-postgresql-test-app-0/charm/venv/ops/main.py", line 518, in _emit
    _emit_charm_event(self.charm, self.dispatcher.event_name, self._juju_context)
  File "/var/lib/juju/agents/unit-postgresql-test-app-0/charm/venv/ops/main.py", line 139, in _emit_charm_event
    event_to_emit.emit(*args, **kwargs)
  File "/var/lib/juju/agents/unit-postgresql-test-app-0/charm/venv/ops/framework.py", line 347, in emit
    framework._emit(event)
  File "/var/lib/juju/agents/unit-postgresql-test-app-0/charm/venv/ops/framework.py", line 853, in _emit
    self._reemit(event_path)
  File "/var/lib/juju/agents/unit-postgresql-test-app-0/charm/venv/ops/framework.py", line 943, in _reemit
    custom_handler(event)
  File "/var/lib/juju/agents/unit-postgresql-test-app-0/charm/./src/charm.py", line 289, in _on_clear_continuous_writes_action
    if self._connection_string is None:
  File "/var/lib/juju/agents/unit-postgresql-test-app-0/charm/./src/charm.py", line 259, in _connection_string
    data = list(self.first_database.fetch_relation_data().values())[0]
AttributeError: 'ApplicationCharm' object has no attribute 'first_database'
unit-postgresql-test-app-0: 02:05:28 ERROR unit.postgresql-test-app/0.juju-log Uncaught exception while in charm code:
Traceback (most recent call last):
  File "/var/lib/juju/agents/unit-postgresql-test-app-0/charm/./src/charm.py", line 538, in <module>
    main(ApplicationCharm)
  File "/var/lib/juju/agents/unit-postgresql-test-app-0/charm/venv/ops/main.py", line 553, in main
    manager.run()
  File "/var/lib/juju/agents/unit-postgresql-test-app-0/charm/venv/ops/main.py", line 529, in run
    self._emit()
  File "/var/lib/juju/agents/unit-postgresql-test-app-0/charm/venv/ops/main.py", line 518, in _emit
    _emit_charm_event(self.charm, self.dispatcher.event_name, self._juju_context)
  File "/var/lib/juju/agents/unit-postgresql-test-app-0/charm/venv/ops/main.py", line 139, in _emit_charm_event
    event_to_emit.emit(*args, **kwargs)
  File "/var/lib/juju/agents/unit-postgresql-test-app-0/charm/venv/ops/framework.py", line 347, in emit
    framework._emit(event)
  File "/var/lib/juju/agents/unit-postgresql-test-app-0/charm/venv/ops/framework.py", line 853, in _emit
    self._reemit(event_path)
  File "/var/lib/juju/agents/unit-postgresql-test-app-0/charm/venv/ops/framework.py", line 943, in _reemit
    custom_handler(event)
  File "/var/lib/juju/agents/unit-postgresql-test-app-0/charm/./src/charm.py", line 289, in _on_clear_continuous_writes_action
    if self._connection_string is None:
  File "/var/lib/juju/agents/unit-postgresql-test-app-0/charm/./src/charm.py", line 259, in _connection_string
    data = list(self.first_database.fetch_relation_data().values())[0]
AttributeError: 'ApplicationCharm' object has no attribute 'first_database'
unit-postgresql-test-app-0: 02:05:33 ERROR unit.postgresql-test-app/0.juju-log Uncaught exception while in charm code:
Traceback (most recent call last):
  File "/var/lib/juju/agents/unit-postgresql-test-app-0/charm/./src/charm.py", line 538, in <module>
    main(ApplicationCharm)
  File "/var/lib/juju/agents/unit-postgresql-test-app-0/charm/venv/ops/main.py", line 553, in main
    manager.run()
  File "/var/lib/juju/agents/unit-postgresql-test-app-0/charm/venv/ops/main.py", line 529, in run
    self._emit()
  File "/var/lib/juju/agents/unit-postgresql-test-app-0/charm/venv/ops/main.py", line 518, in _emit
    _emit_charm_event(self.charm, self.dispatcher.event_name, self._juju_context)
  File "/var/lib/juju/agents/unit-postgresql-test-app-0/charm/venv/ops/main.py", line 139, in _emit_charm_event
    event_to_emit.emit(*args, **kwargs)
  File "/var/lib/juju/agents/unit-postgresql-test-app-0/charm/venv/ops/framework.py", line 347, in emit
    framework._emit(event)
  File "/var/lib/juju/agents/unit-postgresql-test-app-0/charm/venv/ops/framework.py", line 853, in _emit
    self._reemit(event_path)
  File "/var/lib/juju/agents/unit-postgresql-test-app-0/charm/venv/ops/framework.py", line 943, in _reemit
    custom_handler(event)
  File "/var/lib/juju/agents/unit-postgresql-test-app-0/charm/./src/charm.py", line 289, in _on_clear_continuous_writes_action
    if self._connection_string is None:
  File "/var/lib/juju/agents/unit-postgresql-test-app-0/charm/./src/charm.py", line 259, in _connection_string
    data = list(self.first_database.fetch_relation_data().values())[0]
AttributeError: 'ApplicationCharm' object has no attribute 'first_database'
unit-postgresql-test-app-0: 02:05:37 ERROR unit.postgresql-test-app/0.juju-log Uncaught exception while in charm code:
Traceback (most recent call last):
  File "/var/lib/juju/agents/unit-postgresql-test-app-0/charm/./src/charm.py", line 538, in <module>
    main(ApplicationCharm)
  File "/var/lib/juju/agents/unit-postgresql-test-app-0/charm/venv/ops/main.py", line 553, in main
    manager.run()
  File "/var/lib/juju/agents/unit-postgresql-test-app-0/charm/venv/ops/main.py", line 529, in run
    self._emit()
  File "/var/lib/juju/agents/unit-postgresql-test-app-0/charm/venv/ops/main.py", line 518, in _emit
    _emit_charm_event(self.charm, self.dispatcher.event_name, self._juju_context)
  File "/var/lib/juju/agents/unit-postgresql-test-app-0/charm/venv/ops/main.py", line 139, in _emit_charm_event
    event_to_emit.emit(*args, **kwargs)
  File "/var/lib/juju/agents/unit-postgresql-test-app-0/charm/venv/ops/framework.py", line 347, in emit
    framework._emit(event)
  File "/var/lib/juju/agents/unit-postgresql-test-app-0/charm/venv/ops/framework.py", line 853, in _emit
    self._reemit(event_path)
  File "/var/lib/juju/agents/unit-postgresql-test-app-0/charm/venv/ops/framework.py", line 943, in _reemit
    custom_handler(event)
  File "/var/lib/juju/agents/unit-postgresql-test-app-0/charm/./src/charm.py", line 289, in _on_clear_continuous_writes_action
    if self._connection_string is None:
  File "/var/lib/juju/agents/unit-postgresql-test-app-0/charm/./src/charm.py", line 259, in _connection_string
    data = list(self.first_database.fetch_relation_data().values())[0]
AttributeError: 'ApplicationCharm' object has no attribute 'first_database'
unit-postgresql-test-app-0: 02:05:41 ERROR unit.postgresql-test-app/0.juju-log Uncaught exception while in charm code:
Traceback (most recent call last):
  File "/var/lib/juju/agents/unit-postgresql-test-app-0/charm/./src/charm.py", line 538, in <module>
    main(ApplicationCharm)
  File "/var/lib/juju/agents/unit-postgresql-test-app-0/charm/venv/ops/main.py", line 553, in main
    manager.run()
  File "/var/lib/juju/agents/unit-postgresql-test-app-0/charm/venv/ops/main.py", line 529, in run
    self._emit()
  File "/var/lib/juju/agents/unit-postgresql-test-app-0/charm/venv/ops/main.py", line 518, in _emit
    _emit_charm_event(self.charm, self.dispatcher.event_name, self._juju_context)
  File "/var/lib/juju/agents/unit-postgresql-test-app-0/charm/venv/ops/main.py", line 139, in _emit_charm_event
    event_to_emit.emit(*args, **kwargs)
  File "/var/lib/juju/agents/unit-postgresql-test-app-0/charm/venv/ops/framework.py", line 347, in emit
    framework._emit(event)
  File "/var/lib/juju/agents/unit-postgresql-test-app-0/charm/venv/ops/framework.py", line 853, in _emit
    self._reemit(event_path)
  File "/var/lib/juju/agents/unit-postgresql-test-app-0/charm/venv/ops/framework.py", line 943, in _reemit
    custom_handler(event)
  File "/var/lib/juju/agents/unit-postgresql-test-app-0/charm/./src/charm.py", line 289, in _on_clear_continuous_writes_action
    if self._connection_string is None:
  File "/var/lib/juju/agents/unit-postgresql-test-app-0/charm/./src/charm.py", line 259, in _connection_string
    data = list(self.first_database.fetch_relation_data().values())[0]
AttributeError: 'ApplicationCharm' object has no attribute 'first_database'
unit-postgresql-test-app-0: 02:05:45 ERROR unit.postgresql-test-app/0.juju-log Uncaught exception while in charm code:
Traceback (most recent call last):
  File "/var/lib/juju/agents/unit-postgresql-test-app-0/charm/./src/charm.py", line 538, in <module>
    main(ApplicationCharm)
  File "/var/lib/juju/agents/unit-postgresql-test-app-0/charm/venv/ops/main.py", line 553, in main
    manager.run()
  File "/var/lib/juju/agents/unit-postgresql-test-app-0/charm/venv/ops/main.py", line 529, in run
    self._emit()
  File "/var/lib/juju/agents/unit-postgresql-test-app-0/charm/venv/ops/main.py", line 518, in _emit
    _emit_charm_event(self.charm, self.dispatcher.event_name, self._juju_context)
  File "/var/lib/juju/agents/unit-postgresql-test-app-0/charm/venv/ops/main.py", line 139, in _emit_charm_event
    event_to_emit.emit(*args, **kwargs)
  File "/var/lib/juju/agents/unit-postgresql-test-app-0/charm/venv/ops/framework.py", line 347, in emit
    framework._emit(event)
  File "/var/lib/juju/agents/unit-postgresql-test-app-0/charm/venv/ops/framework.py", line 853, in _emit
    self._reemit(event_path)
  File "/var/lib/juju/agents/unit-postgresql-test-app-0/charm/venv/ops/framework.py", line 943, in _reemit
    custom_handler(event)
  File "/var/lib/juju/agents/unit-postgresql-test-app-0/charm/./src/charm.py", line 289, in _on_clear_continuous_writes_action
    if self._connection_string is None:
  File "/var/lib/juju/agents/unit-postgresql-test-app-0/charm/./src/charm.py", line 259, in _connection_string
    data = list(self.first_database.fetch_relation_data().values())[0]
AttributeError: 'ApplicationCharm' object has no attribute 'first_database'
unit-postgresql-test-app-0: 02:05:49 ERROR unit.postgresql-test-app/0.juju-log Uncaught exception while in charm code:
Traceback (most recent call last):
  File "/var/lib/juju/agents/unit-postgresql-test-app-0/charm/./src/charm.py", line 538, in <module>
    main(ApplicationCharm)
  File "/var/lib/juju/agents/unit-postgresql-test-app-0/charm/venv/ops/main.py", line 553, in main
    manager.run()
  File "/var/lib/juju/agents/unit-postgresql-test-app-0/charm/venv/ops/main.py", line 529, in run
    self._emit()
  File "/var/lib/juju/agents/unit-postgresql-test-app-0/charm/venv/ops/main.py", line 518, in _emit
    _emit_charm_event(self.charm, self.dispatcher.event_name, self._juju_context)
  File "/var/lib/juju/agents/unit-postgresql-test-app-0/charm/venv/ops/main.py", line 139, in _emit_charm_event
    event_to_emit.emit(*args, **kwargs)
  File "/var/lib/juju/agents/unit-postgresql-test-app-0/charm/venv/ops/framework.py", line 347, in emit
    framework._emit(event)
  File "/var/lib/juju/agents/unit-postgresql-test-app-0/charm/venv/ops/framework.py", line 853, in _emit
    self._reemit(event_path)
  File "/var/lib/juju/agents/unit-postgresql-test-app-0/charm/venv/ops/framework.py", line 943, in _reemit
    custom_handler(event)
  File "/var/lib/juju/agents/unit-postgresql-test-app-0/charm/./src/charm.py", line 289, in _on_clear_continuous_writes_action
    if self._connection_string is None:
  File "/var/lib/juju/agents/unit-postgresql-test-app-0/charm/./src/charm.py", line 259, in _connection_string
    data = list(self.first_database.fetch_relation_data().values())[0]
AttributeError: 'ApplicationCharm' object has no attribute 'first_database'
unit-postgresql-test-app-0: 02:05:53 ERROR unit.postgresql-test-app/0.juju-log Uncaught exception while in charm code:
Traceback (most recent call last):
  File "/var/lib/juju/agents/unit-postgresql-test-app-0/charm/./src/charm.py", line 538, in <module>
    main(ApplicationCharm)
  File "/var/lib/juju/agents/unit-postgresql-test-app-0/charm/venv/ops/main.py", line 553, in main
    manager.run()
  File "/var/lib/juju/agents/unit-postgresql-test-app-0/charm/venv/ops/main.py", line 529, in run
    self._emit()
  File "/var/lib/juju/agents/unit-postgresql-test-app-0/charm/venv/ops/main.py", line 518, in _emit
    _emit_charm_event(self.charm, self.dispatcher.event_name, self._juju_context)
  File "/var/lib/juju/agents/unit-postgresql-test-app-0/charm/venv/ops/main.py", line 139, in _emit_charm_event
    event_to_emit.emit(*args, **kwargs)
  File "/var/lib/juju/agents/unit-postgresql-test-app-0/charm/venv/ops/framework.py", line 347, in emit
    framework._emit(event)
  File "/var/lib/juju/agents/unit-postgresql-test-app-0/charm/venv/ops/framework.py", line 853, in _emit
    self._reemit(event_path)
  File "/var/lib/juju/agents/unit-postgresql-test-app-0/charm/venv/ops/framework.py", line 943, in _reemit
    custom_handler(event)
  File "/var/lib/juju/agents/unit-postgresql-test-app-0/charm/./src/charm.py", line 289, in _on_clear_continuous_writes_action
    if self._connection_string is None:
  File "/var/lib/juju/agents/unit-postgresql-test-app-0/charm/./src/charm.py", line 259, in _connection_string
    data = list(self.first_database.fetch_relation_data().values())[0]
AttributeError: 'ApplicationCharm' object has no attribute 'first_database'
unit-postgresql-test-app-0: 02:05:57 ERROR unit.postgresql-test-app/0.juju-log Uncaught exception while in charm code:
Traceback (most recent call last):
  File "/var/lib/juju/agents/unit-postgresql-test-app-0/charm/./src/charm.py", line 538, in <module>
    main(ApplicationCharm)
  File "/var/lib/juju/agents/unit-postgresql-test-app-0/charm/venv/ops/main.py", line 553, in main
    manager.run()
  File "/var/lib/juju/agents/unit-postgresql-test-app-0/charm/venv/ops/main.py", line 529, in run
    self._emit()
  File "/var/lib/juju/agents/unit-postgresql-test-app-0/charm/venv/ops/main.py", line 518, in _emit
    _emit_charm_event(self.charm, self.dispatcher.event_name, self._juju_context)
  File "/var/lib/juju/agents/unit-postgresql-test-app-0/charm/venv/ops/main.py", line 139, in _emit_charm_event
    event_to_emit.emit(*args, **kwargs)
  File "/var/lib/juju/agents/unit-postgresql-test-app-0/charm/venv/ops/framework.py", line 347, in emit
    framework._emit(event)
  File "/var/lib/juju/agents/unit-postgresql-test-app-0/charm/venv/ops/framework.py", line 853, in _emit
    self._reemit(event_path)
  File "/var/lib/juju/agents/unit-postgresql-test-app-0/charm/venv/ops/framework.py", line 943, in _reemit
    custom_handler(event)
  File "/var/lib/juju/agents/unit-postgresql-test-app-0/charm/./src/charm.py", line 289, in _on_clear_continuous_writes_action
    if self._connection_string is None:
  File "/var/lib/juju/agents/unit-postgresql-test-app-0/charm/./src/charm.py", line 259, in _connection_string
    data = list(self.first_database.fetch_relation_data().values())[0]
AttributeError: 'ApplicationCharm' object has no attribute 'first_database'
unit-postgresql-test-app-0: 02:06:01 ERROR unit.postgresql-test-app/0.juju-log Uncaught exception while in charm code:
Traceback (most recent call last):
  File "/var/lib/juju/agents/unit-postgresql-test-app-0/charm/./src/charm.py", line 538, in <module>
    main(ApplicationCharm)
  File "/var/lib/juju/agents/unit-postgresql-test-app-0/charm/venv/ops/main.py", line 553, in main
    manager.run()
  File "/var/lib/juju/agents/unit-postgresql-test-app-0/charm/venv/ops/main.py", line 529, in run
    self._emit()
  File "/var/lib/juju/agents/unit-postgresql-test-app-0/charm/venv/ops/main.py", line 518, in _emit
    _emit_charm_event(self.charm, self.dispatcher.event_name, self._juju_context)
  File "/var/lib/juju/agents/unit-postgresql-test-app-0/charm/venv/ops/main.py", line 139, in _emit_charm_event
    event_to_emit.emit(*args, **kwargs)
  File "/var/lib/juju/agents/unit-postgresql-test-app-0/charm/venv/ops/framework.py", line 347, in emit
    framework._emit(event)
  File "/var/lib/juju/agents/unit-postgresql-test-app-0/charm/venv/ops/framework.py", line 853, in _emit
    self._reemit(event_path)
  File "/var/lib/juju/agents/unit-postgresql-test-app-0/charm/venv/ops/framework.py", line 943, in _reemit
    custom_handler(event)
  File "/var/lib/juju/agents/unit-postgresql-test-app-0/charm/./src/charm.py", line 289, in _on_clear_continuous_writes_action
    if self._connection_string is None:
  File "/var/lib/juju/agents/unit-postgresql-test-app-0/charm/./src/charm.py", line 259, in _connection_string
    data = list(self.first_database.fetch_relation_data().values())[0]
AttributeError: 'ApplicationCharm' object has no attribute 'first_database'
unit-postgresql-test-app-0: 02:06:05 ERROR unit.postgresql-test-app/0.juju-log Uncaught exception while in charm code:
Traceback (most recent call last):
  File "/var/lib/juju/agents/unit-postgresql-test-app-0/charm/./src/charm.py", line 538, in <module>
    main(ApplicationCharm)
  File "/var/lib/juju/agents/unit-postgresql-test-app-0/charm/venv/ops/main.py", line 553, in main
    manager.run()
  File "/var/lib/juju/agents/unit-postgresql-test-app-0/charm/venv/ops/main.py", line 529, in run
    self._emit()
  File "/var/lib/juju/agents/unit-postgresql-test-app-0/charm/venv/ops/main.py", line 518, in _emit
    _emit_charm_event(self.charm, self.dispatcher.event_name, self._juju_context)
  File "/var/lib/juju/agents/unit-postgresql-test-app-0/charm/venv/ops/main.py", line 139, in _emit_charm_event
    event_to_emit.emit(*args, **kwargs)
  File "/var/lib/juju/agents/unit-postgresql-test-app-0/charm/venv/ops/framework.py", line 347, in emit
    framework._emit(event)
  File "/var/lib/juju/agents/unit-postgresql-test-app-0/charm/venv/ops/framework.py", line 853, in _emit
    self._reemit(event_path)
  File "/var/lib/juju/agents/unit-postgresql-test-app-0/charm/venv/ops/framework.py", line 943, in _reemit
    custom_handler(event)
  File "/var/lib/juju/agents/unit-postgresql-test-app-0/charm/./src/charm.py", line 289, in _on_clear_continuous_writes_action
    if self._connection_string is None:
  File "/var/lib/juju/agents/unit-postgresql-test-app-0/charm/./src/charm.py", line 259, in _connection_string
    data = list(self.first_database.fetch_relation_data().values())[0]
AttributeError: 'ApplicationCharm' object has no attribute 'first_database'
unit-postgresql-test-app-0: 02:06:09 ERROR unit.postgresql-test-app/0.juju-log Uncaught exception while in charm code:
Traceback (most recent call last):
  File "/var/lib/juju/agents/unit-postgresql-test-app-0/charm/./src/charm.py", line 538, in <module>
    main(ApplicationCharm)
  File "/var/lib/juju/agents/unit-postgresql-test-app-0/charm/venv/ops/main.py", line 553, in main
    manager.run()
  File "/var/lib/juju/agents/unit-postgresql-test-app-0/charm/venv/ops/main.py", line 529, in run
    self._emit()
  File "/var/lib/juju/agents/unit-postgresql-test-app-0/charm/venv/ops/main.py", line 518, in _emit
    _emit_charm_event(self.charm, self.dispatcher.event_name, self._juju_context)
  File "/var/lib/juju/agents/unit-postgresql-test-app-0/charm/venv/ops/main.py", line 139, in _emit_charm_event
    event_to_emit.emit(*args, **kwargs)
  File "/var/lib/juju/agents/unit-postgresql-test-app-0/charm/venv/ops/framework.py", line 347, in emit
    framework._emit(event)
  File "/var/lib/juju/agents/unit-postgresql-test-app-0/charm/venv/ops/framework.py", line 853, in _emit
    self._reemit(event_path)
  File "/var/lib/juju/agents/unit-postgresql-test-app-0/charm/venv/ops/framework.py", line 943, in _reemit
    custom_handler(event)
  File "/var/lib/juju/agents/unit-postgresql-test-app-0/charm/./src/charm.py", line 289, in _on_clear_continuous_writes_action
    if self._connection_string is None:
  File "/var/lib/juju/agents/unit-postgresql-test-app-0/charm/./src/charm.py", line 259, in _connection_string
    data = list(self.first_database.fetch_relation_data().values())[0]
AttributeError: 'ApplicationCharm' object has no attribute 'first_database'
unit-postgresql-test-app-0: 02:06:13 ERROR unit.postgresql-test-app/0.juju-log Uncaught exception while in charm code:
Traceback (most recent call last):
  File "/var/lib/juju/agents/unit-postgresql-test-app-0/charm/./src/charm.py", line 538, in <module>
    main(ApplicationCharm)
  File "/var/lib/juju/agents/unit-postgresql-test-app-0/charm/venv/ops/main.py", line 553, in main
    manager.run()
  File "/var/lib/juju/agents/unit-postgresql-test-app-0/charm/venv/ops/main.py", line 529, in run
    self._emit()
  File "/var/lib/juju/agents/unit-postgresql-test-app-0/charm/venv/ops/main.py", line 518, in _emit
    _emit_charm_event(self.charm, self.dispatcher.event_name, self._juju_context)
  File "/var/lib/juju/agents/unit-postgresql-test-app-0/charm/venv/ops/main.py", line 139, in _emit_charm_event
    event_to_emit.emit(*args, **kwargs)
  File "/var/lib/juju/agents/unit-postgresql-test-app-0/charm/venv/ops/framework.py", line 347, in emit
    framework._emit(event)
  File "/var/lib/juju/agents/unit-postgresql-test-app-0/charm/venv/ops/framework.py", line 853, in _emit
    self._reemit(event_path)
  File "/var/lib/juju/agents/unit-postgresql-test-app-0/charm/venv/ops/framework.py", line 943, in _reemit
    custom_handler(event)
  File "/var/lib/juju/agents/unit-postgresql-test-app-0/charm/./src/charm.py", line 289, in _on_clear_continuous_writes_action
    if self._connection_string is None:
  File "/var/lib/juju/agents/unit-postgresql-test-app-0/charm/./src/charm.py", line 259, in _connection_string
    data = list(self.first_database.fetch_relation_data().values())[0]
AttributeError: 'ApplicationCharm' object has no attribute 'first_database'
unit-postgresql-test-app-0: 02:06:17 ERROR unit.postgresql-test-app/0.juju-log Uncaught exception while in charm code:
Traceback (most recent call last):
  File "/var/lib/juju/agents/unit-postgresql-test-app-0/charm/./src/charm.py", line 538, in <module>
    main(ApplicationCharm)
  File "/var/lib/juju/agents/unit-postgresql-test-app-0/charm/venv/ops/main.py", line 553, in main
    manager.run()
  File "/var/lib/juju/agents/unit-postgresql-test-app-0/charm/venv/ops/main.py", line 529, in run
    self._emit()
  File "/var/lib/juju/agents/unit-postgresql-test-app-0/charm/venv/ops/main.py", line 518, in _emit
    _emit_charm_event(self.charm, self.dispatcher.event_name, self._juju_context)
  File "/var/lib/juju/agents/unit-postgresql-test-app-0/charm/venv/ops/main.py", line 139, in _emit_charm_event
    event_to_emit.emit(*args, **kwargs)
  File "/var/lib/juju/agents/unit-postgresql-test-app-0/charm/venv/ops/framework.py", line 347, in emit
    framework._emit(event)
  File "/var/lib/juju/agents/unit-postgresql-test-app-0/charm/venv/ops/framework.py", line 853, in _emit
    self._reemit(event_path)
  File "/var/lib/juju/agents/unit-postgresql-test-app-0/charm/venv/ops/framework.py", line 943, in _reemit
    custom_handler(event)
  File "/var/lib/juju/agents/unit-postgresql-test-app-0/charm/./src/charm.py", line 289, in _on_clear_continuous_writes_action
    if self._connection_string is None:
  File "/var/lib/juju/agents/unit-postgresql-test-app-0/charm/./src/charm.py", line 259, in _connection_string
    data = list(self.first_database.fetch_relation_data().values())[0]
AttributeError: 'ApplicationCharm' object has no attribute 'first_database'
unit-postgresql-test-app-0: 02:06:21 ERROR unit.postgresql-test-app/0.juju-log Uncaught exception while in charm code:
Traceback (most recent call last):
  File "/var/lib/juju/agents/unit-postgresql-test-app-0/charm/./src/charm.py", line 538, in <module>
    main(ApplicationCharm)
  File "/var/lib/juju/agents/unit-postgresql-test-app-0/charm/venv/ops/main.py", line 553, in main
    manager.run()
  File "/var/lib/juju/agents/unit-postgresql-test-app-0/charm/venv/ops/main.py", line 529, in run
    self._emit()
  File "/var/lib/juju/agents/unit-postgresql-test-app-0/charm/venv/ops/main.py", line 518, in _emit
    _emit_charm_event(self.charm, self.dispatcher.event_name, self._juju_context)
  File "/var/lib/juju/agents/unit-postgresql-test-app-0/charm/venv/ops/main.py", line 139, in _emit_charm_event
    event_to_emit.emit(*args, **kwargs)
  File "/var/lib/juju/agents/unit-postgresql-test-app-0/charm/venv/ops/framework.py", line 347, in emit
    framework._emit(event)
  File "/var/lib/juju/agents/unit-postgresql-test-app-0/charm/venv/ops/framework.py", line 853, in _emit
    self._reemit(event_path)
  File "/var/lib/juju/agents/unit-postgresql-test-app-0/charm/venv/ops/framework.py", line 943, in _reemit
    custom_handler(event)
  File "/var/lib/juju/agents/unit-postgresql-test-app-0/charm/./src/charm.py", line 289, in _on_clear_continuous_writes_action
    if self._connection_string is None:
  File "/var/lib/juju/agents/unit-postgresql-test-app-0/charm/./src/charm.py", line 259, in _connection_string
    data = list(self.first_database.fetch_relation_data().values())[0]
AttributeError: 'ApplicationCharm' object has no attribute 'first_database'
unit-postgresql-test-app-0: 02:06:25 ERROR unit.postgresql-test-app/0.juju-log Uncaught exception while in charm code:
Traceback (most recent call last):
  File "/var/lib/juju/agents/unit-postgresql-test-app-0/charm/./src/charm.py", line 538, in <module>
    main(ApplicationCharm)
  File "/var/lib/juju/agents/unit-postgresql-test-app-0/charm/venv/ops/main.py", line 553, in main
    manager.run()
  File "/var/lib/juju/agents/unit-postgresql-test-app-0/charm/venv/ops/main.py", line 529, in run
    self._emit()
  File "/var/lib/juju/agents/unit-postgresql-test-app-0/charm/venv/ops/main.py", line 518, in _emit
    _emit_charm_event(self.charm, self.dispatcher.event_name, self._juju_context)
  File "/var/lib/juju/agents/unit-postgresql-test-app-0/charm/venv/ops/main.py", line 139, in _emit_charm_event
    event_to_emit.emit(*args, **kwargs)
  File "/var/lib/juju/agents/unit-postgresql-test-app-0/charm/venv/ops/framework.py", line 347, in emit
    framework._emit(event)
  File "/var/lib/juju/agents/unit-postgresql-test-app-0/charm/venv/ops/framework.py", line 853, in _emit
    self._reemit(event_path)
  File "/var/lib/juju/agents/unit-postgresql-test-app-0/charm/venv/ops/framework.py", line 943, in _reemit
    custom_handler(event)
  File "/var/lib/juju/agents/unit-postgresql-test-app-0/charm/./src/charm.py", line 289, in _on_clear_continuous_writes_action
    if self._connection_string is None:
  File "/var/lib/juju/agents/unit-postgresql-test-app-0/charm/./src/charm.py", line 259, in _connection_string
    data = list(self.first_database.fetch_relation_data().values())[0]
AttributeError: 'ApplicationCharm' object has no attribute 'first_database'
unit-postgresql-test-app-0: 02:06:29 ERROR unit.postgresql-test-app/0.juju-log Uncaught exception while in charm code:
Traceback (most recent call last):
  File "/var/lib/juju/agents/unit-postgresql-test-app-0/charm/./src/charm.py", line 538, in <module>
    main(ApplicationCharm)
  File "/var/lib/juju/agents/unit-postgresql-test-app-0/charm/venv/ops/main.py", line 553, in main
    manager.run()
  File "/var/lib/juju/agents/unit-postgresql-test-app-0/charm/venv/ops/main.py", line 529, in run
    self._emit()
  File "/var/lib/juju/agents/unit-postgresql-test-app-0/charm/venv/ops/main.py", line 518, in _emit
    _emit_charm_event(self.charm, self.dispatcher.event_name, self._juju_context)
  File "/var/lib/juju/agents/unit-postgresql-test-app-0/charm/venv/ops/main.py", line 139, in _emit_charm_event
    event_to_emit.emit(*args, **kwargs)
  File "/var/lib/juju/agents/unit-postgresql-test-app-0/charm/venv/ops/framework.py", line 347, in emit
    framework._emit(event)
  File "/var/lib/juju/agents/unit-postgresql-test-app-0/charm/venv/ops/framework.py", line 853, in _emit
    self._reemit(event_path)
  File "/var/lib/juju/agents/unit-postgresql-test-app-0/charm/venv/ops/framework.py", line 943, in _reemit
    custom_handler(event)
  File "/var/lib/juju/agents/unit-postgresql-test-app-0/charm/./src/charm.py", line 289, in _on_clear_continuous_writes_action
    if self._connection_string is None:
  File "/var/lib/juju/agents/unit-postgresql-test-app-0/charm/./src/charm.py", line 259, in _connection_string
    data = list(self.first_database.fetch_relation_data().values())[0]
AttributeError: 'ApplicationCharm' object has no attribute 'first_database'
unit-postgresql-test-app-0: 02:06:33 ERROR unit.postgresql-test-app/0.juju-log Uncaught exception while in charm code:
Traceback (most recent call last):
  File "/var/lib/juju/agents/unit-postgresql-test-app-0/charm/./src/charm.py", line 538, in <module>
    main(ApplicationCharm)
  File "/var/lib/juju/agents/unit-postgresql-test-app-0/charm/venv/ops/main.py", line 553, in main
    manager.run()
  File "/var/lib/juju/agents/unit-postgresql-test-app-0/charm/venv/ops/main.py", line 529, in run
    self._emit()
  File "/var/lib/juju/agents/unit-postgresql-test-app-0/charm/venv/ops/main.py", line 518, in _emit
    _emit_charm_event(self.charm, self.dispatcher.event_name, self._juju_context)
  File "/var/lib/juju/agents/unit-postgresql-test-app-0/charm/venv/ops/main.py", line 139, in _emit_charm_event
    event_to_emit.emit(*args, **kwargs)
  File "/var/lib/juju/agents/unit-postgresql-test-app-0/charm/venv/ops/framework.py", line 347, in emit
    framework._emit(event)
  File "/var/lib/juju/agents/unit-postgresql-test-app-0/charm/venv/ops/framework.py", line 853, in _emit
    self._reemit(event_path)
  File "/var/lib/juju/agents/unit-postgresql-test-app-0/charm/venv/ops/framework.py", line 943, in _reemit
    custom_handler(event)
  File "/var/lib/juju/agents/unit-postgresql-test-app-0/charm/./src/charm.py", line 289, in _on_clear_continuous_writes_action
    if self._connection_string is None:
  File "/var/lib/juju/agents/unit-postgresql-test-app-0/charm/./src/charm.py", line 259, in _connection_string
    data = list(self.first_database.fetch_relation_data().values())[0]
AttributeError: 'ApplicationCharm' object has no attribute 'first_database'
unit-postgresql-test-app-0: 02:06:37 ERROR unit.postgresql-test-app/0.juju-log Uncaught exception while in charm code:
Traceback (most recent call last):
  File "/var/lib/juju/agents/unit-postgresql-test-app-0/charm/./src/charm.py", line 538, in <module>
    main(ApplicationCharm)
  File "/var/lib/juju/agents/unit-postgresql-test-app-0/charm/venv/ops/main.py", line 553, in main
    manager.run()
  File "/var/lib/juju/agents/unit-postgresql-test-app-0/charm/venv/ops/main.py", line 529, in run
    self._emit()
  File "/var/lib/juju/agents/unit-postgresql-test-app-0/charm/venv/ops/main.py", line 518, in _emit
    _emit_charm_event(self.charm, self.dispatcher.event_name, self._juju_context)
  File "/var/lib/juju/agents/unit-postgresql-test-app-0/charm/venv/ops/main.py", line 139, in _emit_charm_event
    event_to_emit.emit(*args, **kwargs)
  File "/var/lib/juju/agents/unit-postgresql-test-app-0/charm/venv/ops/framework.py", line 347, in emit
    framework._emit(event)
  File "/var/lib/juju/agents/unit-postgresql-test-app-0/charm/venv/ops/framework.py", line 853, in _emit
    self._reemit(event_path)
  File "/var/lib/juju/agents/unit-postgresql-test-app-0/charm/venv/ops/framework.py", line 943, in _reemit
    custom_handler(event)
  File "/var/lib/juju/agents/unit-postgresql-test-app-0/charm/./src/charm.py", line 289, in _on_clear_continuous_writes_action
    if self._connection_string is None:
  File "/var/lib/juju/agents/unit-postgresql-test-app-0/charm/./src/charm.py", line 259, in _connection_string
    data = list(self.first_database.fetch_relation_data().values())[0]
AttributeError: 'ApplicationCharm' object has no attribute 'first_database'
unit-postgresql-test-app-0: 02:06:41 ERROR unit.postgresql-test-app/0.juju-log Uncaught exception while in charm code:
Traceback (most recent call last):
  File "/var/lib/juju/agents/unit-postgresql-test-app-0/charm/./src/charm.py", line 538, in <module>
    main(ApplicationCharm)
  File "/var/lib/juju/agents/unit-postgresql-test-app-0/charm/venv/ops/main.py", line 553, in main
    manager.run()
  File "/var/lib/juju/agents/unit-postgresql-test-app-0/charm/venv/ops/main.py", line 529, in run
    self._emit()
  File "/var/lib/juju/agents/unit-postgresql-test-app-0/charm/venv/ops/main.py", line 518, in _emit
    _emit_charm_event(self.charm, self.dispatcher.event_name, self._juju_context)
  File "/var/lib/juju/agents/unit-postgresql-test-app-0/charm/venv/ops/main.py", line 139, in _emit_charm_event
    event_to_emit.emit(*args, **kwargs)
  File "/var/lib/juju/agents/unit-postgresql-test-app-0/charm/venv/ops/framework.py", line 347, in emit
    framework._emit(event)
  File "/var/lib/juju/agents/unit-postgresql-test-app-0/charm/venv/ops/framework.py", line 853, in _emit
    self._reemit(event_path)
  File "/var/lib/juju/agents/unit-postgresql-test-app-0/charm/venv/ops/framework.py", line 943, in _reemit
    custom_handler(event)
  File "/var/lib/juju/agents/unit-postgresql-test-app-0/charm/./src/charm.py", line 289, in _on_clear_continuous_writes_action
    if self._connection_string is None:
  File "/var/lib/juju/agents/unit-postgresql-test-app-0/charm/./src/charm.py", line 259, in _connection_string
    data = list(self.first_database.fetch_relation_data().values())[0]
AttributeError: 'ApplicationCharm' object has no attribute 'first_database'
unit-postgresql-test-app-0: 02:06:45 ERROR unit.postgresql-test-app/0.juju-log Uncaught exception while in charm code:
Traceback (most recent call last):
  File "/var/lib/juju/agents/unit-postgresql-test-app-0/charm/./src/charm.py", line 538, in <module>
    main(ApplicationCharm)
  File "/var/lib/juju/agents/unit-postgresql-test-app-0/charm/venv/ops/main.py", line 553, in main
    manager.run()
  File "/var/lib/juju/agents/unit-postgresql-test-app-0/charm/venv/ops/main.py", line 529, in run
    self._emit()
  File "/var/lib/juju/agents/unit-postgresql-test-app-0/charm/venv/ops/main.py", line 518, in _emit
    _emit_charm_event(self.charm, self.dispatcher.event_name, self._juju_context)
  File "/var/lib/juju/agents/unit-postgresql-test-app-0/charm/venv/ops/main.py", line 139, in _emit_charm_event
    event_to_emit.emit(*args, **kwargs)
  File "/var/lib/juju/agents/unit-postgresql-test-app-0/charm/venv/ops/framework.py", line 347, in emit
    framework._emit(event)
  File "/var/lib/juju/agents/unit-postgresql-test-app-0/charm/venv/ops/framework.py", line 853, in _emit
    self._reemit(event_path)
  File "/var/lib/juju/agents/unit-postgresql-test-app-0/charm/venv/ops/framework.py", line 943, in _reemit
    custom_handler(event)
  File "/var/lib/juju/agents/unit-postgresql-test-app-0/charm/./src/charm.py", line 289, in _on_clear_continuous_writes_action
    if self._connection_string is None:
  File "/var/lib/juju/agents/unit-postgresql-test-app-0/charm/./src/charm.py", line 259, in _connection_string
    data = list(self.first_database.fetch_relation_data().values())[0]
AttributeError: 'ApplicationCharm' object has no attribute 'first_database'
unit-postgresql-test-app-0: 02:06:49 ERROR unit.postgresql-test-app/0.juju-log Uncaught exception while in charm code:
Traceback (most recent call last):
  File "/var/lib/juju/agents/unit-postgresql-test-app-0/charm/./src/charm.py", line 538, in <module>
    main(ApplicationCharm)
  File "/var/lib/juju/agents/unit-postgresql-test-app-0/charm/venv/ops/main.py", line 553, in main
    manager.run()
  File "/var/lib/juju/agents/unit-postgresql-test-app-0/charm/venv/ops/main.py", line 529, in run
    self._emit()
  File "/var/lib/juju/agents/unit-postgresql-test-app-0/charm/venv/ops/main.py", line 518, in _emit
    _emit_charm_event(self.charm, self.dispatcher.event_name, self._juju_context)
  File "/var/lib/juju/agents/unit-postgresql-test-app-0/charm/venv/ops/main.py", line 139, in _emit_charm_event
    event_to_emit.emit(*args, **kwargs)
  File "/var/lib/juju/agents/unit-postgresql-test-app-0/charm/venv/ops/framework.py", line 347, in emit
    framework._emit(event)
  File "/var/lib/juju/agents/unit-postgresql-test-app-0/charm/venv/ops/framework.py", line 853, in _emit
    self._reemit(event_path)
  File "/var/lib/juju/agents/unit-postgresql-test-app-0/charm/venv/ops/framework.py", line 943, in _reemit
    custom_handler(event)
  File "/var/lib/juju/agents/unit-postgresql-test-app-0/charm/./src/charm.py", line 289, in _on_clear_continuous_writes_action
    if self._connection_string is None:
  File "/var/lib/juju/agents/unit-postgresql-test-app-0/charm/./src/charm.py", line 259, in _connection_string
    data = list(self.first_database.fetch_relation_data().values())[0]
AttributeError: 'ApplicationCharm' object has no attribute 'first_database'
unit-postgresql-test-app-0: 02:06:53 ERROR unit.postgresql-test-app/0.juju-log Uncaught exception while in charm code:
Traceback (most recent call last):
  File "/var/lib/juju/agents/unit-postgresql-test-app-0/charm/./src/charm.py", line 538, in <module>
    main(ApplicationCharm)
  File "/var/lib/juju/agents/unit-postgresql-test-app-0/charm/venv/ops/main.py", line 553, in main
    manager.run()
  File "/var/lib/juju/agents/unit-postgresql-test-app-0/charm/venv/ops/main.py", line 529, in run
    self._emit()
  File "/var/lib/juju/agents/unit-postgresql-test-app-0/charm/venv/ops/main.py", line 518, in _emit
    _emit_charm_event(self.charm, self.dispatcher.event_name, self._juju_context)
  File "/var/lib/juju/agents/unit-postgresql-test-app-0/charm/venv/ops/main.py", line 139, in _emit_charm_event
    event_to_emit.emit(*args, **kwargs)
  File "/var/lib/juju/agents/unit-postgresql-test-app-0/charm/venv/ops/framework.py", line 347, in emit
    framework._emit(event)
  File "/var/lib/juju/agents/unit-postgresql-test-app-0/charm/venv/ops/framework.py", line 853, in _emit
    self._reemit(event_path)
  File "/var/lib/juju/agents/unit-postgresql-test-app-0/charm/venv/ops/framework.py", line 943, in _reemit
    custom_handler(event)
  File "/var/lib/juju/agents/unit-postgresql-test-app-0/charm/./src/charm.py", line 289, in _on_clear_continuous_writes_action
    if self._connection_string is None:
  File "/var/lib/juju/agents/unit-postgresql-test-app-0/charm/./src/charm.py", line 259, in _connection_string
    data = list(self.first_database.fetch_relation_data().values())[0]
AttributeError: 'ApplicationCharm' object has no attribute 'first_database'
unit-postgresql-test-app-0: 02:06:57 ERROR unit.postgresql-test-app/0.juju-log Uncaught exception while in charm code:
Traceback (most recent call last):
  File "/var/lib/juju/agents/unit-postgresql-test-app-0/charm/./src/charm.py", line 538, in <module>
    main(ApplicationCharm)
  File "/var/lib/juju/agents/unit-postgresql-test-app-0/charm/venv/ops/main.py", line 553, in main
    manager.run()
  File "/var/lib/juju/agents/unit-postgresql-test-app-0/charm/venv/ops/main.py", line 529, in run
    self._emit()
  File "/var/lib/juju/agents/unit-postgresql-test-app-0/charm/venv/ops/main.py", line 518, in _emit
    _emit_charm_event(self.charm, self.dispatcher.event_name, self._juju_context)
  File "/var/lib/juju/agents/unit-postgresql-test-app-0/charm/venv/ops/main.py", line 139, in _emit_charm_event
    event_to_emit.emit(*args, **kwargs)
  File "/var/lib/juju/agents/unit-postgresql-test-app-0/charm/venv/ops/framework.py", line 347, in emit
    framework._emit(event)
  File "/var/lib/juju/agents/unit-postgresql-test-app-0/charm/venv/ops/framework.py", line 853, in _emit
    self._reemit(event_path)
  File "/var/lib/juju/agents/unit-postgresql-test-app-0/charm/venv/ops/framework.py", line 943, in _reemit
    custom_handler(event)
  File "/var/lib/juju/agents/unit-postgresql-test-app-0/charm/./src/charm.py", line 289, in _on_clear_continuous_writes_action
    if self._connection_string is None:
  File "/var/lib/juju/agents/unit-postgresql-test-app-0/charm/./src/charm.py", line 259, in _connection_string
    data = list(self.first_database.fetch_relation_data().values())[0]
AttributeError: 'ApplicationCharm' object has no attribute 'first_database'
unit-postgresql-test-app-0: 02:07:01 ERROR unit.postgresql-test-app/0.juju-log Uncaught exception while in charm code:
Traceback (most recent call last):
  File "/var/lib/juju/agents/unit-postgresql-test-app-0/charm/./src/charm.py", line 538, in <module>
    main(ApplicationCharm)
  File "/var/lib/juju/agents/unit-postgresql-test-app-0/charm/venv/ops/main.py", line 553, in main
    manager.run()
  File "/var/lib/juju/agents/unit-postgresql-test-app-0/charm/venv/ops/main.py", line 529, in run
    self._emit()
  File "/var/lib/juju/agents/unit-postgresql-test-app-0/charm/venv/ops/main.py", line 518, in _emit
    _emit_charm_event(self.charm, self.dispatcher.event_name, self._juju_context)
  File "/var/lib/juju/agents/unit-postgresql-test-app-0/charm/venv/ops/main.py", line 139, in _emit_charm_event
    event_to_emit.emit(*args, **kwargs)
  File "/var/lib/juju/agents/unit-postgresql-test-app-0/charm/venv/ops/framework.py", line 347, in emit
    framework._emit(event)
  File "/var/lib/juju/agents/unit-postgresql-test-app-0/charm/venv/ops/framework.py", line 853, in _emit
    self._reemit(event_path)
  File "/var/lib/juju/agents/unit-postgresql-test-app-0/charm/venv/ops/framework.py", line 943, in _reemit
    custom_handler(event)
  File "/var/lib/juju/agents/unit-postgresql-test-app-0/charm/./src/charm.py", line 289, in _on_clear_continuous_writes_action
    if self._connection_string is None:
  File "/var/lib/juju/agents/unit-postgresql-test-app-0/charm/./src/charm.py", line 259, in _connection_string
    data = list(self.first_database.fetch_relation_data().values())[0]
AttributeError: 'ApplicationCharm' object has no attribute 'first_database'
unit-postgresql-test-app-0: 02:07:05 ERROR unit.postgresql-test-app/0.juju-log Uncaught exception while in charm code:
Traceback (most recent call last):
  File "/var/lib/juju/agents/unit-postgresql-test-app-0/charm/./src/charm.py", line 538, in <module>
    main(ApplicationCharm)
  File "/var/lib/juju/agents/unit-postgresql-test-app-0/charm/venv/ops/main.py", line 553, in main
    manager.run()
  File "/var/lib/juju/agents/unit-postgresql-test-app-0/charm/venv/ops/main.py", line 529, in run
    self._emit()
  File "/var/lib/juju/agents/unit-postgresql-test-app-0/charm/venv/ops/main.py", line 518, in _emit
    _emit_charm_event(self.charm, self.dispatcher.event_name, self._juju_context)
  File "/var/lib/juju/agents/unit-postgresql-test-app-0/charm/venv/ops/main.py", line 139, in _emit_charm_event
    event_to_emit.emit(*args, **kwargs)
  File "/var/lib/juju/agents/unit-postgresql-test-app-0/charm/venv/ops/framework.py", line 347, in emit
    framework._emit(event)
  File "/var/lib/juju/agents/unit-postgresql-test-app-0/charm/venv/ops/framework.py", line 853, in _emit
    self._reemit(event_path)
  File "/var/lib/juju/agents/unit-postgresql-test-app-0/charm/venv/ops/framework.py", line 943, in _reemit
    custom_handler(event)
  File "/var/lib/juju/agents/unit-postgresql-test-app-0/charm/./src/charm.py", line 289, in _on_clear_continuous_writes_action
    if self._connection_string is None:
  File "/var/lib/juju/agents/unit-postgresql-test-app-0/charm/./src/charm.py", line 259, in _connection_string
    data = list(self.first_database.fetch_relation_data().values())[0]
AttributeError: 'ApplicationCharm' object has no attribute 'first_database'
unit-postgresql-test-app-0: 02:07:09 ERROR unit.postgresql-test-app/0.juju-log Uncaught exception while in charm code:
Traceback (most recent call last):
  File "/var/lib/juju/agents/unit-postgresql-test-app-0/charm/./src/charm.py", line 538, in <module>
    main(ApplicationCharm)
  File "/var/lib/juju/agents/unit-postgresql-test-app-0/charm/venv/ops/main.py", line 553, in main
    manager.run()
  File "/var/lib/juju/agents/unit-postgresql-test-app-0/charm/venv/ops/main.py", line 529, in run
    self._emit()
  File "/var/lib/juju/agents/unit-postgresql-test-app-0/charm/venv/ops/main.py", line 518, in _emit
    _emit_charm_event(self.charm, self.dispatcher.event_name, self._juju_context)
  File "/var/lib/juju/agents/unit-postgresql-test-app-0/charm/venv/ops/main.py", line 139, in _emit_charm_event
    event_to_emit.emit(*args, **kwargs)
  File "/var/lib/juju/agents/unit-postgresql-test-app-0/charm/venv/ops/framework.py", line 347, in emit
    framework._emit(event)
  File "/var/lib/juju/agents/unit-postgresql-test-app-0/charm/venv/ops/framework.py", line 853, in _emit
    self._reemit(event_path)
  File "/var/lib/juju/agents/unit-postgresql-test-app-0/charm/venv/ops/framework.py", line 943, in _reemit
    custom_handler(event)
  File "/var/lib/juju/agents/unit-postgresql-test-app-0/charm/./src/charm.py", line 289, in _on_clear_continuous_writes_action
    if self._connection_string is None:
  File "/var/lib/juju/agents/unit-postgresql-test-app-0/charm/./src/charm.py", line 259, in _connection_string
    data = list(self.first_database.fetch_relation_data().values())[0]
AttributeError: 'ApplicationCharm' object has no attribute 'first_database'
unit-postgresql-test-app-0: 02:07:13 ERROR unit.postgresql-test-app/0.juju-log Uncaught exception while in charm code:
Traceback (most recent call last):
  File "/var/lib/juju/agents/unit-postgresql-test-app-0/charm/./src/charm.py", line 538, in <module>
    main(ApplicationCharm)
  File "/var/lib/juju/agents/unit-postgresql-test-app-0/charm/venv/ops/main.py", line 553, in main
    manager.run()
  File "/var/lib/juju/agents/unit-postgresql-test-app-0/charm/venv/ops/main.py", line 529, in run
    self._emit()
  File "/var/lib/juju/agents/unit-postgresql-test-app-0/charm/venv/ops/main.py", line 518, in _emit
    _emit_charm_event(self.charm, self.dispatcher.event_name, self._juju_context)
  File "/var/lib/juju/agents/unit-postgresql-test-app-0/charm/venv/ops/main.py", line 139, in _emit_charm_event
    event_to_emit.emit(*args, **kwargs)
  File "/var/lib/juju/agents/unit-postgresql-test-app-0/charm/venv/ops/framework.py", line 347, in emit
    framework._emit(event)
  File "/var/lib/juju/agents/unit-postgresql-test-app-0/charm/venv/ops/framework.py", line 853, in _emit
    self._reemit(event_path)
  File "/var/lib/juju/agents/unit-postgresql-test-app-0/charm/venv/ops/framework.py", line 943, in _reemit
    custom_handler(event)
  File "/var/lib/juju/agents/unit-postgresql-test-app-0/charm/./src/charm.py", line 289, in _on_clear_continuous_writes_action
    if self._connection_string is None:
  File "/var/lib/juju/agents/unit-postgresql-test-app-0/charm/./src/charm.py", line 259, in _connection_string
    data = list(self.first_database.fetch_relation_data().values())[0]
AttributeError: 'ApplicationCharm' object has no attribute 'first_database'
unit-postgresql-test-app-0: 02:07:17 ERROR unit.postgresql-test-app/0.juju-log Uncaught exception while in charm code:
Traceback (most recent call last):
  File "/var/lib/juju/agents/unit-postgresql-test-app-0/charm/./src/charm.py", line 538, in <module>
    main(ApplicationCharm)
  File "/var/lib/juju/agents/unit-postgresql-test-app-0/charm/venv/ops/main.py", line 553, in main
    manager.run()
  File "/var/lib/juju/agents/unit-postgresql-test-app-0/charm/venv/ops/main.py", line 529, in run
    self._emit()
  File "/var/lib/juju/agents/unit-postgresql-test-app-0/charm/venv/ops/main.py", line 518, in _emit
    _emit_charm_event(self.charm, self.dispatcher.event_name, self._juju_context)
  File "/var/lib/juju/agents/unit-postgresql-test-app-0/charm/venv/ops/main.py", line 139, in _emit_charm_event
    event_to_emit.emit(*args, **kwargs)
  File "/var/lib/juju/agents/unit-postgresql-test-app-0/charm/venv/ops/framework.py", line 347, in emit
    framework._emit(event)
  File "/var/lib/juju/agents/unit-postgresql-test-app-0/charm/venv/ops/framework.py", line 853, in _emit
    self._reemit(event_path)
  File "/var/lib/juju/agents/unit-postgresql-test-app-0/charm/venv/ops/framework.py", line 943, in _reemit
    custom_handler(event)
  File "/var/lib/juju/agents/unit-postgresql-test-app-0/charm/./src/charm.py", line 289, in _on_clear_continuous_writes_action
    if self._connection_string is None:
  File "/var/lib/juju/agents/unit-postgresql-test-app-0/charm/./src/charm.py", line 259, in _connection_string
    data = list(self.first_database.fetch_relation_data().values())[0]
AttributeError: 'ApplicationCharm' object has no attribute 'first_database'
unit-postgresql-test-app-0: 02:07:21 ERROR unit.postgresql-test-app/0.juju-log Uncaught exception while in charm code:
Traceback (most recent call last):
  File "/var/lib/juju/agents/unit-postgresql-test-app-0/charm/./src/charm.py", line 538, in <module>
    main(ApplicationCharm)
  File "/var/lib/juju/agents/unit-postgresql-test-app-0/charm/venv/ops/main.py", line 553, in main
    manager.run()
  File "/var/lib/juju/agents/unit-postgresql-test-app-0/charm/venv/ops/main.py", line 529, in run
    self._emit()
  File "/var/lib/juju/agents/unit-postgresql-test-app-0/charm/venv/ops/main.py", line 518, in _emit
    _emit_charm_event(self.charm, self.dispatcher.event_name, self._juju_context)
  File "/var/lib/juju/agents/unit-postgresql-test-app-0/charm/venv/ops/main.py", line 139, in _emit_charm_event
    event_to_emit.emit(*args, **kwargs)
  File "/var/lib/juju/agents/unit-postgresql-test-app-0/charm/venv/ops/framework.py", line 347, in emit
    framework._emit(event)
  File "/var/lib/juju/agents/unit-postgresql-test-app-0/charm/venv/ops/framework.py", line 853, in _emit
    self._reemit(event_path)
  File "/var/lib/juju/agents/unit-postgresql-test-app-0/charm/venv/ops/framework.py", line 943, in _reemit
    custom_handler(event)
  File "/var/lib/juju/agents/unit-postgresql-test-app-0/charm/./src/charm.py", line 289, in _on_clear_continuous_writes_action
    if self._connection_string is None:
  File "/var/lib/juju/agents/unit-postgresql-test-app-0/charm/./src/charm.py", line 259, in _connection_string
    data = list(self.first_database.fetch_relation_data().values())[0]
AttributeError: 'ApplicationCharm' object has no attribute 'first_database'
unit-postgresql-test-app-0: 02:07:25 ERROR unit.postgresql-test-app/0.juju-log Uncaught exception while in charm code:
Traceback (most recent call last):
  File "/var/lib/juju/agents/unit-postgresql-test-app-0/charm/./src/charm.py", line 538, in <module>
    main(ApplicationCharm)
  File "/var/lib/juju/agents/unit-postgresql-test-app-0/charm/venv/ops/main.py", line 553, in main
    manager.run()
  File "/var/lib/juju/agents/unit-postgresql-test-app-0/charm/venv/ops/main.py", line 529, in run
    self._emit()
  File "/var/lib/juju/agents/unit-postgresql-test-app-0/charm/venv/ops/main.py", line 518, in _emit
    _emit_charm_event(self.charm, self.dispatcher.event_name, self._juju_context)
  File "/var/lib/juju/agents/unit-postgresql-test-app-0/charm/venv/ops/main.py", line 139, in _emit_charm_event
    event_to_emit.emit(*args, **kwargs)
  File "/var/lib/juju/agents/unit-postgresql-test-app-0/charm/venv/ops/framework.py", line 347, in emit
    framework._emit(event)
  File "/var/lib/juju/agents/unit-postgresql-test-app-0/charm/venv/ops/framework.py", line 853, in _emit
    self._reemit(event_path)
  File "/var/lib/juju/agents/unit-postgresql-test-app-0/charm/venv/ops/framework.py", line 943, in _reemit
    custom_handler(event)
  File "/var/lib/juju/agents/unit-postgresql-test-app-0/charm/./src/charm.py", line 289, in _on_clear_continuous_writes_action
    if self._connection_string is None:
  File "/var/lib/juju/agents/unit-postgresql-test-app-0/charm/./src/charm.py", line 259, in _connection_string
    data = list(self.first_database.fetch_relation_data().values())[0]
AttributeError: 'ApplicationCharm' object has no attribute 'first_database'
unit-postgresql-test-app-0: 02:07:29 ERROR unit.postgresql-test-app/0.juju-log Uncaught exception while in charm code:
Traceback (most recent call last):
  File "/var/lib/juju/agents/unit-postgresql-test-app-0/charm/./src/charm.py", line 538, in <module>
    main(ApplicationCharm)
  File "/var/lib/juju/agents/unit-postgresql-test-app-0/charm/venv/ops/main.py", line 553, in main
    manager.run()
  File "/var/lib/juju/agents/unit-postgresql-test-app-0/charm/venv/ops/main.py", line 529, in run
    self._emit()
  File "/var/lib/juju/agents/unit-postgresql-test-app-0/charm/venv/ops/main.py", line 518, in _emit
    _emit_charm_event(self.charm, self.dispatcher.event_name, self._juju_context)
  File "/var/lib/juju/agents/unit-postgresql-test-app-0/charm/venv/ops/main.py", line 139, in _emit_charm_event
    event_to_emit.emit(*args, **kwargs)
  File "/var/lib/juju/agents/unit-postgresql-test-app-0/charm/venv/ops/framework.py", line 347, in emit
    framework._emit(event)
  File "/var/lib/juju/agents/unit-postgresql-test-app-0/charm/venv/ops/framework.py", line 853, in _emit
    self._reemit(event_path)
  File "/var/lib/juju/agents/unit-postgresql-test-app-0/charm/venv/ops/framework.py", line 943, in _reemit
    custom_handler(event)
  File "/var/lib/juju/agents/unit-postgresql-test-app-0/charm/./src/charm.py", line 289, in _on_clear_continuous_writes_action
    if self._connection_string is None:
  File "/var/lib/juju/agents/unit-postgresql-test-app-0/charm/./src/charm.py", line 259, in _connection_string
    data = list(self.first_database.fetch_relation_data().values())[0]
AttributeError: 'ApplicationCharm' object has no attribute 'first_database'
unit-postgresql-test-app-0: 02:07:34 ERROR unit.postgresql-test-app/0.juju-log Uncaught exception while in charm code:
Traceback (most recent call last):
  File "/var/lib/juju/agents/unit-postgresql-test-app-0/charm/./src/charm.py", line 538, in <module>
    main(ApplicationCharm)
  File "/var/lib/juju/agents/unit-postgresql-test-app-0/charm/venv/ops/main.py", line 553, in main
    manager.run()
  File "/var/lib/juju/agents/unit-postgresql-test-app-0/charm/venv/ops/main.py", line 529, in run
    self._emit()
  File "/var/lib/juju/agents/unit-postgresql-test-app-0/charm/venv/ops/main.py", line 518, in _emit
    _emit_charm_event(self.charm, self.dispatcher.event_name, self._juju_context)
  File "/var/lib/juju/agents/unit-postgresql-test-app-0/charm/venv/ops/main.py", line 139, in _emit_charm_event
    event_to_emit.emit(*args, **kwargs)
  File "/var/lib/juju/agents/unit-postgresql-test-app-0/charm/venv/ops/framework.py", line 347, in emit
    framework._emit(event)
  File "/var/lib/juju/agents/unit-postgresql-test-app-0/charm/venv/ops/framework.py", line 853, in _emit
    self._reemit(event_path)
  File "/var/lib/juju/agents/unit-postgresql-test-app-0/charm/venv/ops/framework.py", line 943, in _reemit
    custom_handler(event)
  File "/var/lib/juju/agents/unit-postgresql-test-app-0/charm/./src/charm.py", line 289, in _on_clear_continuous_writes_action
    if self._connection_string is None:
  File "/var/lib/juju/agents/unit-postgresql-test-app-0/charm/./src/charm.py", line 259, in _connection_string
    data = list(self.first_database.fetch_relation_data().values())[0]
AttributeError: 'ApplicationCharm' object has no attribute 'first_database'
unit-postgresql-test-app-0: 02:07:38 ERROR unit.postgresql-test-app/0.juju-log Uncaught exception while in charm code:
Traceback (most recent call last):
  File "/var/lib/juju/agents/unit-postgresql-test-app-0/charm/./src/charm.py", line 538, in <module>
    main(ApplicationCharm)
  File "/var/lib/juju/agents/unit-postgresql-test-app-0/charm/venv/ops/main.py", line 553, in main
    manager.run()
  File "/var/lib/juju/agents/unit-postgresql-test-app-0/charm/venv/ops/main.py", line 529, in run
    self._emit()
  File "/var/lib/juju/agents/unit-postgresql-test-app-0/charm/venv/ops/main.py", line 518, in _emit
    _emit_charm_event(self.charm, self.dispatcher.event_name, self._juju_context)
  File "/var/lib/juju/agents/unit-postgresql-test-app-0/charm/venv/ops/main.py", line 139, in _emit_charm_event
    event_to_emit.emit(*args, **kwargs)
  File "/var/lib/juju/agents/unit-postgresql-test-app-0/charm/venv/ops/framework.py", line 347, in emit
    framework._emit(event)
  File "/var/lib/juju/agents/unit-postgresql-test-app-0/charm/venv/ops/framework.py", line 853, in _emit
    self._reemit(event_path)
  File "/var/lib/juju/agents/unit-postgresql-test-app-0/charm/venv/ops/framework.py", line 943, in _reemit
    custom_handler(event)
  File "/var/lib/juju/agents/unit-postgresql-test-app-0/charm/./src/charm.py", line 289, in _on_clear_continuous_writes_action
    if self._connection_string is None:
  File "/var/lib/juju/agents/unit-postgresql-test-app-0/charm/./src/charm.py", line 259, in _connection_string
    data = list(self.first_database.fetch_relation_data().values())[0]
AttributeError: 'ApplicationCharm' object has no attribute 'first_database'
unit-postgresql-test-app-0: 02:07:42 ERROR unit.postgresql-test-app/0.juju-log Uncaught exception while in charm code:
Traceback (most recent call last):
  File "/var/lib/juju/agents/unit-postgresql-test-app-0/charm/./src/charm.py", line 538, in <module>
    main(ApplicationCharm)
  File "/var/lib/juju/agents/unit-postgresql-test-app-0/charm/venv/ops/main.py", line 553, in main
    manager.run()
  File "/var/lib/juju/agents/unit-postgresql-test-app-0/charm/venv/ops/main.py", line 529, in run
    self._emit()
  File "/var/lib/juju/agents/unit-postgresql-test-app-0/charm/venv/ops/main.py", line 518, in _emit
    _emit_charm_event(self.charm, self.dispatcher.event_name, self._juju_context)
  File "/var/lib/juju/agents/unit-postgresql-test-app-0/charm/venv/ops/main.py", line 139, in _emit_charm_event
    event_to_emit.emit(*args, **kwargs)
  File "/var/lib/juju/agents/unit-postgresql-test-app-0/charm/venv/ops/framework.py", line 347, in emit
    framework._emit(event)
  File "/var/lib/juju/agents/unit-postgresql-test-app-0/charm/venv/ops/framework.py", line 853, in _emit
    self._reemit(event_path)
  File "/var/lib/juju/agents/unit-postgresql-test-app-0/charm/venv/ops/framework.py", line 943, in _reemit
    custom_handler(event)
  File "/var/lib/juju/agents/unit-postgresql-test-app-0/charm/./src/charm.py", line 289, in _on_clear_continuous_writes_action
    if self._connection_string is None:
  File "/var/lib/juju/agents/unit-postgresql-test-app-0/charm/./src/charm.py", line 259, in _connection_string
    data = list(self.first_database.fetch_relation_data().values())[0]
AttributeError: 'ApplicationCharm' object has no attribute 'first_database'
unit-postgresql-test-app-0: 02:07:46 ERROR unit.postgresql-test-app/0.juju-log Uncaught exception while in charm code:
Traceback (most recent call last):
  File "/var/lib/juju/agents/unit-postgresql-test-app-0/charm/./src/charm.py", line 538, in <module>
    main(ApplicationCharm)
  File "/var/lib/juju/agents/unit-postgresql-test-app-0/charm/venv/ops/main.py", line 553, in main
    manager.run()
  File "/var/lib/juju/agents/unit-postgresql-test-app-0/charm/venv/ops/main.py", line 529, in run
    self._emit()
  File "/var/lib/juju/agents/unit-postgresql-test-app-0/charm/venv/ops/main.py", line 518, in _emit
    _emit_charm_event(self.charm, self.dispatcher.event_name, self._juju_context)
  File "/var/lib/juju/agents/unit-postgresql-test-app-0/charm/venv/ops/main.py", line 139, in _emit_charm_event
    event_to_emit.emit(*args, **kwargs)
  File "/var/lib/juju/agents/unit-postgresql-test-app-0/charm/venv/ops/framework.py", line 347, in emit
    framework._emit(event)
  File "/var/lib/juju/agents/unit-postgresql-test-app-0/charm/venv/ops/framework.py", line 853, in _emit
    self._reemit(event_path)
  File "/var/lib/juju/agents/unit-postgresql-test-app-0/charm/venv/ops/framework.py", line 943, in _reemit
    custom_handler(event)
  File "/var/lib/juju/agents/unit-postgresql-test-app-0/charm/./src/charm.py", line 289, in _on_clear_continuous_writes_action
    if self._connection_string is None:
  File "/var/lib/juju/agents/unit-postgresql-test-app-0/charm/./src/charm.py", line 259, in _connection_string
    data = list(self.first_database.fetch_relation_data().values())[0]
AttributeError: 'ApplicationCharm' object has no attribute 'first_database'
unit-postgresql-test-app-0: 02:07:50 ERROR unit.postgresql-test-app/0.juju-log Uncaught exception while in charm code:
Traceback (most recent call last):
  File "/var/lib/juju/agents/unit-postgresql-test-app-0/charm/./src/charm.py", line 538, in <module>
    main(ApplicationCharm)
  File "/var/lib/juju/agents/unit-postgresql-test-app-0/charm/venv/ops/main.py", line 553, in main
    manager.run()
  File "/var/lib/juju/agents/unit-postgresql-test-app-0/charm/venv/ops/main.py", line 529, in run
    self._emit()
  File "/var/lib/juju/agents/unit-postgresql-test-app-0/charm/venv/ops/main.py", line 518, in _emit
    _emit_charm_event(self.charm, self.dispatcher.event_name, self._juju_context)
  File "/var/lib/juju/agents/unit-postgresql-test-app-0/charm/venv/ops/main.py", line 139, in _emit_charm_event
    event_to_emit.emit(*args, **kwargs)
  File "/var/lib/juju/agents/unit-postgresql-test-app-0/charm/venv/ops/framework.py", line 347, in emit
    framework._emit(event)
  File "/var/lib/juju/agents/unit-postgresql-test-app-0/charm/venv/ops/framework.py", line 853, in _emit
    self._reemit(event_path)
  File "/var/lib/juju/agents/unit-postgresql-test-app-0/charm/venv/ops/framework.py", line 943, in _reemit
    custom_handler(event)
  File "/var/lib/juju/agents/unit-postgresql-test-app-0/charm/./src/charm.py", line 289, in _on_clear_continuous_writes_action
    if self._connection_string is None:
  File "/var/lib/juju/agents/unit-postgresql-test-app-0/charm/./src/charm.py", line 259, in _connection_string
    data = list(self.first_database.fetch_relation_data().values())[0]
AttributeError: 'ApplicationCharm' object has no attribute 'first_database'
unit-postgresql-test-app-0: 02:07:54 ERROR unit.postgresql-test-app/0.juju-log Uncaught exception while in charm code:
Traceback (most recent call last):
  File "/var/lib/juju/agents/unit-postgresql-test-app-0/charm/./src/charm.py", line 538, in <module>
    main(ApplicationCharm)
  File "/var/lib/juju/agents/unit-postgresql-test-app-0/charm/venv/ops/main.py", line 553, in main
    manager.run()
  File "/var/lib/juju/agents/unit-postgresql-test-app-0/charm/venv/ops/main.py", line 529, in run
    self._emit()
  File "/var/lib/juju/agents/unit-postgresql-test-app-0/charm/venv/ops/main.py", line 518, in _emit
    _emit_charm_event(self.charm, self.dispatcher.event_name, self._juju_context)
  File "/var/lib/juju/agents/unit-postgresql-test-app-0/charm/venv/ops/main.py", line 139, in _emit_charm_event
    event_to_emit.emit(*args, **kwargs)
  File "/var/lib/juju/agents/unit-postgresql-test-app-0/charm/venv/ops/framework.py", line 347, in emit
    framework._emit(event)
  File "/var/lib/juju/agents/unit-postgresql-test-app-0/charm/venv/ops/framework.py", line 853, in _emit
    self._reemit(event_path)
  File "/var/lib/juju/agents/unit-postgresql-test-app-0/charm/venv/ops/framework.py", line 943, in _reemit
    custom_handler(event)
  File "/var/lib/juju/agents/unit-postgresql-test-app-0/charm/./src/charm.py", line 289, in _on_clear_continuous_writes_action
    if self._connection_string is None:
  File "/var/lib/juju/agents/unit-postgresql-test-app-0/charm/./src/charm.py", line 259, in _connection_string
    data = list(self.first_database.fetch_relation_data().values())[0]
AttributeError: 'ApplicationCharm' object has no attribute 'first_database'
unit-postgresql-test-app-0: 02:07:58 ERROR unit.postgresql-test-app/0.juju-log Uncaught exception while in charm code:
Traceback (most recent call last):
  File "/var/lib/juju/agents/unit-postgresql-test-app-0/charm/./src/charm.py", line 538, in <module>
    main(ApplicationCharm)
  File "/var/lib/juju/agents/unit-postgresql-test-app-0/charm/venv/ops/main.py", line 553, in main
    manager.run()
  File "/var/lib/juju/agents/unit-postgresql-test-app-0/charm/venv/ops/main.py", line 529, in run
    self._emit()
  File "/var/lib/juju/agents/unit-postgresql-test-app-0/charm/venv/ops/main.py", line 518, in _emit
    _emit_charm_event(self.charm, self.dispatcher.event_name, self._juju_context)
  File "/var/lib/juju/agents/unit-postgresql-test-app-0/charm/venv/ops/main.py", line 139, in _emit_charm_event
    event_to_emit.emit(*args, **kwargs)
  File "/var/lib/juju/agents/unit-postgresql-test-app-0/charm/venv/ops/framework.py", line 347, in emit
    framework._emit(event)
  File "/var/lib/juju/agents/unit-postgresql-test-app-0/charm/venv/ops/framework.py", line 853, in _emit
    self._reemit(event_path)
  File "/var/lib/juju/agents/unit-postgresql-test-app-0/charm/venv/ops/framework.py", line 943, in _reemit
    custom_handler(event)
  File "/var/lib/juju/agents/unit-postgresql-test-app-0/charm/./src/charm.py", line 289, in _on_clear_continuous_writes_action
    if self._connection_string is None:
  File "/var/lib/juju/agents/unit-postgresql-test-app-0/charm/./src/charm.py", line 259, in _connection_string
    data = list(self.first_database.fetch_relation_data().values())[0]
AttributeError: 'ApplicationCharm' object has no attribute 'first_database'
unit-postgresql-test-app-0: 02:08:02 ERROR unit.postgresql-test-app/0.juju-log Uncaught exception while in charm code:
Traceback (most recent call last):
  File "/var/lib/juju/agents/unit-postgresql-test-app-0/charm/./src/charm.py", line 538, in <module>
    main(ApplicationCharm)
  File "/var/lib/juju/agents/unit-postgresql-test-app-0/charm/venv/ops/main.py", line 553, in main
    manager.run()
  File "/var/lib/juju/agents/unit-postgresql-test-app-0/charm/venv/ops/main.py", line 529, in run
    self._emit()
  File "/var/lib/juju/agents/unit-postgresql-test-app-0/charm/venv/ops/main.py", line 518, in _emit
    _emit_charm_event(self.charm, self.dispatcher.event_name, self._juju_context)
  File "/var/lib/juju/agents/unit-postgresql-test-app-0/charm/venv/ops/main.py", line 139, in _emit_charm_event
    event_to_emit.emit(*args, **kwargs)
  File "/var/lib/juju/agents/unit-postgresql-test-app-0/charm/venv/ops/framework.py", line 347, in emit
    framework._emit(event)
  File "/var/lib/juju/agents/unit-postgresql-test-app-0/charm/venv/ops/framework.py", line 853, in _emit
    self._reemit(event_path)
  File "/var/lib/juju/agents/unit-postgresql-test-app-0/charm/venv/ops/framework.py", line 943, in _reemit
    custom_handler(event)
  File "/var/lib/juju/agents/unit-postgresql-test-app-0/charm/./src/charm.py", line 289, in _on_clear_continuous_writes_action
    if self._connection_string is None:
  File "/var/lib/juju/agents/unit-postgresql-test-app-0/charm/./src/charm.py", line 259, in _connection_string
    data = list(self.first_database.fetch_relation_data().values())[0]
AttributeError: 'ApplicationCharm' object has no attribute 'first_database'
unit-postgresql-test-app-0: 02:08:06 ERROR unit.postgresql-test-app/0.juju-log Uncaught exception while in charm code:
Traceback (most recent call last):
  File "/var/lib/juju/agents/unit-postgresql-test-app-0/charm/./src/charm.py", line 538, in <module>
    main(ApplicationCharm)
  File "/var/lib/juju/agents/unit-postgresql-test-app-0/charm/venv/ops/main.py", line 553, in main
    manager.run()
  File "/var/lib/juju/agents/unit-postgresql-test-app-0/charm/venv/ops/main.py", line 529, in run
    self._emit()
  File "/var/lib/juju/agents/unit-postgresql-test-app-0/charm/venv/ops/main.py", line 518, in _emit
    _emit_charm_event(self.charm, self.dispatcher.event_name, self._juju_context)
  File "/var/lib/juju/agents/unit-postgresql-test-app-0/charm/venv/ops/main.py", line 139, in _emit_charm_event
    event_to_emit.emit(*args, **kwargs)
  File "/var/lib/juju/agents/unit-postgresql-test-app-0/charm/venv/ops/framework.py", line 347, in emit
    framework._emit(event)
  File "/var/lib/juju/agents/unit-postgresql-test-app-0/charm/venv/ops/framework.py", line 853, in _emit
    self._reemit(event_path)
  File "/var/lib/juju/agents/unit-postgresql-test-app-0/charm/venv/ops/framework.py", line 943, in _reemit
    custom_handler(event)
  File "/var/lib/juju/agents/unit-postgresql-test-app-0/charm/./src/charm.py", line 289, in _on_clear_continuous_writes_action
    if self._connection_string is None:
  File "/var/lib/juju/agents/unit-postgresql-test-app-0/charm/./src/charm.py", line 259, in _connection_string
    data = list(self.first_database.fetch_relation_data().values())[0]
AttributeError: 'ApplicationCharm' object has no attribute 'first_database'
unit-postgresql-test-app-0: 02:08:10 ERROR unit.postgresql-test-app/0.juju-log Uncaught exception while in charm code:
Traceback (most recent call last):
  File "/var/lib/juju/agents/unit-postgresql-test-app-0/charm/./src/charm.py", line 538, in <module>
    main(ApplicationCharm)
  File "/var/lib/juju/agents/unit-postgresql-test-app-0/charm/venv/ops/main.py", line 553, in main
    manager.run()
  File "/var/lib/juju/agents/unit-postgresql-test-app-0/charm/venv/ops/main.py", line 529, in run
    self._emit()
  File "/var/lib/juju/agents/unit-postgresql-test-app-0/charm/venv/ops/main.py", line 518, in _emit
    _emit_charm_event(self.charm, self.dispatcher.event_name, self._juju_context)
  File "/var/lib/juju/agents/unit-postgresql-test-app-0/charm/venv/ops/main.py", line 139, in _emit_charm_event
    event_to_emit.emit(*args, **kwargs)
  File "/var/lib/juju/agents/unit-postgresql-test-app-0/charm/venv/ops/framework.py", line 347, in emit
    framework._emit(event)
  File "/var/lib/juju/agents/unit-postgresql-test-app-0/charm/venv/ops/framework.py", line 853, in _emit
    self._reemit(event_path)
  File "/var/lib/juju/agents/unit-postgresql-test-app-0/charm/venv/ops/framework.py", line 943, in _reemit
    custom_handler(event)
  File "/var/lib/juju/agents/unit-postgresql-test-app-0/charm/./src/charm.py", line 289, in _on_clear_continuous_writes_action
    if self._connection_string is None:
  File "/var/lib/juju/agents/unit-postgresql-test-app-0/charm/./src/charm.py", line 259, in _connection_string
    data = list(self.first_database.fetch_relation_data().values())[0]
AttributeError: 'ApplicationCharm' object has no attribute 'first_database'
unit-postgresql-test-app-0: 02:08:14 ERROR unit.postgresql-test-app/0.juju-log Uncaught exception while in charm code:
Traceback (most recent call last):
  File "/var/lib/juju/agents/unit-postgresql-test-app-0/charm/./src/charm.py", line 538, in <module>
    main(ApplicationCharm)
  File "/var/lib/juju/agents/unit-postgresql-test-app-0/charm/venv/ops/main.py", line 553, in main
    manager.run()
  File "/var/lib/juju/agents/unit-postgresql-test-app-0/charm/venv/ops/main.py", line 529, in run
    self._emit()
  File "/var/lib/juju/agents/unit-postgresql-test-app-0/charm/venv/ops/main.py", line 518, in _emit
    _emit_charm_event(self.charm, self.dispatcher.event_name, self._juju_context)
  File "/var/lib/juju/agents/unit-postgresql-test-app-0/charm/venv/ops/main.py", line 139, in _emit_charm_event
    event_to_emit.emit(*args, **kwargs)
  File "/var/lib/juju/agents/unit-postgresql-test-app-0/charm/venv/ops/framework.py", line 347, in emit
    framework._emit(event)
  File "/var/lib/juju/agents/unit-postgresql-test-app-0/charm/venv/ops/framework.py", line 853, in _emit
    self._reemit(event_path)
  File "/var/lib/juju/agents/unit-postgresql-test-app-0/charm/venv/ops/framework.py", line 943, in _reemit
    custom_handler(event)
  File "/var/lib/juju/agents/unit-postgresql-test-app-0/charm/./src/charm.py", line 289, in _on_clear_continuous_writes_action
    if self._connection_string is None:
  File "/var/lib/juju/agents/unit-postgresql-test-app-0/charm/./src/charm.py", line 259, in _connection_string
    data = list(self.first_database.fetch_relation_data().values())[0]
AttributeError: 'ApplicationCharm' object has no attribute 'first_database'
unit-postgresql-test-app-0: 02:08:18 ERROR unit.postgresql-test-app/0.juju-log Uncaught exception while in charm code:
Traceback (most recent call last):
  File "/var/lib/juju/agents/unit-postgresql-test-app-0/charm/./src/charm.py", line 538, in <module>
    main(ApplicationCharm)
  File "/var/lib/juju/agents/unit-postgresql-test-app-0/charm/venv/ops/main.py", line 553, in main
    manager.run()
  File "/var/lib/juju/agents/unit-postgresql-test-app-0/charm/venv/ops/main.py", line 529, in run
    self._emit()
  File "/var/lib/juju/agents/unit-postgresql-test-app-0/charm/venv/ops/main.py", line 518, in _emit
    _emit_charm_event(self.charm, self.dispatcher.event_name, self._juju_context)
  File "/var/lib/juju/agents/unit-postgresql-test-app-0/charm/venv/ops/main.py", line 139, in _emit_charm_event
    event_to_emit.emit(*args, **kwargs)
  File "/var/lib/juju/agents/unit-postgresql-test-app-0/charm/venv/ops/framework.py", line 347, in emit
    framework._emit(event)
  File "/var/lib/juju/agents/unit-postgresql-test-app-0/charm/venv/ops/framework.py", line 853, in _emit
    self._reemit(event_path)
  File "/var/lib/juju/agents/unit-postgresql-test-app-0/charm/venv/ops/framework.py", line 943, in _reemit
    custom_handler(event)
  File "/var/lib/juju/agents/unit-postgresql-test-app-0/charm/./src/charm.py", line 289, in _on_clear_continuous_writes_action
    if self._connection_string is None:
  File "/var/lib/juju/agents/unit-postgresql-test-app-0/charm/./src/charm.py", line 259, in _connection_string
    data = list(self.first_database.fetch_relation_data().values())[0]
AttributeError: 'ApplicationCharm' object has no attribute 'first_database'
unit-postgresql-test-app-0: 02:08:22 ERROR unit.postgresql-test-app/0.juju-log Uncaught exception while in charm code:
Traceback (most recent call last):
  File "/var/lib/juju/agents/unit-postgresql-test-app-0/charm/./src/charm.py", line 538, in <module>
    main(ApplicationCharm)
  File "/var/lib/juju/agents/unit-postgresql-test-app-0/charm/venv/ops/main.py", line 553, in main
    manager.run()
  File "/var/lib/juju/agents/unit-postgresql-test-app-0/charm/venv/ops/main.py", line 529, in run
    self._emit()
  File "/var/lib/juju/agents/unit-postgresql-test-app-0/charm/venv/ops/main.py", line 518, in _emit
    _emit_charm_event(self.charm, self.dispatcher.event_name, self._juju_context)
  File "/var/lib/juju/agents/unit-postgresql-test-app-0/charm/venv/ops/main.py", line 139, in _emit_charm_event
    event_to_emit.emit(*args, **kwargs)
  File "/var/lib/juju/agents/unit-postgresql-test-app-0/charm/venv/ops/framework.py", line 347, in emit
    framework._emit(event)
  File "/var/lib/juju/agents/unit-postgresql-test-app-0/charm/venv/ops/framework.py", line 853, in _emit
    self._reemit(event_path)
  File "/var/lib/juju/agents/unit-postgresql-test-app-0/charm/venv/ops/framework.py", line 943, in _reemit
    custom_handler(event)
  File "/var/lib/juju/agents/unit-postgresql-test-app-0/charm/./src/charm.py", line 289, in _on_clear_continuous_writes_action
    if self._connection_string is None:
  File "/var/lib/juju/agents/unit-postgresql-test-app-0/charm/./src/charm.py", line 259, in _connection_string
    data = list(self.first_database.fetch_relation_data().values())[0]
AttributeError: 'ApplicationCharm' object has no attribute 'first_database'
unit-postgresql-test-app-0: 02:08:26 ERROR unit.postgresql-test-app/0.juju-log Uncaught exception while in charm code:
Traceback (most recent call last):
  File "/var/lib/juju/agents/unit-postgresql-test-app-0/charm/./src/charm.py", line 538, in <module>
    main(ApplicationCharm)
  File "/var/lib/juju/agents/unit-postgresql-test-app-0/charm/venv/ops/main.py", line 553, in main
    manager.run()
  File "/var/lib/juju/agents/unit-postgresql-test-app-0/charm/venv/ops/main.py", line 529, in run
    self._emit()
  File "/var/lib/juju/agents/unit-postgresql-test-app-0/charm/venv/ops/main.py", line 518, in _emit
    _emit_charm_event(self.charm, self.dispatcher.event_name, self._juju_context)
  File "/var/lib/juju/agents/unit-postgresql-test-app-0/charm/venv/ops/main.py", line 139, in _emit_charm_event
    event_to_emit.emit(*args, **kwargs)
  File "/var/lib/juju/agents/unit-postgresql-test-app-0/charm/venv/ops/framework.py", line 347, in emit
    framework._emit(event)
  File "/var/lib/juju/agents/unit-postgresql-test-app-0/charm/venv/ops/framework.py", line 853, in _emit
    self._reemit(event_path)
  File "/var/lib/juju/agents/unit-postgresql-test-app-0/charm/venv/ops/framework.py", line 943, in _reemit
    custom_handler(event)
  File "/var/lib/juju/agents/unit-postgresql-test-app-0/charm/./src/charm.py", line 289, in _on_clear_continuous_writes_action
    if self._connection_string is None:
  File "/var/lib/juju/agents/unit-postgresql-test-app-0/charm/./src/charm.py", line 259, in _connection_string
    data = list(self.first_database.fetch_relation_data().values())[0]
AttributeError: 'ApplicationCharm' object has no attribute 'first_database'
unit-postgresql-test-app-0: 02:08:30 ERROR unit.postgresql-test-app/0.juju-log Uncaught exception while in charm code:
Traceback (most recent call last):
  File "/var/lib/juju/agents/unit-postgresql-test-app-0/charm/./src/charm.py", line 538, in <module>
    main(ApplicationCharm)
  File "/var/lib/juju/agents/unit-postgresql-test-app-0/charm/venv/ops/main.py", line 553, in main
    manager.run()
  File "/var/lib/juju/agents/unit-postgresql-test-app-0/charm/venv/ops/main.py", line 529, in run
    self._emit()
  File "/var/lib/juju/agents/unit-postgresql-test-app-0/charm/venv/ops/main.py", line 518, in _emit
    _emit_charm_event(self.charm, self.dispatcher.event_name, self._juju_context)
  File "/var/lib/juju/agents/unit-postgresql-test-app-0/charm/venv/ops/main.py", line 139, in _emit_charm_event
    event_to_emit.emit(*args, **kwargs)
  File "/var/lib/juju/agents/unit-postgresql-test-app-0/charm/venv/ops/framework.py", line 347, in emit
    framework._emit(event)
  File "/var/lib/juju/agents/unit-postgresql-test-app-0/charm/venv/ops/framework.py", line 853, in _emit
    self._reemit(event_path)
  File "/var/lib/juju/agents/unit-postgresql-test-app-0/charm/venv/ops/framework.py", line 943, in _reemit
    custom_handler(event)
  File "/var/lib/juju/agents/unit-postgresql-test-app-0/charm/./src/charm.py", line 289, in _on_clear_continuous_writes_action
    if self._connection_string is None:
  File "/var/lib/juju/agents/unit-postgresql-test-app-0/charm/./src/charm.py", line 259, in _connection_string
    data = list(self.first_database.fetch_relation_data().values())[0]
AttributeError: 'ApplicationCharm' object has no attribute 'first_database'
unit-postgresql-test-app-0: 02:08:34 ERROR unit.postgresql-test-app/0.juju-log Uncaught exception while in charm code:
Traceback (most recent call last):
  File "/var/lib/juju/agents/unit-postgresql-test-app-0/charm/./src/charm.py", line 538, in <module>
    main(ApplicationCharm)
  File "/var/lib/juju/agents/unit-postgresql-test-app-0/charm/venv/ops/main.py", line 553, in main
    manager.run()
  File "/var/lib/juju/agents/unit-postgresql-test-app-0/charm/venv/ops/main.py", line 529, in run
    self._emit()
  File "/var/lib/juju/agents/unit-postgresql-test-app-0/charm/venv/ops/main.py", line 518, in _emit
    _emit_charm_event(self.charm, self.dispatcher.event_name, self._juju_context)
  File "/var/lib/juju/agents/unit-postgresql-test-app-0/charm/venv/ops/main.py", line 139, in _emit_charm_event
    event_to_emit.emit(*args, **kwargs)
  File "/var/lib/juju/agents/unit-postgresql-test-app-0/charm/venv/ops/framework.py", line 347, in emit
    framework._emit(event)
  File "/var/lib/juju/agents/unit-postgresql-test-app-0/charm/venv/ops/framework.py", line 853, in _emit
    self._reemit(event_path)
  File "/var/lib/juju/agents/unit-postgresql-test-app-0/charm/venv/ops/framework.py", line 943, in _reemit
    custom_handler(event)
  File "/var/lib/juju/agents/unit-postgresql-test-app-0/charm/./src/charm.py", line 289, in _on_clear_continuous_writes_action
    if self._connection_string is None:
  File "/var/lib/juju/agents/unit-postgresql-test-app-0/charm/./src/charm.py", line 259, in _connection_string
    data = list(self.first_database.fetch_relation_data().values())[0]
AttributeError: 'ApplicationCharm' object has no attribute 'first_database'
unit-postgresql-test-app-0: 02:08:38 ERROR unit.postgresql-test-app/0.juju-log Uncaught exception while in charm code:
Traceback (most recent call last):
  File "/var/lib/juju/agents/unit-postgresql-test-app-0/charm/./src/charm.py", line 538, in <module>
    main(ApplicationCharm)
  File "/var/lib/juju/agents/unit-postgresql-test-app-0/charm/venv/ops/main.py", line 553, in main
    manager.run()
  File "/var/lib/juju/agents/unit-postgresql-test-app-0/charm/venv/ops/main.py", line 529, in run
    self._emit()
  File "/var/lib/juju/agents/unit-postgresql-test-app-0/charm/venv/ops/main.py", line 518, in _emit
    _emit_charm_event(self.charm, self.dispatcher.event_name, self._juju_context)
  File "/var/lib/juju/agents/unit-postgresql-test-app-0/charm/venv/ops/main.py", line 139, in _emit_charm_event
    event_to_emit.emit(*args, **kwargs)
  File "/var/lib/juju/agents/unit-postgresql-test-app-0/charm/venv/ops/framework.py", line 347, in emit
    framework._emit(event)
  File "/var/lib/juju/agents/unit-postgresql-test-app-0/charm/venv/ops/framework.py", line 853, in _emit
    self._reemit(event_path)
  File "/var/lib/juju/agents/unit-postgresql-test-app-0/charm/venv/ops/framework.py", line 943, in _reemit
    custom_handler(event)
  File "/var/lib/juju/agents/unit-postgresql-test-app-0/charm/./src/charm.py", line 289, in _on_clear_continuous_writes_action
    if self._connection_string is None:
  File "/var/lib/juju/agents/unit-postgresql-test-app-0/charm/./src/charm.py", line 259, in _connection_string
    data = list(self.first_database.fetch_relation_data().values())[0]
AttributeError: 'ApplicationCharm' object has no attribute 'first_database'
unit-postgresql-test-app-0: 02:08:42 ERROR unit.postgresql-test-app/0.juju-log Uncaught exception while in charm code:
Traceback (most recent call last):
  File "/var/lib/juju/agents/unit-postgresql-test-app-0/charm/./src/charm.py", line 538, in <module>
    main(ApplicationCharm)
  File "/var/lib/juju/agents/unit-postgresql-test-app-0/charm/venv/ops/main.py", line 553, in main
    manager.run()
  File "/var/lib/juju/agents/unit-postgresql-test-app-0/charm/venv/ops/main.py", line 529, in run
    self._emit()
  File "/var/lib/juju/agents/unit-postgresql-test-app-0/charm/venv/ops/main.py", line 518, in _emit
    _emit_charm_event(self.charm, self.dispatcher.event_name, self._juju_context)
  File "/var/lib/juju/agents/unit-postgresql-test-app-0/charm/venv/ops/main.py", line 139, in _emit_charm_event
    event_to_emit.emit(*args, **kwargs)
  File "/var/lib/juju/agents/unit-postgresql-test-app-0/charm/venv/ops/framework.py", line 347, in emit
    framework._emit(event)
  File "/var/lib/juju/agents/unit-postgresql-test-app-0/charm/venv/ops/framework.py", line 853, in _emit
    self._reemit(event_path)
  File "/var/lib/juju/agents/unit-postgresql-test-app-0/charm/venv/ops/framework.py", line 943, in _reemit
    custom_handler(event)
  File "/var/lib/juju/agents/unit-postgresql-test-app-0/charm/./src/charm.py", line 289, in _on_clear_continuous_writes_action
    if self._connection_string is None:
  File "/var/lib/juju/agents/unit-postgresql-test-app-0/charm/./src/charm.py", line 259, in _connection_string
    data = list(self.first_database.fetch_relation_data().values())[0]
AttributeError: 'ApplicationCharm' object has no attribute 'first_database'
unit-postgresql-test-app-0: 02:08:46 ERROR unit.postgresql-test-app/0.juju-log Uncaught exception while in charm code:
Traceback (most recent call last):
  File "/var/lib/juju/agents/unit-postgresql-test-app-0/charm/./src/charm.py", line 538, in <module>
    main(ApplicationCharm)
  File "/var/lib/juju/agents/unit-postgresql-test-app-0/charm/venv/ops/main.py", line 553, in main
    manager.run()
  File "/var/lib/juju/agents/unit-postgresql-test-app-0/charm/venv/ops/main.py", line 529, in run
    self._emit()
  File "/var/lib/juju/agents/unit-postgresql-test-app-0/charm/venv/ops/main.py", line 518, in _emit
    _emit_charm_event(self.charm, self.dispatcher.event_name, self._juju_context)
  File "/var/lib/juju/agents/unit-postgresql-test-app-0/charm/venv/ops/main.py", line 139, in _emit_charm_event
    event_to_emit.emit(*args, **kwargs)
  File "/var/lib/juju/agents/unit-postgresql-test-app-0/charm/venv/ops/framework.py", line 347, in emit
    framework._emit(event)
  File "/var/lib/juju/agents/unit-postgresql-test-app-0/charm/venv/ops/framework.py", line 853, in _emit
    self._reemit(event_path)
  File "/var/lib/juju/agents/unit-postgresql-test-app-0/charm/venv/ops/framework.py", line 943, in _reemit
    custom_handler(event)
  File "/var/lib/juju/agents/unit-postgresql-test-app-0/charm/./src/charm.py", line 289, in _on_clear_continuous_writes_action
    if self._connection_string is None:
  File "/var/lib/juju/agents/unit-postgresql-test-app-0/charm/./src/charm.py", line 259, in _connection_string
    data = list(self.first_database.fetch_relation_data().values())[0]
AttributeError: 'ApplicationCharm' object has no attribute 'first_database'
unit-postgresql-test-app-0: 02:08:50 ERROR unit.postgresql-test-app/0.juju-log Uncaught exception while in charm code:
Traceback (most recent call last):
  File "/var/lib/juju/agents/unit-postgresql-test-app-0/charm/./src/charm.py", line 538, in <module>
    main(ApplicationCharm)
  File "/var/lib/juju/agents/unit-postgresql-test-app-0/charm/venv/ops/main.py", line 553, in main
    manager.run()
  File "/var/lib/juju/agents/unit-postgresql-test-app-0/charm/venv/ops/main.py", line 529, in run
    self._emit()
  File "/var/lib/juju/agents/unit-postgresql-test-app-0/charm/venv/ops/main.py", line 518, in _emit
    _emit_charm_event(self.charm, self.dispatcher.event_name, self._juju_context)
  File "/var/lib/juju/agents/unit-postgresql-test-app-0/charm/venv/ops/main.py", line 139, in _emit_charm_event
    event_to_emit.emit(*args, **kwargs)
  File "/var/lib/juju/agents/unit-postgresql-test-app-0/charm/venv/ops/framework.py", line 347, in emit
    framework._emit(event)
  File "/var/lib/juju/agents/unit-postgresql-test-app-0/charm/venv/ops/framework.py", line 853, in _emit
    self._reemit(event_path)
  File "/var/lib/juju/agents/unit-postgresql-test-app-0/charm/venv/ops/framework.py", line 943, in _reemit
    custom_handler(event)
  File "/var/lib/juju/agents/unit-postgresql-test-app-0/charm/./src/charm.py", line 289, in _on_clear_continuous_writes_action
    if self._connection_string is None:
  File "/var/lib/juju/agents/unit-postgresql-test-app-0/charm/./src/charm.py", line 259, in _connection_string
    data = list(self.first_database.fetch_relation_data().values())[0]
AttributeError: 'ApplicationCharm' object has no attribute 'first_database'
unit-postgresql-test-app-0: 02:08:54 ERROR unit.postgresql-test-app/0.juju-log Uncaught exception while in charm code:
Traceback (most recent call last):
  File "/var/lib/juju/agents/unit-postgresql-test-app-0/charm/./src/charm.py", line 538, in <module>
    main(ApplicationCharm)
  File "/var/lib/juju/agents/unit-postgresql-test-app-0/charm/venv/ops/main.py", line 553, in main
    manager.run()
  File "/var/lib/juju/agents/unit-postgresql-test-app-0/charm/venv/ops/main.py", line 529, in run
    self._emit()
  File "/var/lib/juju/agents/unit-postgresql-test-app-0/charm/venv/ops/main.py", line 518, in _emit
    _emit_charm_event(self.charm, self.dispatcher.event_name, self._juju_context)
  File "/var/lib/juju/agents/unit-postgresql-test-app-0/charm/venv/ops/main.py", line 139, in _emit_charm_event
    event_to_emit.emit(*args, **kwargs)
  File "/var/lib/juju/agents/unit-postgresql-test-app-0/charm/venv/ops/framework.py", line 347, in emit
    framework._emit(event)
  File "/var/lib/juju/agents/unit-postgresql-test-app-0/charm/venv/ops/framework.py", line 853, in _emit
    self._reemit(event_path)
  File "/var/lib/juju/agents/unit-postgresql-test-app-0/charm/venv/ops/framework.py", line 943, in _reemit
    custom_handler(event)
  File "/var/lib/juju/agents/unit-postgresql-test-app-0/charm/./src/charm.py", line 289, in _on_clear_continuous_writes_action
    if self._connection_string is None:
  File "/var/lib/juju/agents/unit-postgresql-test-app-0/charm/./src/charm.py", line 259, in _connection_string
    data = list(self.first_database.fetch_relation_data().values())[0]
AttributeError: 'ApplicationCharm' object has no attribute 'first_database'
unit-postgresql-test-app-0: 02:08:58 ERROR unit.postgresql-test-app/0.juju-log Uncaught exception while in charm code:
Traceback (most recent call last):
  File "/var/lib/juju/agents/unit-postgresql-test-app-0/charm/./src/charm.py", line 538, in <module>
    main(ApplicationCharm)
  File "/var/lib/juju/agents/unit-postgresql-test-app-0/charm/venv/ops/main.py", line 553, in main
    manager.run()
  File "/var/lib/juju/agents/unit-postgresql-test-app-0/charm/venv/ops/main.py", line 529, in run
    self._emit()
  File "/var/lib/juju/agents/unit-postgresql-test-app-0/charm/venv/ops/main.py", line 518, in _emit
    _emit_charm_event(self.charm, self.dispatcher.event_name, self._juju_context)
  File "/var/lib/juju/agents/unit-postgresql-test-app-0/charm/venv/ops/main.py", line 139, in _emit_charm_event
    event_to_emit.emit(*args, **kwargs)
  File "/var/lib/juju/agents/unit-postgresql-test-app-0/charm/venv/ops/framework.py", line 347, in emit
    framework._emit(event)
  File "/var/lib/juju/agents/unit-postgresql-test-app-0/charm/venv/ops/framework.py", line 853, in _emit
    self._reemit(event_path)
  File "/var/lib/juju/agents/unit-postgresql-test-app-0/charm/venv/ops/framework.py", line 943, in _reemit
    custom_handler(event)
  File "/var/lib/juju/agents/unit-postgresql-test-app-0/charm/./src/charm.py", line 289, in _on_clear_continuous_writes_action
    if self._connection_string is None:
  File "/var/lib/juju/agents/unit-postgresql-test-app-0/charm/./src/charm.py", line 259, in _connection_string
    data = list(self.first_database.fetch_relation_data().values())[0]
AttributeError: 'ApplicationCharm' object has no attribute 'first_database'
unit-postgresql-test-app-0: 02:09:02 ERROR unit.postgresql-test-app/0.juju-log Uncaught exception while in charm code:
Traceback (most recent call last):
  File "/var/lib/juju/agents/unit-postgresql-test-app-0/charm/./src/charm.py", line 538, in <module>
    main(ApplicationCharm)
  File "/var/lib/juju/agents/unit-postgresql-test-app-0/charm/venv/ops/main.py", line 553, in main
    manager.run()
  File "/var/lib/juju/agents/unit-postgresql-test-app-0/charm/venv/ops/main.py", line 529, in run
    self._emit()
  File "/var/lib/juju/agents/unit-postgresql-test-app-0/charm/venv/ops/main.py", line 518, in _emit
    _emit_charm_event(self.charm, self.dispatcher.event_name, self._juju_context)
  File "/var/lib/juju/agents/unit-postgresql-test-app-0/charm/venv/ops/main.py", line 139, in _emit_charm_event
    event_to_emit.emit(*args, **kwargs)
  File "/var/lib/juju/agents/unit-postgresql-test-app-0/charm/venv/ops/framework.py", line 347, in emit
    framework._emit(event)
  File "/var/lib/juju/agents/unit-postgresql-test-app-0/charm/venv/ops/framework.py", line 853, in _emit
    self._reemit(event_path)
  File "/var/lib/juju/agents/unit-postgresql-test-app-0/charm/venv/ops/framework.py", line 943, in _reemit
    custom_handler(event)
  File "/var/lib/juju/agents/unit-postgresql-test-app-0/charm/./src/charm.py", line 289, in _on_clear_continuous_writes_action
    if self._connection_string is None:
  File "/var/lib/juju/agents/unit-postgresql-test-app-0/charm/./src/charm.py", line 259, in _connection_string
    data = list(self.first_database.fetch_relation_data().values())[0]
AttributeError: 'ApplicationCharm' object has no attribute 'first_database'
unit-postgresql-test-app-0: 02:09:06 ERROR unit.postgresql-test-app/0.juju-log Uncaught exception while in charm code:
Traceback (most recent call last):
  File "/var/lib/juju/agents/unit-postgresql-test-app-0/charm/./src/charm.py", line 538, in <module>
    main(ApplicationCharm)
  File "/var/lib/juju/agents/unit-postgresql-test-app-0/charm/venv/ops/main.py", line 553, in main
    manager.run()
  File "/var/lib/juju/agents/unit-postgresql-test-app-0/charm/venv/ops/main.py", line 529, in run
    self._emit()
  File "/var/lib/juju/agents/unit-postgresql-test-app-0/charm/venv/ops/main.py", line 518, in _emit
    _emit_charm_event(self.charm, self.dispatcher.event_name, self._juju_context)
  File "/var/lib/juju/agents/unit-postgresql-test-app-0/charm/venv/ops/main.py", line 139, in _emit_charm_event
    event_to_emit.emit(*args, **kwargs)
  File "/var/lib/juju/agents/unit-postgresql-test-app-0/charm/venv/ops/framework.py", line 347, in emit
    framework._emit(event)
  File "/var/lib/juju/agents/unit-postgresql-test-app-0/charm/venv/ops/framework.py", line 853, in _emit
    self._reemit(event_path)
  File "/var/lib/juju/agents/unit-postgresql-test-app-0/charm/venv/ops/framework.py", line 943, in _reemit
    custom_handler(event)
  File "/var/lib/juju/agents/unit-postgresql-test-app-0/charm/./src/charm.py", line 289, in _on_clear_continuous_writes_action
    if self._connection_string is None:
  File "/var/lib/juju/agents/unit-postgresql-test-app-0/charm/./src/charm.py", line 259, in _connection_string
    data = list(self.first_database.fetch_relation_data().values())[0]
AttributeError: 'ApplicationCharm' object has no attribute 'first_database'
unit-postgresql-test-app-0: 02:09:10 ERROR unit.postgresql-test-app/0.juju-log Uncaught exception while in charm code:
Traceback (most recent call last):
  File "/var/lib/juju/agents/unit-postgresql-test-app-0/charm/./src/charm.py", line 538, in <module>
    main(ApplicationCharm)
  File "/var/lib/juju/agents/unit-postgresql-test-app-0/charm/venv/ops/main.py", line 553, in main
    manager.run()
  File "/var/lib/juju/agents/unit-postgresql-test-app-0/charm/venv/ops/main.py", line 529, in run
    self._emit()
  File "/var/lib/juju/agents/unit-postgresql-test-app-0/charm/venv/ops/main.py", line 518, in _emit
    _emit_charm_event(self.charm, self.dispatcher.event_name, self._juju_context)
  File "/var/lib/juju/agents/unit-postgresql-test-app-0/charm/venv/ops/main.py", line 139, in _emit_charm_event
    event_to_emit.emit(*args, **kwargs)
  File "/var/lib/juju/agents/unit-postgresql-test-app-0/charm/venv/ops/framework.py", line 347, in emit
    framework._emit(event)
  File "/var/lib/juju/agents/unit-postgresql-test-app-0/charm/venv/ops/framework.py", line 853, in _emit
    self._reemit(event_path)
  File "/var/lib/juju/agents/unit-postgresql-test-app-0/charm/venv/ops/framework.py", line 943, in _reemit
    custom_handler(event)
  File "/var/lib/juju/agents/unit-postgresql-test-app-0/charm/./src/charm.py", line 289, in _on_clear_continuous_writes_action
    if self._connection_string is None:
  File "/var/lib/juju/agents/unit-postgresql-test-app-0/charm/./src/charm.py", line 259, in _connection_string
    data = list(self.first_database.fetch_relation_data().values())[0]
AttributeError: 'ApplicationCharm' object has no attribute 'first_database'
unit-postgresql-test-app-0: 02:09:14 ERROR unit.postgresql-test-app/0.juju-log Uncaught exception while in charm code:
Traceback (most recent call last):
  File "/var/lib/juju/agents/unit-postgresql-test-app-0/charm/./src/charm.py", line 538, in <module>
    main(ApplicationCharm)
  File "/var/lib/juju/agents/unit-postgresql-test-app-0/charm/venv/ops/main.py", line 553, in main
    manager.run()
  File "/var/lib/juju/agents/unit-postgresql-test-app-0/charm/venv/ops/main.py", line 529, in run
    self._emit()
  File "/var/lib/juju/agents/unit-postgresql-test-app-0/charm/venv/ops/main.py", line 518, in _emit
    _emit_charm_event(self.charm, self.dispatcher.event_name, self._juju_context)
  File "/var/lib/juju/agents/unit-postgresql-test-app-0/charm/venv/ops/main.py", line 139, in _emit_charm_event
    event_to_emit.emit(*args, **kwargs)
  File "/var/lib/juju/agents/unit-postgresql-test-app-0/charm/venv/ops/framework.py", line 347, in emit
    framework._emit(event)
  File "/var/lib/juju/agents/unit-postgresql-test-app-0/charm/venv/ops/framework.py", line 853, in _emit
    self._reemit(event_path)
  File "/var/lib/juju/agents/unit-postgresql-test-app-0/charm/venv/ops/framework.py", line 943, in _reemit
    custom_handler(event)
  File "/var/lib/juju/agents/unit-postgresql-test-app-0/charm/./src/charm.py", line 289, in _on_clear_continuous_writes_action
    if self._connection_string is None:
  File "/var/lib/juju/agents/unit-postgresql-test-app-0/charm/./src/charm.py", line 259, in _connection_string
    data = list(self.first_database.fetch_relation_data().values())[0]
AttributeError: 'ApplicationCharm' object has no attribute 'first_database'
unit-postgresql-test-app-0: 02:09:18 ERROR unit.postgresql-test-app/0.juju-log Uncaught exception while in charm code:
Traceback (most recent call last):
  File "/var/lib/juju/agents/unit-postgresql-test-app-0/charm/./src/charm.py", line 538, in <module>
    main(ApplicationCharm)
  File "/var/lib/juju/agents/unit-postgresql-test-app-0/charm/venv/ops/main.py", line 553, in main
    manager.run()
  File "/var/lib/juju/agents/unit-postgresql-test-app-0/charm/venv/ops/main.py", line 529, in run
    self._emit()
  File "/var/lib/juju/agents/unit-postgresql-test-app-0/charm/venv/ops/main.py", line 518, in _emit
    _emit_charm_event(self.charm, self.dispatcher.event_name, self._juju_context)
  File "/var/lib/juju/agents/unit-postgresql-test-app-0/charm/venv/ops/main.py", line 139, in _emit_charm_event
    event_to_emit.emit(*args, **kwargs)
  File "/var/lib/juju/agents/unit-postgresql-test-app-0/charm/venv/ops/framework.py", line 347, in emit
    framework._emit(event)
  File "/var/lib/juju/agents/unit-postgresql-test-app-0/charm/venv/ops/framework.py", line 853, in _emit
    self._reemit(event_path)
  File "/var/lib/juju/agents/unit-postgresql-test-app-0/charm/venv/ops/framework.py", line 943, in _reemit
    custom_handler(event)
  File "/var/lib/juju/agents/unit-postgresql-test-app-0/charm/./src/charm.py", line 289, in _on_clear_continuous_writes_action
    if self._connection_string is None:
  File "/var/lib/juju/agents/unit-postgresql-test-app-0/charm/./src/charm.py", line 259, in _connection_string
    data = list(self.first_database.fetch_relation_data().values())[0]
AttributeError: 'ApplicationCharm' object has no attribute 'first_database'
unit-postgresql-test-app-0: 02:09:22 ERROR unit.postgresql-test-app/0.juju-log Uncaught exception while in charm code:
Traceback (most recent call last):
  File "/var/lib/juju/agents/unit-postgresql-test-app-0/charm/./src/charm.py", line 538, in <module>
    main(ApplicationCharm)
  File "/var/lib/juju/agents/unit-postgresql-test-app-0/charm/venv/ops/main.py", line 553, in main
    manager.run()
  File "/var/lib/juju/agents/unit-postgresql-test-app-0/charm/venv/ops/main.py", line 529, in run
    self._emit()
  File "/var/lib/juju/agents/unit-postgresql-test-app-0/charm/venv/ops/main.py", line 518, in _emit
    _emit_charm_event(self.charm, self.dispatcher.event_name, self._juju_context)
  File "/var/lib/juju/agents/unit-postgresql-test-app-0/charm/venv/ops/main.py", line 139, in _emit_charm_event
    event_to_emit.emit(*args, **kwargs)
  File "/var/lib/juju/agents/unit-postgresql-test-app-0/charm/venv/ops/framework.py", line 347, in emit
    framework._emit(event)
  File "/var/lib/juju/agents/unit-postgresql-test-app-0/charm/venv/ops/framework.py", line 853, in _emit
    self._reemit(event_path)
  File "/var/lib/juju/agents/unit-postgresql-test-app-0/charm/venv/ops/framework.py", line 943, in _reemit
    custom_handler(event)
  File "/var/lib/juju/agents/unit-postgresql-test-app-0/charm/./src/charm.py", line 289, in _on_clear_continuous_writes_action
    if self._connection_string is None:
  File "/var/lib/juju/agents/unit-postgresql-test-app-0/charm/./src/charm.py", line 259, in _connection_string
    data = list(self.first_database.fetch_relation_data().values())[0]
AttributeError: 'ApplicationCharm' object has no attribute 'first_database'
unit-postgresql-test-app-0: 02:09:26 ERROR unit.postgresql-test-app/0.juju-log Uncaught exception while in charm code:
Traceback (most recent call last):
  File "/var/lib/juju/agents/unit-postgresql-test-app-0/charm/./src/charm.py", line 538, in <module>
    main(ApplicationCharm)
  File "/var/lib/juju/agents/unit-postgresql-test-app-0/charm/venv/ops/main.py", line 553, in main
    manager.run()
  File "/var/lib/juju/agents/unit-postgresql-test-app-0/charm/venv/ops/main.py", line 529, in run
    self._emit()
  File "/var/lib/juju/agents/unit-postgresql-test-app-0/charm/venv/ops/main.py", line 518, in _emit
    _emit_charm_event(self.charm, self.dispatcher.event_name, self._juju_context)
  File "/var/lib/juju/agents/unit-postgresql-test-app-0/charm/venv/ops/main.py", line 139, in _emit_charm_event
    event_to_emit.emit(*args, **kwargs)
  File "/var/lib/juju/agents/unit-postgresql-test-app-0/charm/venv/ops/framework.py", line 347, in emit
    framework._emit(event)
  File "/var/lib/juju/agents/unit-postgresql-test-app-0/charm/venv/ops/framework.py", line 853, in _emit
    self._reemit(event_path)
  File "/var/lib/juju/agents/unit-postgresql-test-app-0/charm/venv/ops/framework.py", line 943, in _reemit
    custom_handler(event)
  File "/var/lib/juju/agents/unit-postgresql-test-app-0/charm/./src/charm.py", line 289, in _on_clear_continuous_writes_action
    if self._connection_string is None:
  File "/var/lib/juju/agents/unit-postgresql-test-app-0/charm/./src/charm.py", line 259, in _connection_string
    data = list(self.first_database.fetch_relation_data().values())[0]
AttributeError: 'ApplicationCharm' object has no attribute 'first_database'
unit-postgresql-test-app-0: 02:09:30 ERROR unit.postgresql-test-app/0.juju-log Uncaught exception while in charm code:
Traceback (most recent call last):
  File "/var/lib/juju/agents/unit-postgresql-test-app-0/charm/./src/charm.py", line 538, in <module>
    main(ApplicationCharm)
  File "/var/lib/juju/agents/unit-postgresql-test-app-0/charm/venv/ops/main.py", line 553, in main
    manager.run()
  File "/var/lib/juju/agents/unit-postgresql-test-app-0/charm/venv/ops/main.py", line 529, in run
    self._emit()
  File "/var/lib/juju/agents/unit-postgresql-test-app-0/charm/venv/ops/main.py", line 518, in _emit
    _emit_charm_event(self.charm, self.dispatcher.event_name, self._juju_context)
  File "/var/lib/juju/agents/unit-postgresql-test-app-0/charm/venv/ops/main.py", line 139, in _emit_charm_event
    event_to_emit.emit(*args, **kwargs)
  File "/var/lib/juju/agents/unit-postgresql-test-app-0/charm/venv/ops/framework.py", line 347, in emit
    framework._emit(event)
  File "/var/lib/juju/agents/unit-postgresql-test-app-0/charm/venv/ops/framework.py", line 853, in _emit
    self._reemit(event_path)
  File "/var/lib/juju/agents/unit-postgresql-test-app-0/charm/venv/ops/framework.py", line 943, in _reemit
    custom_handler(event)
  File "/var/lib/juju/agents/unit-postgresql-test-app-0/charm/./src/charm.py", line 289, in _on_clear_continuous_writes_action
    if self._connection_string is None:
  File "/var/lib/juju/agents/unit-postgresql-test-app-0/charm/./src/charm.py", line 259, in _connection_string
    data = list(self.first_database.fetch_relation_data().values())[0]
AttributeError: 'ApplicationCharm' object has no attribute 'first_database'
unit-postgresql-test-app-0: 02:09:34 ERROR unit.postgresql-test-app/0.juju-log Uncaught exception while in charm code:
Traceback (most recent call last):
  File "/var/lib/juju/agents/unit-postgresql-test-app-0/charm/./src/charm.py", line 538, in <module>
    main(ApplicationCharm)
  File "/var/lib/juju/agents/unit-postgresql-test-app-0/charm/venv/ops/main.py", line 553, in main
    manager.run()
  File "/var/lib/juju/agents/unit-postgresql-test-app-0/charm/venv/ops/main.py", line 529, in run
    self._emit()
  File "/var/lib/juju/agents/unit-postgresql-test-app-0/charm/venv/ops/main.py", line 518, in _emit
    _emit_charm_event(self.charm, self.dispatcher.event_name, self._juju_context)
  File "/var/lib/juju/agents/unit-postgresql-test-app-0/charm/venv/ops/main.py", line 139, in _emit_charm_event
    event_to_emit.emit(*args, **kwargs)
  File "/var/lib/juju/agents/unit-postgresql-test-app-0/charm/venv/ops/framework.py", line 347, in emit
    framework._emit(event)
  File "/var/lib/juju/agents/unit-postgresql-test-app-0/charm/venv/ops/framework.py", line 853, in _emit
    self._reemit(event_path)
  File "/var/lib/juju/agents/unit-postgresql-test-app-0/charm/venv/ops/framework.py", line 943, in _reemit
    custom_handler(event)
  File "/var/lib/juju/agents/unit-postgresql-test-app-0/charm/./src/charm.py", line 289, in _on_clear_continuous_writes_action
    if self._connection_string is None:
  File "/var/lib/juju/agents/unit-postgresql-test-app-0/charm/./src/charm.py", line 259, in _connection_string
    data = list(self.first_database.fetch_relation_data().values())[0]
AttributeError: 'ApplicationCharm' object has no attribute 'first_database'
unit-postgresql-test-app-0: 02:09:39 ERROR unit.postgresql-test-app/0.juju-log Uncaught exception while in charm code:
Traceback (most recent call last):
  File "/var/lib/juju/agents/unit-postgresql-test-app-0/charm/./src/charm.py", line 538, in <module>
    main(ApplicationCharm)
  File "/var/lib/juju/agents/unit-postgresql-test-app-0/charm/venv/ops/main.py", line 553, in main
    manager.run()
  File "/var/lib/juju/agents/unit-postgresql-test-app-0/charm/venv/ops/main.py", line 529, in run
    self._emit()
  File "/var/lib/juju/agents/unit-postgresql-test-app-0/charm/venv/ops/main.py", line 518, in _emit
    _emit_charm_event(self.charm, self.dispatcher.event_name, self._juju_context)
  File "/var/lib/juju/agents/unit-postgresql-test-app-0/charm/venv/ops/main.py", line 139, in _emit_charm_event
    event_to_emit.emit(*args, **kwargs)
  File "/var/lib/juju/agents/unit-postgresql-test-app-0/charm/venv/ops/framework.py", line 347, in emit
    framework._emit(event)
  File "/var/lib/juju/agents/unit-postgresql-test-app-0/charm/venv/ops/framework.py", line 853, in _emit
    self._reemit(event_path)
  File "/var/lib/juju/agents/unit-postgresql-test-app-0/charm/venv/ops/framework.py", line 943, in _reemit
    custom_handler(event)
  File "/var/lib/juju/agents/unit-postgresql-test-app-0/charm/./src/charm.py", line 289, in _on_clear_continuous_writes_action
    if self._connection_string is None:
  File "/var/lib/juju/agents/unit-postgresql-test-app-0/charm/./src/charm.py", line 259, in _connection_string
    data = list(self.first_database.fetch_relation_data().values())[0]
AttributeError: 'ApplicationCharm' object has no attribute 'first_database'
unit-postgresql-test-app-0: 02:09:43 ERROR unit.postgresql-test-app/0.juju-log Uncaught exception while in charm code:
Traceback (most recent call last):
  File "/var/lib/juju/agents/unit-postgresql-test-app-0/charm/./src/charm.py", line 538, in <module>
    main(ApplicationCharm)
  File "/var/lib/juju/agents/unit-postgresql-test-app-0/charm/venv/ops/main.py", line 553, in main
    manager.run()
  File "/var/lib/juju/agents/unit-postgresql-test-app-0/charm/venv/ops/main.py", line 529, in run
    self._emit()
  File "/var/lib/juju/agents/unit-postgresql-test-app-0/charm/venv/ops/main.py", line 518, in _emit
    _emit_charm_event(self.charm, self.dispatcher.event_name, self._juju_context)
  File "/var/lib/juju/agents/unit-postgresql-test-app-0/charm/venv/ops/main.py", line 139, in _emit_charm_event
    event_to_emit.emit(*args, **kwargs)
  File "/var/lib/juju/agents/unit-postgresql-test-app-0/charm/venv/ops/framework.py", line 347, in emit
    framework._emit(event)
  File "/var/lib/juju/agents/unit-postgresql-test-app-0/charm/venv/ops/framework.py", line 853, in _emit
    self._reemit(event_path)
  File "/var/lib/juju/agents/unit-postgresql-test-app-0/charm/venv/ops/framework.py", line 943, in _reemit
    custom_handler(event)
  File "/var/lib/juju/agents/unit-postgresql-test-app-0/charm/./src/charm.py", line 289, in _on_clear_continuous_writes_action
    if self._connection_string is None:
  File "/var/lib/juju/agents/unit-postgresql-test-app-0/charm/./src/charm.py", line 259, in _connection_string
    data = list(self.first_database.fetch_relation_data().values())[0]
AttributeError: 'ApplicationCharm' object has no attribute 'first_database'
unit-postgresql-test-app-0: 02:09:47 ERROR unit.postgresql-test-app/0.juju-log Uncaught exception while in charm code:
Traceback (most recent call last):
  File "/var/lib/juju/agents/unit-postgresql-test-app-0/charm/./src/charm.py", line 538, in <module>
    main(ApplicationCharm)
  File "/var/lib/juju/agents/unit-postgresql-test-app-0/charm/venv/ops/main.py", line 553, in main
    manager.run()
  File "/var/lib/juju/agents/unit-postgresql-test-app-0/charm/venv/ops/main.py", line 529, in run
    self._emit()
  File "/var/lib/juju/agents/unit-postgresql-test-app-0/charm/venv/ops/main.py", line 518, in _emit
    _emit_charm_event(self.charm, self.dispatcher.event_name, self._juju_context)
  File "/var/lib/juju/agents/unit-postgresql-test-app-0/charm/venv/ops/main.py", line 139, in _emit_charm_event
    event_to_emit.emit(*args, **kwargs)
  File "/var/lib/juju/agents/unit-postgresql-test-app-0/charm/venv/ops/framework.py", line 347, in emit
    framework._emit(event)
  File "/var/lib/juju/agents/unit-postgresql-test-app-0/charm/venv/ops/framework.py", line 853, in _emit
    self._reemit(event_path)
  File "/var/lib/juju/agents/unit-postgresql-test-app-0/charm/venv/ops/framework.py", line 943, in _reemit
    custom_handler(event)
  File "/var/lib/juju/agents/unit-postgresql-test-app-0/charm/./src/charm.py", line 289, in _on_clear_continuous_writes_action
    if self._connection_string is None:
  File "/var/lib/juju/agents/unit-postgresql-test-app-0/charm/./src/charm.py", line 259, in _connection_string
    data = list(self.first_database.fetch_relation_data().values())[0]
AttributeError: 'ApplicationCharm' object has no attribute 'first_database'
unit-postgresql-test-app-0: 02:09:51 ERROR unit.postgresql-test-app/0.juju-log Uncaught exception while in charm code:
Traceback (most recent call last):
  File "/var/lib/juju/agents/unit-postgresql-test-app-0/charm/./src/charm.py", line 538, in <module>
    main(ApplicationCharm)
  File "/var/lib/juju/agents/unit-postgresql-test-app-0/charm/venv/ops/main.py", line 553, in main
    manager.run()
  File "/var/lib/juju/agents/unit-postgresql-test-app-0/charm/venv/ops/main.py", line 529, in run
    self._emit()
  File "/var/lib/juju/agents/unit-postgresql-test-app-0/charm/venv/ops/main.py", line 518, in _emit
    _emit_charm_event(self.charm, self.dispatcher.event_name, self._juju_context)
  File "/var/lib/juju/agents/unit-postgresql-test-app-0/charm/venv/ops/main.py", line 139, in _emit_charm_event
    event_to_emit.emit(*args, **kwargs)
  File "/var/lib/juju/agents/unit-postgresql-test-app-0/charm/venv/ops/framework.py", line 347, in emit
    framework._emit(event)
  File "/var/lib/juju/agents/unit-postgresql-test-app-0/charm/venv/ops/framework.py", line 853, in _emit
    self._reemit(event_path)
  File "/var/lib/juju/agents/unit-postgresql-test-app-0/charm/venv/ops/framework.py", line 943, in _reemit
    custom_handler(event)
  File "/var/lib/juju/agents/unit-postgresql-test-app-0/charm/./src/charm.py", line 289, in _on_clear_continuous_writes_action
    if self._connection_string is None:
  File "/var/lib/juju/agents/unit-postgresql-test-app-0/charm/./src/charm.py", line 259, in _connection_string
    data = list(self.first_database.fetch_relation_data().values())[0]
AttributeError: 'ApplicationCharm' object has no attribute 'first_database'
unit-postgresql-test-app-0: 02:09:55 ERROR unit.postgresql-test-app/0.juju-log Uncaught exception while in charm code:
Traceback (most recent call last):
  File "/var/lib/juju/agents/unit-postgresql-test-app-0/charm/./src/charm.py", line 538, in <module>
    main(ApplicationCharm)
  File "/var/lib/juju/agents/unit-postgresql-test-app-0/charm/venv/ops/main.py", line 553, in main
    manager.run()
  File "/var/lib/juju/agents/unit-postgresql-test-app-0/charm/venv/ops/main.py", line 529, in run
    self._emit()
  File "/var/lib/juju/agents/unit-postgresql-test-app-0/charm/venv/ops/main.py", line 518, in _emit
    _emit_charm_event(self.charm, self.dispatcher.event_name, self._juju_context)
  File "/var/lib/juju/agents/unit-postgresql-test-app-0/charm/venv/ops/main.py", line 139, in _emit_charm_event
    event_to_emit.emit(*args, **kwargs)
  File "/var/lib/juju/agents/unit-postgresql-test-app-0/charm/venv/ops/framework.py", line 347, in emit
    framework._emit(event)
  File "/var/lib/juju/agents/unit-postgresql-test-app-0/charm/venv/ops/framework.py", line 853, in _emit
    self._reemit(event_path)
  File "/var/lib/juju/agents/unit-postgresql-test-app-0/charm/venv/ops/framework.py", line 943, in _reemit
    custom_handler(event)
  File "/var/lib/juju/agents/unit-postgresql-test-app-0/charm/./src/charm.py", line 289, in _on_clear_continuous_writes_action
    if self._connection_string is None:
  File "/var/lib/juju/agents/unit-postgresql-test-app-0/charm/./src/charm.py", line 259, in _connection_string
    data = list(self.first_database.fetch_relation_data().values())[0]
AttributeError: 'ApplicationCharm' object has no attribute 'first_database'
unit-postgresql-test-app-0: 02:09:59 ERROR unit.postgresql-test-app/0.juju-log Uncaught exception while in charm code:
Traceback (most recent call last):
  File "/var/lib/juju/agents/unit-postgresql-test-app-0/charm/./src/charm.py", line 538, in <module>
    main(ApplicationCharm)
  File "/var/lib/juju/agents/unit-postgresql-test-app-0/charm/venv/ops/main.py", line 553, in main
    manager.run()
  File "/var/lib/juju/agents/unit-postgresql-test-app-0/charm/venv/ops/main.py", line 529, in run
    self._emit()
  File "/var/lib/juju/agents/unit-postgresql-test-app-0/charm/venv/ops/main.py", line 518, in _emit
    _emit_charm_event(self.charm, self.dispatcher.event_name, self._juju_context)
  File "/var/lib/juju/agents/unit-postgresql-test-app-0/charm/venv/ops/main.py", line 139, in _emit_charm_event
    event_to_emit.emit(*args, **kwargs)
  File "/var/lib/juju/agents/unit-postgresql-test-app-0/charm/venv/ops/framework.py", line 347, in emit
    framework._emit(event)
  File "/var/lib/juju/agents/unit-postgresql-test-app-0/charm/venv/ops/framework.py", line 853, in _emit
    self._reemit(event_path)
  File "/var/lib/juju/agents/unit-postgresql-test-app-0/charm/venv/ops/framework.py", line 943, in _reemit
    custom_handler(event)
  File "/var/lib/juju/agents/unit-postgresql-test-app-0/charm/./src/charm.py", line 289, in _on_clear_continuous_writes_action
    if self._connection_string is None:
  File "/var/lib/juju/agents/unit-postgresql-test-app-0/charm/./src/charm.py", line 259, in _connection_string
    data = list(self.first_database.fetch_relation_data().values())[0]
AttributeError: 'ApplicationCharm' object has no attribute 'first_database'
unit-postgresql-test-app-0: 02:10:03 ERROR unit.postgresql-test-app/0.juju-log Uncaught exception while in charm code:
Traceback (most recent call last):
  File "/var/lib/juju/agents/unit-postgresql-test-app-0/charm/./src/charm.py", line 538, in <module>
    main(ApplicationCharm)
  File "/var/lib/juju/agents/unit-postgresql-test-app-0/charm/venv/ops/main.py", line 553, in main
    manager.run()
  File "/var/lib/juju/agents/unit-postgresql-test-app-0/charm/venv/ops/main.py", line 529, in run
    self._emit()
  File "/var/lib/juju/agents/unit-postgresql-test-app-0/charm/venv/ops/main.py", line 518, in _emit
    _emit_charm_event(self.charm, self.dispatcher.event_name, self._juju_context)
  File "/var/lib/juju/agents/unit-postgresql-test-app-0/charm/venv/ops/main.py", line 139, in _emit_charm_event
    event_to_emit.emit(*args, **kwargs)
  File "/var/lib/juju/agents/unit-postgresql-test-app-0/charm/venv/ops/framework.py", line 347, in emit
    framework._emit(event)
  File "/var/lib/juju/agents/unit-postgresql-test-app-0/charm/venv/ops/framework.py", line 853, in _emit
    self._reemit(event_path)
  File "/var/lib/juju/agents/unit-postgresql-test-app-0/charm/venv/ops/framework.py", line 943, in _reemit
    custom_handler(event)
  File "/var/lib/juju/agents/unit-postgresql-test-app-0/charm/./src/charm.py", line 289, in _on_clear_continuous_writes_action
    if self._connection_string is None:
  File "/var/lib/juju/agents/unit-postgresql-test-app-0/charm/./src/charm.py", line 259, in _connection_string
    data = list(self.first_database.fetch_relation_data().values())[0]
AttributeError: 'ApplicationCharm' object has no attribute 'first_database'
unit-postgresql-test-app-0: 02:10:07 ERROR unit.postgresql-test-app/0.juju-log Uncaught exception while in charm code:
Traceback (most recent call last):
  File "/var/lib/juju/agents/unit-postgresql-test-app-0/charm/./src/charm.py", line 538, in <module>
    main(ApplicationCharm)
  File "/var/lib/juju/agents/unit-postgresql-test-app-0/charm/venv/ops/main.py", line 553, in main
    manager.run()
  File "/var/lib/juju/agents/unit-postgresql-test-app-0/charm/venv/ops/main.py", line 529, in run
    self._emit()
  File "/var/lib/juju/agents/unit-postgresql-test-app-0/charm/venv/ops/main.py", line 518, in _emit
    _emit_charm_event(self.charm, self.dispatcher.event_name, self._juju_context)
  File "/var/lib/juju/agents/unit-postgresql-test-app-0/charm/venv/ops/main.py", line 139, in _emit_charm_event
    event_to_emit.emit(*args, **kwargs)
  File "/var/lib/juju/agents/unit-postgresql-test-app-0/charm/venv/ops/framework.py", line 347, in emit
    framework._emit(event)
  File "/var/lib/juju/agents/unit-postgresql-test-app-0/charm/venv/ops/framework.py", line 853, in _emit
    self._reemit(event_path)
  File "/var/lib/juju/agents/unit-postgresql-test-app-0/charm/venv/ops/framework.py", line 943, in _reemit
    custom_handler(event)
  File "/var/lib/juju/agents/unit-postgresql-test-app-0/charm/./src/charm.py", line 289, in _on_clear_continuous_writes_action
    if self._connection_string is None:
  File "/var/lib/juju/agents/unit-postgresql-test-app-0/charm/./src/charm.py", line 259, in _connection_string
    data = list(self.first_database.fetch_relation_data().values())[0]
AttributeError: 'ApplicationCharm' object has no attribute 'first_database'
unit-postgresql-test-app-0: 02:10:11 ERROR unit.postgresql-test-app/0.juju-log Uncaught exception while in charm code:
Traceback (most recent call last):
  File "/var/lib/juju/agents/unit-postgresql-test-app-0/charm/./src/charm.py", line 538, in <module>
    main(ApplicationCharm)
  File "/var/lib/juju/agents/unit-postgresql-test-app-0/charm/venv/ops/main.py", line 553, in main
    manager.run()
  File "/var/lib/juju/agents/unit-postgresql-test-app-0/charm/venv/ops/main.py", line 529, in run
    self._emit()
  File "/var/lib/juju/agents/unit-postgresql-test-app-0/charm/venv/ops/main.py", line 518, in _emit
    _emit_charm_event(self.charm, self.dispatcher.event_name, self._juju_context)
  File "/var/lib/juju/agents/unit-postgresql-test-app-0/charm/venv/ops/main.py", line 139, in _emit_charm_event
    event_to_emit.emit(*args, **kwargs)
  File "/var/lib/juju/agents/unit-postgresql-test-app-0/charm/venv/ops/framework.py", line 347, in emit
    framework._emit(event)
  File "/var/lib/juju/agents/unit-postgresql-test-app-0/charm/venv/ops/framework.py", line 853, in _emit
    self._reemit(event_path)
  File "/var/lib/juju/agents/unit-postgresql-test-app-0/charm/venv/ops/framework.py", line 943, in _reemit
    custom_handler(event)
  File "/var/lib/juju/agents/unit-postgresql-test-app-0/charm/./src/charm.py", line 289, in _on_clear_continuous_writes_action
    if self._connection_string is None:
  File "/var/lib/juju/agents/unit-postgresql-test-app-0/charm/./src/charm.py", line 259, in _connection_string
    data = list(self.first_database.fetch_relation_data().values())[0]
AttributeError: 'ApplicationCharm' object has no attribute 'first_database'
unit-postgresql-test-app-0: 02:10:15 ERROR unit.postgresql-test-app/0.juju-log Uncaught exception while in charm code:
Traceback (most recent call last):
  File "/var/lib/juju/agents/unit-postgresql-test-app-0/charm/./src/charm.py", line 538, in <module>
    main(ApplicationCharm)
  File "/var/lib/juju/agents/unit-postgresql-test-app-0/charm/venv/ops/main.py", line 553, in main
    manager.run()
  File "/var/lib/juju/agents/unit-postgresql-test-app-0/charm/venv/ops/main.py", line 529, in run
    self._emit()
  File "/var/lib/juju/agents/unit-postgresql-test-app-0/charm/venv/ops/main.py", line 518, in _emit
    _emit_charm_event(self.charm, self.dispatcher.event_name, self._juju_context)
  File "/var/lib/juju/agents/unit-postgresql-test-app-0/charm/venv/ops/main.py", line 139, in _emit_charm_event
    event_to_emit.emit(*args, **kwargs)
  File "/var/lib/juju/agents/unit-postgresql-test-app-0/charm/venv/ops/framework.py", line 347, in emit
    framework._emit(event)
  File "/var/lib/juju/agents/unit-postgresql-test-app-0/charm/venv/ops/framework.py", line 853, in _emit
    self._reemit(event_path)
  File "/var/lib/juju/agents/unit-postgresql-test-app-0/charm/venv/ops/framework.py", line 943, in _reemit
    custom_handler(event)
  File "/var/lib/juju/agents/unit-postgresql-test-app-0/charm/./src/charm.py", line 289, in _on_clear_continuous_writes_action
    if self._connection_string is None:
  File "/var/lib/juju/agents/unit-postgresql-test-app-0/charm/./src/charm.py", line 259, in _connection_string
    data = list(self.first_database.fetch_relation_data().values())[0]
AttributeError: 'ApplicationCharm' object has no attribute 'first_database'
unit-postgresql-test-app-0: 02:10:19 ERROR unit.postgresql-test-app/0.juju-log Uncaught exception while in charm code:
Traceback (most recent call last):
  File "/var/lib/juju/agents/unit-postgresql-test-app-0/charm/./src/charm.py", line 538, in <module>
    main(ApplicationCharm)
  File "/var/lib/juju/agents/unit-postgresql-test-app-0/charm/venv/ops/main.py", line 553, in main
    manager.run()
  File "/var/lib/juju/agents/unit-postgresql-test-app-0/charm/venv/ops/main.py", line 529, in run
    self._emit()
  File "/var/lib/juju/agents/unit-postgresql-test-app-0/charm/venv/ops/main.py", line 518, in _emit
    _emit_charm_event(self.charm, self.dispatcher.event_name, self._juju_context)
  File "/var/lib/juju/agents/unit-postgresql-test-app-0/charm/venv/ops/main.py", line 139, in _emit_charm_event
    event_to_emit.emit(*args, **kwargs)
  File "/var/lib/juju/agents/unit-postgresql-test-app-0/charm/venv/ops/framework.py", line 347, in emit
    framework._emit(event)
  File "/var/lib/juju/agents/unit-postgresql-test-app-0/charm/venv/ops/framework.py", line 853, in _emit
    self._reemit(event_path)
  File "/var/lib/juju/agents/unit-postgresql-test-app-0/charm/venv/ops/framework.py", line 943, in _reemit
    custom_handler(event)
  File "/var/lib/juju/agents/unit-postgresql-test-app-0/charm/./src/charm.py", line 289, in _on_clear_continuous_writes_action
    if self._connection_string is None:
  File "/var/lib/juju/agents/unit-postgresql-test-app-0/charm/./src/charm.py", line 259, in _connection_string
    data = list(self.first_database.fetch_relation_data().values())[0]
AttributeError: 'ApplicationCharm' object has no attribute 'first_database'
unit-postgresql-test-app-0: 02:10:23 ERROR unit.postgresql-test-app/0.juju-log Uncaught exception while in charm code:
Traceback (most recent call last):
  File "/var/lib/juju/agents/unit-postgresql-test-app-0/charm/./src/charm.py", line 538, in <module>
    main(ApplicationCharm)
  File "/var/lib/juju/agents/unit-postgresql-test-app-0/charm/venv/ops/main.py", line 553, in main
    manager.run()
  File "/var/lib/juju/agents/unit-postgresql-test-app-0/charm/venv/ops/main.py", line 529, in run
    self._emit()
  File "/var/lib/juju/agents/unit-postgresql-test-app-0/charm/venv/ops/main.py", line 518, in _emit
    _emit_charm_event(self.charm, self.dispatcher.event_name, self._juju_context)
  File "/var/lib/juju/agents/unit-postgresql-test-app-0/charm/venv/ops/main.py", line 139, in _emit_charm_event
    event_to_emit.emit(*args, **kwargs)
  File "/var/lib/juju/agents/unit-postgresql-test-app-0/charm/venv/ops/framework.py", line 347, in emit
    framework._emit(event)
  File "/var/lib/juju/agents/unit-postgresql-test-app-0/charm/venv/ops/framework.py", line 853, in _emit
    self._reemit(event_path)
  File "/var/lib/juju/agents/unit-postgresql-test-app-0/charm/venv/ops/framework.py", line 943, in _reemit
    custom_handler(event)
  File "/var/lib/juju/agents/unit-postgresql-test-app-0/charm/./src/charm.py", line 289, in _on_clear_continuous_writes_action
    if self._connection_string is None:
  File "/var/lib/juju/agents/unit-postgresql-test-app-0/charm/./src/charm.py", line 259, in _connection_string
    data = list(self.first_database.fetch_relation_data().values())[0]
AttributeError: 'ApplicationCharm' object has no attribute 'first_database'

[32mINFO    [0m pytest_operator.plugin:plugin.py:947 Forgetting model main...