[32mINFO    [0m pytest_operator.plugin:plugin.py:862 Model status:

Model  Controller          Cloud/Region        Version  SLA          Timestamp
test   microk8s-localhost  microk8s/localhost  3.4.4    unsupported  02:44:42Z

App                  Version  Status  Scale  Charm                Channel      Rev  Address        Exposed  Message
postgresql-k8s       14.12    active      3  postgresql-k8s       14/edge      349  10.152.183.57  no       
postgresql-test-app           active      1  postgresql-test-app  latest/edge  215  10.152.183.40  no       

Unit                    Workload  Agent  Address       Ports  Message
postgresql-k8s/0*       active    idle   10.1.139.140         Primary
postgresql-k8s/1        active    idle   10.1.139.142         
postgresql-k8s/2        active    idle   10.1.139.141         
postgresql-test-app/0*  active    idle   10.1.139.136         

[32mINFO    [0m pytest_operator.plugin:plugin.py:868 Juju error logs:

unit-postgresql-test-app-0: 02:39:42 ERROR unit.postgresql-test-app/0.juju-log Uncaught exception while in charm code:
Traceback (most recent call last):
  File "/var/lib/juju/agents/unit-postgresql-test-app-0/charm/./src/charm.py", line 538, in <module>
    main(ApplicationCharm)
  File "/var/lib/juju/agents/unit-postgresql-test-app-0/charm/venv/ops/main.py", line 551, in main
    manager.run()
  File "/var/lib/juju/agents/unit-postgresql-test-app-0/charm/venv/ops/main.py", line 530, in run
    self._emit()
  File "/var/lib/juju/agents/unit-postgresql-test-app-0/charm/venv/ops/main.py", line 519, in _emit
    _emit_charm_event(self.charm, self.dispatcher.event_name)
  File "/var/lib/juju/agents/unit-postgresql-test-app-0/charm/venv/ops/main.py", line 147, in _emit_charm_event
    event_to_emit.emit(*args, **kwargs)
  File "/var/lib/juju/agents/unit-postgresql-test-app-0/charm/venv/ops/framework.py", line 348, in emit
    framework._emit(event)
  File "/var/lib/juju/agents/unit-postgresql-test-app-0/charm/venv/ops/framework.py", line 860, in _emit
    self._reemit(event_path)
  File "/var/lib/juju/agents/unit-postgresql-test-app-0/charm/venv/ops/framework.py", line 950, in _reemit
    custom_handler(event)
  File "/var/lib/juju/agents/unit-postgresql-test-app-0/charm/./src/charm.py", line 289, in _on_clear_continuous_writes_action
    if self._connection_string is None:
  File "/var/lib/juju/agents/unit-postgresql-test-app-0/charm/./src/charm.py", line 259, in _connection_string
    data = list(self.first_database.fetch_relation_data().values())[0]
AttributeError: 'ApplicationCharm' object has no attribute 'first_database'
unit-postgresql-test-app-0: 02:39:46 ERROR unit.postgresql-test-app/0.juju-log Uncaught exception while in charm code:
Traceback (most recent call last):
  File "/var/lib/juju/agents/unit-postgresql-test-app-0/charm/./src/charm.py", line 538, in <module>
    main(ApplicationCharm)
  File "/var/lib/juju/agents/unit-postgresql-test-app-0/charm/venv/ops/main.py", line 551, in main
    manager.run()
  File "/var/lib/juju/agents/unit-postgresql-test-app-0/charm/venv/ops/main.py", line 530, in run
    self._emit()
  File "/var/lib/juju/agents/unit-postgresql-test-app-0/charm/venv/ops/main.py", line 519, in _emit
    _emit_charm_event(self.charm, self.dispatcher.event_name)
  File "/var/lib/juju/agents/unit-postgresql-test-app-0/charm/venv/ops/main.py", line 147, in _emit_charm_event
    event_to_emit.emit(*args, **kwargs)
  File "/var/lib/juju/agents/unit-postgresql-test-app-0/charm/venv/ops/framework.py", line 348, in emit
    framework._emit(event)
  File "/var/lib/juju/agents/unit-postgresql-test-app-0/charm/venv/ops/framework.py", line 860, in _emit
    self._reemit(event_path)
  File "/var/lib/juju/agents/unit-postgresql-test-app-0/charm/venv/ops/framework.py", line 950, in _reemit
    custom_handler(event)
  File "/var/lib/juju/agents/unit-postgresql-test-app-0/charm/./src/charm.py", line 289, in _on_clear_continuous_writes_action
    if self._connection_string is None:
  File "/var/lib/juju/agents/unit-postgresql-test-app-0/charm/./src/charm.py", line 259, in _connection_string
    data = list(self.first_database.fetch_relation_data().values())[0]
AttributeError: 'ApplicationCharm' object has no attribute 'first_database'
unit-postgresql-test-app-0: 02:39:50 ERROR unit.postgresql-test-app/0.juju-log Uncaught exception while in charm code:
Traceback (most recent call last):
  File "/var/lib/juju/agents/unit-postgresql-test-app-0/charm/./src/charm.py", line 538, in <module>
    main(ApplicationCharm)
  File "/var/lib/juju/agents/unit-postgresql-test-app-0/charm/venv/ops/main.py", line 551, in main
    manager.run()
  File "/var/lib/juju/agents/unit-postgresql-test-app-0/charm/venv/ops/main.py", line 530, in run
    self._emit()
  File "/var/lib/juju/agents/unit-postgresql-test-app-0/charm/venv/ops/main.py", line 519, in _emit
    _emit_charm_event(self.charm, self.dispatcher.event_name)
  File "/var/lib/juju/agents/unit-postgresql-test-app-0/charm/venv/ops/main.py", line 147, in _emit_charm_event
    event_to_emit.emit(*args, **kwargs)
  File "/var/lib/juju/agents/unit-postgresql-test-app-0/charm/venv/ops/framework.py", line 348, in emit
    framework._emit(event)
  File "/var/lib/juju/agents/unit-postgresql-test-app-0/charm/venv/ops/framework.py", line 860, in _emit
    self._reemit(event_path)
  File "/var/lib/juju/agents/unit-postgresql-test-app-0/charm/venv/ops/framework.py", line 950, in _reemit
    custom_handler(event)
  File "/var/lib/juju/agents/unit-postgresql-test-app-0/charm/./src/charm.py", line 289, in _on_clear_continuous_writes_action
    if self._connection_string is None:
  File "/var/lib/juju/agents/unit-postgresql-test-app-0/charm/./src/charm.py", line 259, in _connection_string
    data = list(self.first_database.fetch_relation_data().values())[0]
AttributeError: 'ApplicationCharm' object has no attribute 'first_database'
unit-postgresql-test-app-0: 02:39:54 ERROR unit.postgresql-test-app/0.juju-log Uncaught exception while in charm code:
Traceback (most recent call last):
  File "/var/lib/juju/agents/unit-postgresql-test-app-0/charm/./src/charm.py", line 538, in <module>
    main(ApplicationCharm)
  File "/var/lib/juju/agents/unit-postgresql-test-app-0/charm/venv/ops/main.py", line 551, in main
    manager.run()
  File "/var/lib/juju/agents/unit-postgresql-test-app-0/charm/venv/ops/main.py", line 530, in run
    self._emit()
  File "/var/lib/juju/agents/unit-postgresql-test-app-0/charm/venv/ops/main.py", line 519, in _emit
    _emit_charm_event(self.charm, self.dispatcher.event_name)
  File "/var/lib/juju/agents/unit-postgresql-test-app-0/charm/venv/ops/main.py", line 147, in _emit_charm_event
    event_to_emit.emit(*args, **kwargs)
  File "/var/lib/juju/agents/unit-postgresql-test-app-0/charm/venv/ops/framework.py", line 348, in emit
    framework._emit(event)
  File "/var/lib/juju/agents/unit-postgresql-test-app-0/charm/venv/ops/framework.py", line 860, in _emit
    self._reemit(event_path)
  File "/var/lib/juju/agents/unit-postgresql-test-app-0/charm/venv/ops/framework.py", line 950, in _reemit
    custom_handler(event)
  File "/var/lib/juju/agents/unit-postgresql-test-app-0/charm/./src/charm.py", line 289, in _on_clear_continuous_writes_action
    if self._connection_string is None:
  File "/var/lib/juju/agents/unit-postgresql-test-app-0/charm/./src/charm.py", line 259, in _connection_string
    data = list(self.first_database.fetch_relation_data().values())[0]
AttributeError: 'ApplicationCharm' object has no attribute 'first_database'
unit-postgresql-test-app-0: 02:39:58 ERROR unit.postgresql-test-app/0.juju-log Uncaught exception while in charm code:
Traceback (most recent call last):
  File "/var/lib/juju/agents/unit-postgresql-test-app-0/charm/./src/charm.py", line 538, in <module>
    main(ApplicationCharm)
  File "/var/lib/juju/agents/unit-postgresql-test-app-0/charm/venv/ops/main.py", line 551, in main
    manager.run()
  File "/var/lib/juju/agents/unit-postgresql-test-app-0/charm/venv/ops/main.py", line 530, in run
    self._emit()
  File "/var/lib/juju/agents/unit-postgresql-test-app-0/charm/venv/ops/main.py", line 519, in _emit
    _emit_charm_event(self.charm, self.dispatcher.event_name)
  File "/var/lib/juju/agents/unit-postgresql-test-app-0/charm/venv/ops/main.py", line 147, in _emit_charm_event
    event_to_emit.emit(*args, **kwargs)
  File "/var/lib/juju/agents/unit-postgresql-test-app-0/charm/venv/ops/framework.py", line 348, in emit
    framework._emit(event)
  File "/var/lib/juju/agents/unit-postgresql-test-app-0/charm/venv/ops/framework.py", line 860, in _emit
    self._reemit(event_path)
  File "/var/lib/juju/agents/unit-postgresql-test-app-0/charm/venv/ops/framework.py", line 950, in _reemit
    custom_handler(event)
  File "/var/lib/juju/agents/unit-postgresql-test-app-0/charm/./src/charm.py", line 289, in _on_clear_continuous_writes_action
    if self._connection_string is None:
  File "/var/lib/juju/agents/unit-postgresql-test-app-0/charm/./src/charm.py", line 259, in _connection_string
    data = list(self.first_database.fetch_relation_data().values())[0]
AttributeError: 'ApplicationCharm' object has no attribute 'first_database'
unit-postgresql-test-app-0: 02:40:02 ERROR unit.postgresql-test-app/0.juju-log Uncaught exception while in charm code:
Traceback (most recent call last):
  File "/var/lib/juju/agents/unit-postgresql-test-app-0/charm/./src/charm.py", line 538, in <module>
    main(ApplicationCharm)
  File "/var/lib/juju/agents/unit-postgresql-test-app-0/charm/venv/ops/main.py", line 551, in main
    manager.run()
  File "/var/lib/juju/agents/unit-postgresql-test-app-0/charm/venv/ops/main.py", line 530, in run
    self._emit()
  File "/var/lib/juju/agents/unit-postgresql-test-app-0/charm/venv/ops/main.py", line 519, in _emit
    _emit_charm_event(self.charm, self.dispatcher.event_name)
  File "/var/lib/juju/agents/unit-postgresql-test-app-0/charm/venv/ops/main.py", line 147, in _emit_charm_event
    event_to_emit.emit(*args, **kwargs)
  File "/var/lib/juju/agents/unit-postgresql-test-app-0/charm/venv/ops/framework.py", line 348, in emit
    framework._emit(event)
  File "/var/lib/juju/agents/unit-postgresql-test-app-0/charm/venv/ops/framework.py", line 860, in _emit
    self._reemit(event_path)
  File "/var/lib/juju/agents/unit-postgresql-test-app-0/charm/venv/ops/framework.py", line 950, in _reemit
    custom_handler(event)
  File "/var/lib/juju/agents/unit-postgresql-test-app-0/charm/./src/charm.py", line 289, in _on_clear_continuous_writes_action
    if self._connection_string is None:
  File "/var/lib/juju/agents/unit-postgresql-test-app-0/charm/./src/charm.py", line 259, in _connection_string
    data = list(self.first_database.fetch_relation_data().values())[0]
AttributeError: 'ApplicationCharm' object has no attribute 'first_database'
unit-postgresql-test-app-0: 02:40:06 ERROR unit.postgresql-test-app/0.juju-log Uncaught exception while in charm code:
Traceback (most recent call last):
  File "/var/lib/juju/agents/unit-postgresql-test-app-0/charm/./src/charm.py", line 538, in <module>
    main(ApplicationCharm)
  File "/var/lib/juju/agents/unit-postgresql-test-app-0/charm/venv/ops/main.py", line 551, in main
    manager.run()
  File "/var/lib/juju/agents/unit-postgresql-test-app-0/charm/venv/ops/main.py", line 530, in run
    self._emit()
  File "/var/lib/juju/agents/unit-postgresql-test-app-0/charm/venv/ops/main.py", line 519, in _emit
    _emit_charm_event(self.charm, self.dispatcher.event_name)
  File "/var/lib/juju/agents/unit-postgresql-test-app-0/charm/venv/ops/main.py", line 147, in _emit_charm_event
    event_to_emit.emit(*args, **kwargs)
  File "/var/lib/juju/agents/unit-postgresql-test-app-0/charm/venv/ops/framework.py", line 348, in emit
    framework._emit(event)
  File "/var/lib/juju/agents/unit-postgresql-test-app-0/charm/venv/ops/framework.py", line 860, in _emit
    self._reemit(event_path)
  File "/var/lib/juju/agents/unit-postgresql-test-app-0/charm/venv/ops/framework.py", line 950, in _reemit
    custom_handler(event)
  File "/var/lib/juju/agents/unit-postgresql-test-app-0/charm/./src/charm.py", line 289, in _on_clear_continuous_writes_action
    if self._connection_string is None:
  File "/var/lib/juju/agents/unit-postgresql-test-app-0/charm/./src/charm.py", line 259, in _connection_string
    data = list(self.first_database.fetch_relation_data().values())[0]
AttributeError: 'ApplicationCharm' object has no attribute 'first_database'
unit-postgresql-test-app-0: 02:40:10 ERROR unit.postgresql-test-app/0.juju-log Uncaught exception while in charm code:
Traceback (most recent call last):
  File "/var/lib/juju/agents/unit-postgresql-test-app-0/charm/./src/charm.py", line 538, in <module>
    main(ApplicationCharm)
  File "/var/lib/juju/agents/unit-postgresql-test-app-0/charm/venv/ops/main.py", line 551, in main
    manager.run()
  File "/var/lib/juju/agents/unit-postgresql-test-app-0/charm/venv/ops/main.py", line 530, in run
    self._emit()
  File "/var/lib/juju/agents/unit-postgresql-test-app-0/charm/venv/ops/main.py", line 519, in _emit
    _emit_charm_event(self.charm, self.dispatcher.event_name)
  File "/var/lib/juju/agents/unit-postgresql-test-app-0/charm/venv/ops/main.py", line 147, in _emit_charm_event
    event_to_emit.emit(*args, **kwargs)
  File "/var/lib/juju/agents/unit-postgresql-test-app-0/charm/venv/ops/framework.py", line 348, in emit
    framework._emit(event)
  File "/var/lib/juju/agents/unit-postgresql-test-app-0/charm/venv/ops/framework.py", line 860, in _emit
    self._reemit(event_path)
  File "/var/lib/juju/agents/unit-postgresql-test-app-0/charm/venv/ops/framework.py", line 950, in _reemit
    custom_handler(event)
  File "/var/lib/juju/agents/unit-postgresql-test-app-0/charm/./src/charm.py", line 289, in _on_clear_continuous_writes_action
    if self._connection_string is None:
  File "/var/lib/juju/agents/unit-postgresql-test-app-0/charm/./src/charm.py", line 259, in _connection_string
    data = list(self.first_database.fetch_relation_data().values())[0]
AttributeError: 'ApplicationCharm' object has no attribute 'first_database'
unit-postgresql-test-app-0: 02:40:14 ERROR unit.postgresql-test-app/0.juju-log Uncaught exception while in charm code:
Traceback (most recent call last):
  File "/var/lib/juju/agents/unit-postgresql-test-app-0/charm/./src/charm.py", line 538, in <module>
    main(ApplicationCharm)
  File "/var/lib/juju/agents/unit-postgresql-test-app-0/charm/venv/ops/main.py", line 551, in main
    manager.run()
  File "/var/lib/juju/agents/unit-postgresql-test-app-0/charm/venv/ops/main.py", line 530, in run
    self._emit()
  File "/var/lib/juju/agents/unit-postgresql-test-app-0/charm/venv/ops/main.py", line 519, in _emit
    _emit_charm_event(self.charm, self.dispatcher.event_name)
  File "/var/lib/juju/agents/unit-postgresql-test-app-0/charm/venv/ops/main.py", line 147, in _emit_charm_event
    event_to_emit.emit(*args, **kwargs)
  File "/var/lib/juju/agents/unit-postgresql-test-app-0/charm/venv/ops/framework.py", line 348, in emit
    framework._emit(event)
  File "/var/lib/juju/agents/unit-postgresql-test-app-0/charm/venv/ops/framework.py", line 860, in _emit
    self._reemit(event_path)
  File "/var/lib/juju/agents/unit-postgresql-test-app-0/charm/venv/ops/framework.py", line 950, in _reemit
    custom_handler(event)
  File "/var/lib/juju/agents/unit-postgresql-test-app-0/charm/./src/charm.py", line 289, in _on_clear_continuous_writes_action
    if self._connection_string is None:
  File "/var/lib/juju/agents/unit-postgresql-test-app-0/charm/./src/charm.py", line 259, in _connection_string
    data = list(self.first_database.fetch_relation_data().values())[0]
AttributeError: 'ApplicationCharm' object has no attribute 'first_database'
unit-postgresql-test-app-0: 02:40:18 ERROR unit.postgresql-test-app/0.juju-log Uncaught exception while in charm code:
Traceback (most recent call last):
  File "/var/lib/juju/agents/unit-postgresql-test-app-0/charm/./src/charm.py", line 538, in <module>
    main(ApplicationCharm)
  File "/var/lib/juju/agents/unit-postgresql-test-app-0/charm/venv/ops/main.py", line 551, in main
    manager.run()
  File "/var/lib/juju/agents/unit-postgresql-test-app-0/charm/venv/ops/main.py", line 530, in run
    self._emit()
  File "/var/lib/juju/agents/unit-postgresql-test-app-0/charm/venv/ops/main.py", line 519, in _emit
    _emit_charm_event(self.charm, self.dispatcher.event_name)
  File "/var/lib/juju/agents/unit-postgresql-test-app-0/charm/venv/ops/main.py", line 147, in _emit_charm_event
    event_to_emit.emit(*args, **kwargs)
  File "/var/lib/juju/agents/unit-postgresql-test-app-0/charm/venv/ops/framework.py", line 348, in emit
    framework._emit(event)
  File "/var/lib/juju/agents/unit-postgresql-test-app-0/charm/venv/ops/framework.py", line 860, in _emit
    self._reemit(event_path)
  File "/var/lib/juju/agents/unit-postgresql-test-app-0/charm/venv/ops/framework.py", line 950, in _reemit
    custom_handler(event)
  File "/var/lib/juju/agents/unit-postgresql-test-app-0/charm/./src/charm.py", line 289, in _on_clear_continuous_writes_action
    if self._connection_string is None:
  File "/var/lib/juju/agents/unit-postgresql-test-app-0/charm/./src/charm.py", line 259, in _connection_string
    data = list(self.first_database.fetch_relation_data().values())[0]
AttributeError: 'ApplicationCharm' object has no attribute 'first_database'
unit-postgresql-test-app-0: 02:40:22 ERROR unit.postgresql-test-app/0.juju-log Uncaught exception while in charm code:
Traceback (most recent call last):
  File "/var/lib/juju/agents/unit-postgresql-test-app-0/charm/./src/charm.py", line 538, in <module>
    main(ApplicationCharm)
  File "/var/lib/juju/agents/unit-postgresql-test-app-0/charm/venv/ops/main.py", line 551, in main
    manager.run()
  File "/var/lib/juju/agents/unit-postgresql-test-app-0/charm/venv/ops/main.py", line 530, in run
    self._emit()
  File "/var/lib/juju/agents/unit-postgresql-test-app-0/charm/venv/ops/main.py", line 519, in _emit
    _emit_charm_event(self.charm, self.dispatcher.event_name)
  File "/var/lib/juju/agents/unit-postgresql-test-app-0/charm/venv/ops/main.py", line 147, in _emit_charm_event
    event_to_emit.emit(*args, **kwargs)
  File "/var/lib/juju/agents/unit-postgresql-test-app-0/charm/venv/ops/framework.py", line 348, in emit
    framework._emit(event)
  File "/var/lib/juju/agents/unit-postgresql-test-app-0/charm/venv/ops/framework.py", line 860, in _emit
    self._reemit(event_path)
  File "/var/lib/juju/agents/unit-postgresql-test-app-0/charm/venv/ops/framework.py", line 950, in _reemit
    custom_handler(event)
  File "/var/lib/juju/agents/unit-postgresql-test-app-0/charm/./src/charm.py", line 289, in _on_clear_continuous_writes_action
    if self._connection_string is None:
  File "/var/lib/juju/agents/unit-postgresql-test-app-0/charm/./src/charm.py", line 259, in _connection_string
    data = list(self.first_database.fetch_relation_data().values())[0]
AttributeError: 'ApplicationCharm' object has no attribute 'first_database'
unit-postgresql-test-app-0: 02:40:26 ERROR unit.postgresql-test-app/0.juju-log Uncaught exception while in charm code:
Traceback (most recent call last):
  File "/var/lib/juju/agents/unit-postgresql-test-app-0/charm/./src/charm.py", line 538, in <module>
    main(ApplicationCharm)
  File "/var/lib/juju/agents/unit-postgresql-test-app-0/charm/venv/ops/main.py", line 551, in main
    manager.run()
  File "/var/lib/juju/agents/unit-postgresql-test-app-0/charm/venv/ops/main.py", line 530, in run
    self._emit()
  File "/var/lib/juju/agents/unit-postgresql-test-app-0/charm/venv/ops/main.py", line 519, in _emit
    _emit_charm_event(self.charm, self.dispatcher.event_name)
  File "/var/lib/juju/agents/unit-postgresql-test-app-0/charm/venv/ops/main.py", line 147, in _emit_charm_event
    event_to_emit.emit(*args, **kwargs)
  File "/var/lib/juju/agents/unit-postgresql-test-app-0/charm/venv/ops/framework.py", line 348, in emit
    framework._emit(event)
  File "/var/lib/juju/agents/unit-postgresql-test-app-0/charm/venv/ops/framework.py", line 860, in _emit
    self._reemit(event_path)
  File "/var/lib/juju/agents/unit-postgresql-test-app-0/charm/venv/ops/framework.py", line 950, in _reemit
    custom_handler(event)
  File "/var/lib/juju/agents/unit-postgresql-test-app-0/charm/./src/charm.py", line 289, in _on_clear_continuous_writes_action
    if self._connection_string is None:
  File "/var/lib/juju/agents/unit-postgresql-test-app-0/charm/./src/charm.py", line 259, in _connection_string
    data = list(self.first_database.fetch_relation_data().values())[0]
AttributeError: 'ApplicationCharm' object has no attribute 'first_database'
unit-postgresql-test-app-0: 02:40:30 ERROR unit.postgresql-test-app/0.juju-log Uncaught exception while in charm code:
Traceback (most recent call last):
  File "/var/lib/juju/agents/unit-postgresql-test-app-0/charm/./src/charm.py", line 538, in <module>
    main(ApplicationCharm)
  File "/var/lib/juju/agents/unit-postgresql-test-app-0/charm/venv/ops/main.py", line 551, in main
    manager.run()
  File "/var/lib/juju/agents/unit-postgresql-test-app-0/charm/venv/ops/main.py", line 530, in run
    self._emit()
  File "/var/lib/juju/agents/unit-postgresql-test-app-0/charm/venv/ops/main.py", line 519, in _emit
    _emit_charm_event(self.charm, self.dispatcher.event_name)
  File "/var/lib/juju/agents/unit-postgresql-test-app-0/charm/venv/ops/main.py", line 147, in _emit_charm_event
    event_to_emit.emit(*args, **kwargs)
  File "/var/lib/juju/agents/unit-postgresql-test-app-0/charm/venv/ops/framework.py", line 348, in emit
    framework._emit(event)
  File "/var/lib/juju/agents/unit-postgresql-test-app-0/charm/venv/ops/framework.py", line 860, in _emit
    self._reemit(event_path)
  File "/var/lib/juju/agents/unit-postgresql-test-app-0/charm/venv/ops/framework.py", line 950, in _reemit
    custom_handler(event)
  File "/var/lib/juju/agents/unit-postgresql-test-app-0/charm/./src/charm.py", line 289, in _on_clear_continuous_writes_action
    if self._connection_string is None:
  File "/var/lib/juju/agents/unit-postgresql-test-app-0/charm/./src/charm.py", line 259, in _connection_string
    data = list(self.first_database.fetch_relation_data().values())[0]
AttributeError: 'ApplicationCharm' object has no attribute 'first_database'
unit-postgresql-test-app-0: 02:40:35 ERROR unit.postgresql-test-app/0.juju-log Uncaught exception while in charm code:
Traceback (most recent call last):
  File "/var/lib/juju/agents/unit-postgresql-test-app-0/charm/./src/charm.py", line 538, in <module>
    main(ApplicationCharm)
  File "/var/lib/juju/agents/unit-postgresql-test-app-0/charm/venv/ops/main.py", line 551, in main
    manager.run()
  File "/var/lib/juju/agents/unit-postgresql-test-app-0/charm/venv/ops/main.py", line 530, in run
    self._emit()
  File "/var/lib/juju/agents/unit-postgresql-test-app-0/charm/venv/ops/main.py", line 519, in _emit
    _emit_charm_event(self.charm, self.dispatcher.event_name)
  File "/var/lib/juju/agents/unit-postgresql-test-app-0/charm/venv/ops/main.py", line 147, in _emit_charm_event
    event_to_emit.emit(*args, **kwargs)
  File "/var/lib/juju/agents/unit-postgresql-test-app-0/charm/venv/ops/framework.py", line 348, in emit
    framework._emit(event)
  File "/var/lib/juju/agents/unit-postgresql-test-app-0/charm/venv/ops/framework.py", line 860, in _emit
    self._reemit(event_path)
  File "/var/lib/juju/agents/unit-postgresql-test-app-0/charm/venv/ops/framework.py", line 950, in _reemit
    custom_handler(event)
  File "/var/lib/juju/agents/unit-postgresql-test-app-0/charm/./src/charm.py", line 289, in _on_clear_continuous_writes_action
    if self._connection_string is None:
  File "/var/lib/juju/agents/unit-postgresql-test-app-0/charm/./src/charm.py", line 259, in _connection_string
    data = list(self.first_database.fetch_relation_data().values())[0]
AttributeError: 'ApplicationCharm' object has no attribute 'first_database'
unit-postgresql-test-app-0: 02:40:39 ERROR unit.postgresql-test-app/0.juju-log Uncaught exception while in charm code:
Traceback (most recent call last):
  File "/var/lib/juju/agents/unit-postgresql-test-app-0/charm/./src/charm.py", line 538, in <module>
    main(ApplicationCharm)
  File "/var/lib/juju/agents/unit-postgresql-test-app-0/charm/venv/ops/main.py", line 551, in main
    manager.run()
  File "/var/lib/juju/agents/unit-postgresql-test-app-0/charm/venv/ops/main.py", line 530, in run
    self._emit()
  File "/var/lib/juju/agents/unit-postgresql-test-app-0/charm/venv/ops/main.py", line 519, in _emit
    _emit_charm_event(self.charm, self.dispatcher.event_name)
  File "/var/lib/juju/agents/unit-postgresql-test-app-0/charm/venv/ops/main.py", line 147, in _emit_charm_event
    event_to_emit.emit(*args, **kwargs)
  File "/var/lib/juju/agents/unit-postgresql-test-app-0/charm/venv/ops/framework.py", line 348, in emit
    framework._emit(event)
  File "/var/lib/juju/agents/unit-postgresql-test-app-0/charm/venv/ops/framework.py", line 860, in _emit
    self._reemit(event_path)
  File "/var/lib/juju/agents/unit-postgresql-test-app-0/charm/venv/ops/framework.py", line 950, in _reemit
    custom_handler(event)
  File "/var/lib/juju/agents/unit-postgresql-test-app-0/charm/./src/charm.py", line 289, in _on_clear_continuous_writes_action
    if self._connection_string is None:
  File "/var/lib/juju/agents/unit-postgresql-test-app-0/charm/./src/charm.py", line 259, in _connection_string
    data = list(self.first_database.fetch_relation_data().values())[0]
AttributeError: 'ApplicationCharm' object has no attribute 'first_database'
unit-postgresql-test-app-0: 02:40:43 ERROR unit.postgresql-test-app/0.juju-log Uncaught exception while in charm code:
Traceback (most recent call last):
  File "/var/lib/juju/agents/unit-postgresql-test-app-0/charm/./src/charm.py", line 538, in <module>
    main(ApplicationCharm)
  File "/var/lib/juju/agents/unit-postgresql-test-app-0/charm/venv/ops/main.py", line 551, in main
    manager.run()
  File "/var/lib/juju/agents/unit-postgresql-test-app-0/charm/venv/ops/main.py", line 530, in run
    self._emit()
  File "/var/lib/juju/agents/unit-postgresql-test-app-0/charm/venv/ops/main.py", line 519, in _emit
    _emit_charm_event(self.charm, self.dispatcher.event_name)
  File "/var/lib/juju/agents/unit-postgresql-test-app-0/charm/venv/ops/main.py", line 147, in _emit_charm_event
    event_to_emit.emit(*args, **kwargs)
  File "/var/lib/juju/agents/unit-postgresql-test-app-0/charm/venv/ops/framework.py", line 348, in emit
    framework._emit(event)
  File "/var/lib/juju/agents/unit-postgresql-test-app-0/charm/venv/ops/framework.py", line 860, in _emit
    self._reemit(event_path)
  File "/var/lib/juju/agents/unit-postgresql-test-app-0/charm/venv/ops/framework.py", line 950, in _reemit
    custom_handler(event)
  File "/var/lib/juju/agents/unit-postgresql-test-app-0/charm/./src/charm.py", line 289, in _on_clear_continuous_writes_action
    if self._connection_string is None:
  File "/var/lib/juju/agents/unit-postgresql-test-app-0/charm/./src/charm.py", line 259, in _connection_string
    data = list(self.first_database.fetch_relation_data().values())[0]
AttributeError: 'ApplicationCharm' object has no attribute 'first_database'
unit-postgresql-test-app-0: 02:40:47 ERROR unit.postgresql-test-app/0.juju-log Uncaught exception while in charm code:
Traceback (most recent call last):
  File "/var/lib/juju/agents/unit-postgresql-test-app-0/charm/./src/charm.py", line 538, in <module>
    main(ApplicationCharm)
  File "/var/lib/juju/agents/unit-postgresql-test-app-0/charm/venv/ops/main.py", line 551, in main
    manager.run()
  File "/var/lib/juju/agents/unit-postgresql-test-app-0/charm/venv/ops/main.py", line 530, in run
    self._emit()
  File "/var/lib/juju/agents/unit-postgresql-test-app-0/charm/venv/ops/main.py", line 519, in _emit
    _emit_charm_event(self.charm, self.dispatcher.event_name)
  File "/var/lib/juju/agents/unit-postgresql-test-app-0/charm/venv/ops/main.py", line 147, in _emit_charm_event
    event_to_emit.emit(*args, **kwargs)
  File "/var/lib/juju/agents/unit-postgresql-test-app-0/charm/venv/ops/framework.py", line 348, in emit
    framework._emit(event)
  File "/var/lib/juju/agents/unit-postgresql-test-app-0/charm/venv/ops/framework.py", line 860, in _emit
    self._reemit(event_path)
  File "/var/lib/juju/agents/unit-postgresql-test-app-0/charm/venv/ops/framework.py", line 950, in _reemit
    custom_handler(event)
  File "/var/lib/juju/agents/unit-postgresql-test-app-0/charm/./src/charm.py", line 289, in _on_clear_continuous_writes_action
    if self._connection_string is None:
  File "/var/lib/juju/agents/unit-postgresql-test-app-0/charm/./src/charm.py", line 259, in _connection_string
    data = list(self.first_database.fetch_relation_data().values())[0]
AttributeError: 'ApplicationCharm' object has no attribute 'first_database'
unit-postgresql-test-app-0: 02:40:51 ERROR unit.postgresql-test-app/0.juju-log Uncaught exception while in charm code:
Traceback (most recent call last):
  File "/var/lib/juju/agents/unit-postgresql-test-app-0/charm/./src/charm.py", line 538, in <module>
    main(ApplicationCharm)
  File "/var/lib/juju/agents/unit-postgresql-test-app-0/charm/venv/ops/main.py", line 551, in main
    manager.run()
  File "/var/lib/juju/agents/unit-postgresql-test-app-0/charm/venv/ops/main.py", line 530, in run
    self._emit()
  File "/var/lib/juju/agents/unit-postgresql-test-app-0/charm/venv/ops/main.py", line 519, in _emit
    _emit_charm_event(self.charm, self.dispatcher.event_name)
  File "/var/lib/juju/agents/unit-postgresql-test-app-0/charm/venv/ops/main.py", line 147, in _emit_charm_event
    event_to_emit.emit(*args, **kwargs)
  File "/var/lib/juju/agents/unit-postgresql-test-app-0/charm/venv/ops/framework.py", line 348, in emit
    framework._emit(event)
  File "/var/lib/juju/agents/unit-postgresql-test-app-0/charm/venv/ops/framework.py", line 860, in _emit
    self._reemit(event_path)
  File "/var/lib/juju/agents/unit-postgresql-test-app-0/charm/venv/ops/framework.py", line 950, in _reemit
    custom_handler(event)
  File "/var/lib/juju/agents/unit-postgresql-test-app-0/charm/./src/charm.py", line 289, in _on_clear_continuous_writes_action
    if self._connection_string is None:
  File "/var/lib/juju/agents/unit-postgresql-test-app-0/charm/./src/charm.py", line 259, in _connection_string
    data = list(self.first_database.fetch_relation_data().values())[0]
AttributeError: 'ApplicationCharm' object has no attribute 'first_database'
unit-postgresql-test-app-0: 02:40:55 ERROR unit.postgresql-test-app/0.juju-log Uncaught exception while in charm code:
Traceback (most recent call last):
  File "/var/lib/juju/agents/unit-postgresql-test-app-0/charm/./src/charm.py", line 538, in <module>
    main(ApplicationCharm)
  File "/var/lib/juju/agents/unit-postgresql-test-app-0/charm/venv/ops/main.py", line 551, in main
    manager.run()
  File "/var/lib/juju/agents/unit-postgresql-test-app-0/charm/venv/ops/main.py", line 530, in run
    self._emit()
  File "/var/lib/juju/agents/unit-postgresql-test-app-0/charm/venv/ops/main.py", line 519, in _emit
    _emit_charm_event(self.charm, self.dispatcher.event_name)
  File "/var/lib/juju/agents/unit-postgresql-test-app-0/charm/venv/ops/main.py", line 147, in _emit_charm_event
    event_to_emit.emit(*args, **kwargs)
  File "/var/lib/juju/agents/unit-postgresql-test-app-0/charm/venv/ops/framework.py", line 348, in emit
    framework._emit(event)
  File "/var/lib/juju/agents/unit-postgresql-test-app-0/charm/venv/ops/framework.py", line 860, in _emit
    self._reemit(event_path)
  File "/var/lib/juju/agents/unit-postgresql-test-app-0/charm/venv/ops/framework.py", line 950, in _reemit
    custom_handler(event)
  File "/var/lib/juju/agents/unit-postgresql-test-app-0/charm/./src/charm.py", line 289, in _on_clear_continuous_writes_action
    if self._connection_string is None:
  File "/var/lib/juju/agents/unit-postgresql-test-app-0/charm/./src/charm.py", line 259, in _connection_string
    data = list(self.first_database.fetch_relation_data().values())[0]
AttributeError: 'ApplicationCharm' object has no attribute 'first_database'
unit-postgresql-test-app-0: 02:40:59 ERROR unit.postgresql-test-app/0.juju-log Uncaught exception while in charm code:
Traceback (most recent call last):
  File "/var/lib/juju/agents/unit-postgresql-test-app-0/charm/./src/charm.py", line 538, in <module>
    main(ApplicationCharm)
  File "/var/lib/juju/agents/unit-postgresql-test-app-0/charm/venv/ops/main.py", line 551, in main
    manager.run()
  File "/var/lib/juju/agents/unit-postgresql-test-app-0/charm/venv/ops/main.py", line 530, in run
    self._emit()
  File "/var/lib/juju/agents/unit-postgresql-test-app-0/charm/venv/ops/main.py", line 519, in _emit
    _emit_charm_event(self.charm, self.dispatcher.event_name)
  File "/var/lib/juju/agents/unit-postgresql-test-app-0/charm/venv/ops/main.py", line 147, in _emit_charm_event
    event_to_emit.emit(*args, **kwargs)
  File "/var/lib/juju/agents/unit-postgresql-test-app-0/charm/venv/ops/framework.py", line 348, in emit
    framework._emit(event)
  File "/var/lib/juju/agents/unit-postgresql-test-app-0/charm/venv/ops/framework.py", line 860, in _emit
    self._reemit(event_path)
  File "/var/lib/juju/agents/unit-postgresql-test-app-0/charm/venv/ops/framework.py", line 950, in _reemit
    custom_handler(event)
  File "/var/lib/juju/agents/unit-postgresql-test-app-0/charm/./src/charm.py", line 289, in _on_clear_continuous_writes_action
    if self._connection_string is None:
  File "/var/lib/juju/agents/unit-postgresql-test-app-0/charm/./src/charm.py", line 259, in _connection_string
    data = list(self.first_database.fetch_relation_data().values())[0]
AttributeError: 'ApplicationCharm' object has no attribute 'first_database'
unit-postgresql-test-app-0: 02:41:03 ERROR unit.postgresql-test-app/0.juju-log Uncaught exception while in charm code:
Traceback (most recent call last):
  File "/var/lib/juju/agents/unit-postgresql-test-app-0/charm/./src/charm.py", line 538, in <module>
    main(ApplicationCharm)
  File "/var/lib/juju/agents/unit-postgresql-test-app-0/charm/venv/ops/main.py", line 551, in main
    manager.run()
  File "/var/lib/juju/agents/unit-postgresql-test-app-0/charm/venv/ops/main.py", line 530, in run
    self._emit()
  File "/var/lib/juju/agents/unit-postgresql-test-app-0/charm/venv/ops/main.py", line 519, in _emit
    _emit_charm_event(self.charm, self.dispatcher.event_name)
  File "/var/lib/juju/agents/unit-postgresql-test-app-0/charm/venv/ops/main.py", line 147, in _emit_charm_event
    event_to_emit.emit(*args, **kwargs)
  File "/var/lib/juju/agents/unit-postgresql-test-app-0/charm/venv/ops/framework.py", line 348, in emit
    framework._emit(event)
  File "/var/lib/juju/agents/unit-postgresql-test-app-0/charm/venv/ops/framework.py", line 860, in _emit
    self._reemit(event_path)
  File "/var/lib/juju/agents/unit-postgresql-test-app-0/charm/venv/ops/framework.py", line 950, in _reemit
    custom_handler(event)
  File "/var/lib/juju/agents/unit-postgresql-test-app-0/charm/./src/charm.py", line 289, in _on_clear_continuous_writes_action
    if self._connection_string is None:
  File "/var/lib/juju/agents/unit-postgresql-test-app-0/charm/./src/charm.py", line 259, in _connection_string
    data = list(self.first_database.fetch_relation_data().values())[0]
AttributeError: 'ApplicationCharm' object has no attribute 'first_database'
unit-postgresql-test-app-0: 02:41:07 ERROR unit.postgresql-test-app/0.juju-log Uncaught exception while in charm code:
Traceback (most recent call last):
  File "/var/lib/juju/agents/unit-postgresql-test-app-0/charm/./src/charm.py", line 538, in <module>
    main(ApplicationCharm)
  File "/var/lib/juju/agents/unit-postgresql-test-app-0/charm/venv/ops/main.py", line 551, in main
    manager.run()
  File "/var/lib/juju/agents/unit-postgresql-test-app-0/charm/venv/ops/main.py", line 530, in run
    self._emit()
  File "/var/lib/juju/agents/unit-postgresql-test-app-0/charm/venv/ops/main.py", line 519, in _emit
    _emit_charm_event(self.charm, self.dispatcher.event_name)
  File "/var/lib/juju/agents/unit-postgresql-test-app-0/charm/venv/ops/main.py", line 147, in _emit_charm_event
    event_to_emit.emit(*args, **kwargs)
  File "/var/lib/juju/agents/unit-postgresql-test-app-0/charm/venv/ops/framework.py", line 348, in emit
    framework._emit(event)
  File "/var/lib/juju/agents/unit-postgresql-test-app-0/charm/venv/ops/framework.py", line 860, in _emit
    self._reemit(event_path)
  File "/var/lib/juju/agents/unit-postgresql-test-app-0/charm/venv/ops/framework.py", line 950, in _reemit
    custom_handler(event)
  File "/var/lib/juju/agents/unit-postgresql-test-app-0/charm/./src/charm.py", line 289, in _on_clear_continuous_writes_action
    if self._connection_string is None:
  File "/var/lib/juju/agents/unit-postgresql-test-app-0/charm/./src/charm.py", line 259, in _connection_string
    data = list(self.first_database.fetch_relation_data().values())[0]
AttributeError: 'ApplicationCharm' object has no attribute 'first_database'
unit-postgresql-test-app-0: 02:41:11 ERROR unit.postgresql-test-app/0.juju-log Uncaught exception while in charm code:
Traceback (most recent call last):
  File "/var/lib/juju/agents/unit-postgresql-test-app-0/charm/./src/charm.py", line 538, in <module>
    main(ApplicationCharm)
  File "/var/lib/juju/agents/unit-postgresql-test-app-0/charm/venv/ops/main.py", line 551, in main
    manager.run()
  File "/var/lib/juju/agents/unit-postgresql-test-app-0/charm/venv/ops/main.py", line 530, in run
    self._emit()
  File "/var/lib/juju/agents/unit-postgresql-test-app-0/charm/venv/ops/main.py", line 519, in _emit
    _emit_charm_event(self.charm, self.dispatcher.event_name)
  File "/var/lib/juju/agents/unit-postgresql-test-app-0/charm/venv/ops/main.py", line 147, in _emit_charm_event
    event_to_emit.emit(*args, **kwargs)
  File "/var/lib/juju/agents/unit-postgresql-test-app-0/charm/venv/ops/framework.py", line 348, in emit
    framework._emit(event)
  File "/var/lib/juju/agents/unit-postgresql-test-app-0/charm/venv/ops/framework.py", line 860, in _emit
    self._reemit(event_path)
  File "/var/lib/juju/agents/unit-postgresql-test-app-0/charm/venv/ops/framework.py", line 950, in _reemit
    custom_handler(event)
  File "/var/lib/juju/agents/unit-postgresql-test-app-0/charm/./src/charm.py", line 289, in _on_clear_continuous_writes_action
    if self._connection_string is None:
  File "/var/lib/juju/agents/unit-postgresql-test-app-0/charm/./src/charm.py", line 259, in _connection_string
    data = list(self.first_database.fetch_relation_data().values())[0]
AttributeError: 'ApplicationCharm' object has no attribute 'first_database'
unit-postgresql-test-app-0: 02:41:15 ERROR unit.postgresql-test-app/0.juju-log Uncaught exception while in charm code:
Traceback (most recent call last):
  File "/var/lib/juju/agents/unit-postgresql-test-app-0/charm/./src/charm.py", line 538, in <module>
    main(ApplicationCharm)
  File "/var/lib/juju/agents/unit-postgresql-test-app-0/charm/venv/ops/main.py", line 551, in main
    manager.run()
  File "/var/lib/juju/agents/unit-postgresql-test-app-0/charm/venv/ops/main.py", line 530, in run
    self._emit()
  File "/var/lib/juju/agents/unit-postgresql-test-app-0/charm/venv/ops/main.py", line 519, in _emit
    _emit_charm_event(self.charm, self.dispatcher.event_name)
  File "/var/lib/juju/agents/unit-postgresql-test-app-0/charm/venv/ops/main.py", line 147, in _emit_charm_event
    event_to_emit.emit(*args, **kwargs)
  File "/var/lib/juju/agents/unit-postgresql-test-app-0/charm/venv/ops/framework.py", line 348, in emit
    framework._emit(event)
  File "/var/lib/juju/agents/unit-postgresql-test-app-0/charm/venv/ops/framework.py", line 860, in _emit
    self._reemit(event_path)
  File "/var/lib/juju/agents/unit-postgresql-test-app-0/charm/venv/ops/framework.py", line 950, in _reemit
    custom_handler(event)
  File "/var/lib/juju/agents/unit-postgresql-test-app-0/charm/./src/charm.py", line 289, in _on_clear_continuous_writes_action
    if self._connection_string is None:
  File "/var/lib/juju/agents/unit-postgresql-test-app-0/charm/./src/charm.py", line 259, in _connection_string
    data = list(self.first_database.fetch_relation_data().values())[0]
AttributeError: 'ApplicationCharm' object has no attribute 'first_database'
unit-postgresql-test-app-0: 02:41:19 ERROR unit.postgresql-test-app/0.juju-log Uncaught exception while in charm code:
Traceback (most recent call last):
  File "/var/lib/juju/agents/unit-postgresql-test-app-0/charm/./src/charm.py", line 538, in <module>
    main(ApplicationCharm)
  File "/var/lib/juju/agents/unit-postgresql-test-app-0/charm/venv/ops/main.py", line 551, in main
    manager.run()
  File "/var/lib/juju/agents/unit-postgresql-test-app-0/charm/venv/ops/main.py", line 530, in run
    self._emit()
  File "/var/lib/juju/agents/unit-postgresql-test-app-0/charm/venv/ops/main.py", line 519, in _emit
    _emit_charm_event(self.charm, self.dispatcher.event_name)
  File "/var/lib/juju/agents/unit-postgresql-test-app-0/charm/venv/ops/main.py", line 147, in _emit_charm_event
    event_to_emit.emit(*args, **kwargs)
  File "/var/lib/juju/agents/unit-postgresql-test-app-0/charm/venv/ops/framework.py", line 348, in emit
    framework._emit(event)
  File "/var/lib/juju/agents/unit-postgresql-test-app-0/charm/venv/ops/framework.py", line 860, in _emit
    self._reemit(event_path)
  File "/var/lib/juju/agents/unit-postgresql-test-app-0/charm/venv/ops/framework.py", line 950, in _reemit
    custom_handler(event)
  File "/var/lib/juju/agents/unit-postgresql-test-app-0/charm/./src/charm.py", line 289, in _on_clear_continuous_writes_action
    if self._connection_string is None:
  File "/var/lib/juju/agents/unit-postgresql-test-app-0/charm/./src/charm.py", line 259, in _connection_string
    data = list(self.first_database.fetch_relation_data().values())[0]
AttributeError: 'ApplicationCharm' object has no attribute 'first_database'
unit-postgresql-test-app-0: 02:41:23 ERROR unit.postgresql-test-app/0.juju-log Uncaught exception while in charm code:
Traceback (most recent call last):
  File "/var/lib/juju/agents/unit-postgresql-test-app-0/charm/./src/charm.py", line 538, in <module>
    main(ApplicationCharm)
  File "/var/lib/juju/agents/unit-postgresql-test-app-0/charm/venv/ops/main.py", line 551, in main
    manager.run()
  File "/var/lib/juju/agents/unit-postgresql-test-app-0/charm/venv/ops/main.py", line 530, in run
    self._emit()
  File "/var/lib/juju/agents/unit-postgresql-test-app-0/charm/venv/ops/main.py", line 519, in _emit
    _emit_charm_event(self.charm, self.dispatcher.event_name)
  File "/var/lib/juju/agents/unit-postgresql-test-app-0/charm/venv/ops/main.py", line 147, in _emit_charm_event
    event_to_emit.emit(*args, **kwargs)
  File "/var/lib/juju/agents/unit-postgresql-test-app-0/charm/venv/ops/framework.py", line 348, in emit
    framework._emit(event)
  File "/var/lib/juju/agents/unit-postgresql-test-app-0/charm/venv/ops/framework.py", line 860, in _emit
    self._reemit(event_path)
  File "/var/lib/juju/agents/unit-postgresql-test-app-0/charm/venv/ops/framework.py", line 950, in _reemit
    custom_handler(event)
  File "/var/lib/juju/agents/unit-postgresql-test-app-0/charm/./src/charm.py", line 289, in _on_clear_continuous_writes_action
    if self._connection_string is None:
  File "/var/lib/juju/agents/unit-postgresql-test-app-0/charm/./src/charm.py", line 259, in _connection_string
    data = list(self.first_database.fetch_relation_data().values())[0]
AttributeError: 'ApplicationCharm' object has no attribute 'first_database'
unit-postgresql-test-app-0: 02:41:27 ERROR unit.postgresql-test-app/0.juju-log Uncaught exception while in charm code:
Traceback (most recent call last):
  File "/var/lib/juju/agents/unit-postgresql-test-app-0/charm/./src/charm.py", line 538, in <module>
    main(ApplicationCharm)
  File "/var/lib/juju/agents/unit-postgresql-test-app-0/charm/venv/ops/main.py", line 551, in main
    manager.run()
  File "/var/lib/juju/agents/unit-postgresql-test-app-0/charm/venv/ops/main.py", line 530, in run
    self._emit()
  File "/var/lib/juju/agents/unit-postgresql-test-app-0/charm/venv/ops/main.py", line 519, in _emit
    _emit_charm_event(self.charm, self.dispatcher.event_name)
  File "/var/lib/juju/agents/unit-postgresql-test-app-0/charm/venv/ops/main.py", line 147, in _emit_charm_event
    event_to_emit.emit(*args, **kwargs)
  File "/var/lib/juju/agents/unit-postgresql-test-app-0/charm/venv/ops/framework.py", line 348, in emit
    framework._emit(event)
  File "/var/lib/juju/agents/unit-postgresql-test-app-0/charm/venv/ops/framework.py", line 860, in _emit
    self._reemit(event_path)
  File "/var/lib/juju/agents/unit-postgresql-test-app-0/charm/venv/ops/framework.py", line 950, in _reemit
    custom_handler(event)
  File "/var/lib/juju/agents/unit-postgresql-test-app-0/charm/./src/charm.py", line 289, in _on_clear_continuous_writes_action
    if self._connection_string is None:
  File "/var/lib/juju/agents/unit-postgresql-test-app-0/charm/./src/charm.py", line 259, in _connection_string
    data = list(self.first_database.fetch_relation_data().values())[0]
AttributeError: 'ApplicationCharm' object has no attribute 'first_database'
unit-postgresql-test-app-0: 02:41:31 ERROR unit.postgresql-test-app/0.juju-log Uncaught exception while in charm code:
Traceback (most recent call last):
  File "/var/lib/juju/agents/unit-postgresql-test-app-0/charm/./src/charm.py", line 538, in <module>
    main(ApplicationCharm)
  File "/var/lib/juju/agents/unit-postgresql-test-app-0/charm/venv/ops/main.py", line 551, in main
    manager.run()
  File "/var/lib/juju/agents/unit-postgresql-test-app-0/charm/venv/ops/main.py", line 530, in run
    self._emit()
  File "/var/lib/juju/agents/unit-postgresql-test-app-0/charm/venv/ops/main.py", line 519, in _emit
    _emit_charm_event(self.charm, self.dispatcher.event_name)
  File "/var/lib/juju/agents/unit-postgresql-test-app-0/charm/venv/ops/main.py", line 147, in _emit_charm_event
    event_to_emit.emit(*args, **kwargs)
  File "/var/lib/juju/agents/unit-postgresql-test-app-0/charm/venv/ops/framework.py", line 348, in emit
    framework._emit(event)
  File "/var/lib/juju/agents/unit-postgresql-test-app-0/charm/venv/ops/framework.py", line 860, in _emit
    self._reemit(event_path)
  File "/var/lib/juju/agents/unit-postgresql-test-app-0/charm/venv/ops/framework.py", line 950, in _reemit
    custom_handler(event)
  File "/var/lib/juju/agents/unit-postgresql-test-app-0/charm/./src/charm.py", line 289, in _on_clear_continuous_writes_action
    if self._connection_string is None:
  File "/var/lib/juju/agents/unit-postgresql-test-app-0/charm/./src/charm.py", line 259, in _connection_string
    data = list(self.first_database.fetch_relation_data().values())[0]
AttributeError: 'ApplicationCharm' object has no attribute 'first_database'
unit-postgresql-test-app-0: 02:41:35 ERROR unit.postgresql-test-app/0.juju-log Uncaught exception while in charm code:
Traceback (most recent call last):
  File "/var/lib/juju/agents/unit-postgresql-test-app-0/charm/./src/charm.py", line 538, in <module>
    main(ApplicationCharm)
  File "/var/lib/juju/agents/unit-postgresql-test-app-0/charm/venv/ops/main.py", line 551, in main
    manager.run()
  File "/var/lib/juju/agents/unit-postgresql-test-app-0/charm/venv/ops/main.py", line 530, in run
    self._emit()
  File "/var/lib/juju/agents/unit-postgresql-test-app-0/charm/venv/ops/main.py", line 519, in _emit
    _emit_charm_event(self.charm, self.dispatcher.event_name)
  File "/var/lib/juju/agents/unit-postgresql-test-app-0/charm/venv/ops/main.py", line 147, in _emit_charm_event
    event_to_emit.emit(*args, **kwargs)
  File "/var/lib/juju/agents/unit-postgresql-test-app-0/charm/venv/ops/framework.py", line 348, in emit
    framework._emit(event)
  File "/var/lib/juju/agents/unit-postgresql-test-app-0/charm/venv/ops/framework.py", line 860, in _emit
    self._reemit(event_path)
  File "/var/lib/juju/agents/unit-postgresql-test-app-0/charm/venv/ops/framework.py", line 950, in _reemit
    custom_handler(event)
  File "/var/lib/juju/agents/unit-postgresql-test-app-0/charm/./src/charm.py", line 289, in _on_clear_continuous_writes_action
    if self._connection_string is None:
  File "/var/lib/juju/agents/unit-postgresql-test-app-0/charm/./src/charm.py", line 259, in _connection_string
    data = list(self.first_database.fetch_relation_data().values())[0]
AttributeError: 'ApplicationCharm' object has no attribute 'first_database'
unit-postgresql-test-app-0: 02:41:39 ERROR unit.postgresql-test-app/0.juju-log Uncaught exception while in charm code:
Traceback (most recent call last):
  File "/var/lib/juju/agents/unit-postgresql-test-app-0/charm/./src/charm.py", line 538, in <module>
    main(ApplicationCharm)
  File "/var/lib/juju/agents/unit-postgresql-test-app-0/charm/venv/ops/main.py", line 551, in main
    manager.run()
  File "/var/lib/juju/agents/unit-postgresql-test-app-0/charm/venv/ops/main.py", line 530, in run
    self._emit()
  File "/var/lib/juju/agents/unit-postgresql-test-app-0/charm/venv/ops/main.py", line 519, in _emit
    _emit_charm_event(self.charm, self.dispatcher.event_name)
  File "/var/lib/juju/agents/unit-postgresql-test-app-0/charm/venv/ops/main.py", line 147, in _emit_charm_event
    event_to_emit.emit(*args, **kwargs)
  File "/var/lib/juju/agents/unit-postgresql-test-app-0/charm/venv/ops/framework.py", line 348, in emit
    framework._emit(event)
  File "/var/lib/juju/agents/unit-postgresql-test-app-0/charm/venv/ops/framework.py", line 860, in _emit
    self._reemit(event_path)
  File "/var/lib/juju/agents/unit-postgresql-test-app-0/charm/venv/ops/framework.py", line 950, in _reemit
    custom_handler(event)
  File "/var/lib/juju/agents/unit-postgresql-test-app-0/charm/./src/charm.py", line 289, in _on_clear_continuous_writes_action
    if self._connection_string is None:
  File "/var/lib/juju/agents/unit-postgresql-test-app-0/charm/./src/charm.py", line 259, in _connection_string
    data = list(self.first_database.fetch_relation_data().values())[0]
AttributeError: 'ApplicationCharm' object has no attribute 'first_database'
unit-postgresql-test-app-0: 02:41:43 ERROR unit.postgresql-test-app/0.juju-log Uncaught exception while in charm code:
Traceback (most recent call last):
  File "/var/lib/juju/agents/unit-postgresql-test-app-0/charm/./src/charm.py", line 538, in <module>
    main(ApplicationCharm)
  File "/var/lib/juju/agents/unit-postgresql-test-app-0/charm/venv/ops/main.py", line 551, in main
    manager.run()
  File "/var/lib/juju/agents/unit-postgresql-test-app-0/charm/venv/ops/main.py", line 530, in run
    self._emit()
  File "/var/lib/juju/agents/unit-postgresql-test-app-0/charm/venv/ops/main.py", line 519, in _emit
    _emit_charm_event(self.charm, self.dispatcher.event_name)
  File "/var/lib/juju/agents/unit-postgresql-test-app-0/charm/venv/ops/main.py", line 147, in _emit_charm_event
    event_to_emit.emit(*args, **kwargs)
  File "/var/lib/juju/agents/unit-postgresql-test-app-0/charm/venv/ops/framework.py", line 348, in emit
    framework._emit(event)
  File "/var/lib/juju/agents/unit-postgresql-test-app-0/charm/venv/ops/framework.py", line 860, in _emit
    self._reemit(event_path)
  File "/var/lib/juju/agents/unit-postgresql-test-app-0/charm/venv/ops/framework.py", line 950, in _reemit
    custom_handler(event)
  File "/var/lib/juju/agents/unit-postgresql-test-app-0/charm/./src/charm.py", line 289, in _on_clear_continuous_writes_action
    if self._connection_string is None:
  File "/var/lib/juju/agents/unit-postgresql-test-app-0/charm/./src/charm.py", line 259, in _connection_string
    data = list(self.first_database.fetch_relation_data().values())[0]
AttributeError: 'ApplicationCharm' object has no attribute 'first_database'
unit-postgresql-test-app-0: 02:41:47 ERROR unit.postgresql-test-app/0.juju-log Uncaught exception while in charm code:
Traceback (most recent call last):
  File "/var/lib/juju/agents/unit-postgresql-test-app-0/charm/./src/charm.py", line 538, in <module>
    main(ApplicationCharm)
  File "/var/lib/juju/agents/unit-postgresql-test-app-0/charm/venv/ops/main.py", line 551, in main
    manager.run()
  File "/var/lib/juju/agents/unit-postgresql-test-app-0/charm/venv/ops/main.py", line 530, in run
    self._emit()
  File "/var/lib/juju/agents/unit-postgresql-test-app-0/charm/venv/ops/main.py", line 519, in _emit
    _emit_charm_event(self.charm, self.dispatcher.event_name)
  File "/var/lib/juju/agents/unit-postgresql-test-app-0/charm/venv/ops/main.py", line 147, in _emit_charm_event
    event_to_emit.emit(*args, **kwargs)
  File "/var/lib/juju/agents/unit-postgresql-test-app-0/charm/venv/ops/framework.py", line 348, in emit
    framework._emit(event)
  File "/var/lib/juju/agents/unit-postgresql-test-app-0/charm/venv/ops/framework.py", line 860, in _emit
    self._reemit(event_path)
  File "/var/lib/juju/agents/unit-postgresql-test-app-0/charm/venv/ops/framework.py", line 950, in _reemit
    custom_handler(event)
  File "/var/lib/juju/agents/unit-postgresql-test-app-0/charm/./src/charm.py", line 289, in _on_clear_continuous_writes_action
    if self._connection_string is None:
  File "/var/lib/juju/agents/unit-postgresql-test-app-0/charm/./src/charm.py", line 259, in _connection_string
    data = list(self.first_database.fetch_relation_data().values())[0]
AttributeError: 'ApplicationCharm' object has no attribute 'first_database'
unit-postgresql-test-app-0: 02:41:51 ERROR unit.postgresql-test-app/0.juju-log Uncaught exception while in charm code:
Traceback (most recent call last):
  File "/var/lib/juju/agents/unit-postgresql-test-app-0/charm/./src/charm.py", line 538, in <module>
    main(ApplicationCharm)
  File "/var/lib/juju/agents/unit-postgresql-test-app-0/charm/venv/ops/main.py", line 551, in main
    manager.run()
  File "/var/lib/juju/agents/unit-postgresql-test-app-0/charm/venv/ops/main.py", line 530, in run
    self._emit()
  File "/var/lib/juju/agents/unit-postgresql-test-app-0/charm/venv/ops/main.py", line 519, in _emit
    _emit_charm_event(self.charm, self.dispatcher.event_name)
  File "/var/lib/juju/agents/unit-postgresql-test-app-0/charm/venv/ops/main.py", line 147, in _emit_charm_event
    event_to_emit.emit(*args, **kwargs)
  File "/var/lib/juju/agents/unit-postgresql-test-app-0/charm/venv/ops/framework.py", line 348, in emit
    framework._emit(event)
  File "/var/lib/juju/agents/unit-postgresql-test-app-0/charm/venv/ops/framework.py", line 860, in _emit
    self._reemit(event_path)
  File "/var/lib/juju/agents/unit-postgresql-test-app-0/charm/venv/ops/framework.py", line 950, in _reemit
    custom_handler(event)
  File "/var/lib/juju/agents/unit-postgresql-test-app-0/charm/./src/charm.py", line 289, in _on_clear_continuous_writes_action
    if self._connection_string is None:
  File "/var/lib/juju/agents/unit-postgresql-test-app-0/charm/./src/charm.py", line 259, in _connection_string
    data = list(self.first_database.fetch_relation_data().values())[0]
AttributeError: 'ApplicationCharm' object has no attribute 'first_database'
unit-postgresql-test-app-0: 02:41:55 ERROR unit.postgresql-test-app/0.juju-log Uncaught exception while in charm code:
Traceback (most recent call last):
  File "/var/lib/juju/agents/unit-postgresql-test-app-0/charm/./src/charm.py", line 538, in <module>
    main(ApplicationCharm)
  File "/var/lib/juju/agents/unit-postgresql-test-app-0/charm/venv/ops/main.py", line 551, in main
    manager.run()
  File "/var/lib/juju/agents/unit-postgresql-test-app-0/charm/venv/ops/main.py", line 530, in run
    self._emit()
  File "/var/lib/juju/agents/unit-postgresql-test-app-0/charm/venv/ops/main.py", line 519, in _emit
    _emit_charm_event(self.charm, self.dispatcher.event_name)
  File "/var/lib/juju/agents/unit-postgresql-test-app-0/charm/venv/ops/main.py", line 147, in _emit_charm_event
    event_to_emit.emit(*args, **kwargs)
  File "/var/lib/juju/agents/unit-postgresql-test-app-0/charm/venv/ops/framework.py", line 348, in emit
    framework._emit(event)
  File "/var/lib/juju/agents/unit-postgresql-test-app-0/charm/venv/ops/framework.py", line 860, in _emit
    self._reemit(event_path)
  File "/var/lib/juju/agents/unit-postgresql-test-app-0/charm/venv/ops/framework.py", line 950, in _reemit
    custom_handler(event)
  File "/var/lib/juju/agents/unit-postgresql-test-app-0/charm/./src/charm.py", line 289, in _on_clear_continuous_writes_action
    if self._connection_string is None:
  File "/var/lib/juju/agents/unit-postgresql-test-app-0/charm/./src/charm.py", line 259, in _connection_string
    data = list(self.first_database.fetch_relation_data().values())[0]
AttributeError: 'ApplicationCharm' object has no attribute 'first_database'
unit-postgresql-test-app-0: 02:41:59 ERROR unit.postgresql-test-app/0.juju-log Uncaught exception while in charm code:
Traceback (most recent call last):
  File "/var/lib/juju/agents/unit-postgresql-test-app-0/charm/./src/charm.py", line 538, in <module>
    main(ApplicationCharm)
  File "/var/lib/juju/agents/unit-postgresql-test-app-0/charm/venv/ops/main.py", line 551, in main
    manager.run()
  File "/var/lib/juju/agents/unit-postgresql-test-app-0/charm/venv/ops/main.py", line 530, in run
    self._emit()
  File "/var/lib/juju/agents/unit-postgresql-test-app-0/charm/venv/ops/main.py", line 519, in _emit
    _emit_charm_event(self.charm, self.dispatcher.event_name)
  File "/var/lib/juju/agents/unit-postgresql-test-app-0/charm/venv/ops/main.py", line 147, in _emit_charm_event
    event_to_emit.emit(*args, **kwargs)
  File "/var/lib/juju/agents/unit-postgresql-test-app-0/charm/venv/ops/framework.py", line 348, in emit
    framework._emit(event)
  File "/var/lib/juju/agents/unit-postgresql-test-app-0/charm/venv/ops/framework.py", line 860, in _emit
    self._reemit(event_path)
  File "/var/lib/juju/agents/unit-postgresql-test-app-0/charm/venv/ops/framework.py", line 950, in _reemit
    custom_handler(event)
  File "/var/lib/juju/agents/unit-postgresql-test-app-0/charm/./src/charm.py", line 289, in _on_clear_continuous_writes_action
    if self._connection_string is None:
  File "/var/lib/juju/agents/unit-postgresql-test-app-0/charm/./src/charm.py", line 259, in _connection_string
    data = list(self.first_database.fetch_relation_data().values())[0]
AttributeError: 'ApplicationCharm' object has no attribute 'first_database'
unit-postgresql-test-app-0: 02:42:03 ERROR unit.postgresql-test-app/0.juju-log Uncaught exception while in charm code:
Traceback (most recent call last):
  File "/var/lib/juju/agents/unit-postgresql-test-app-0/charm/./src/charm.py", line 538, in <module>
    main(ApplicationCharm)
  File "/var/lib/juju/agents/unit-postgresql-test-app-0/charm/venv/ops/main.py", line 551, in main
    manager.run()
  File "/var/lib/juju/agents/unit-postgresql-test-app-0/charm/venv/ops/main.py", line 530, in run
    self._emit()
  File "/var/lib/juju/agents/unit-postgresql-test-app-0/charm/venv/ops/main.py", line 519, in _emit
    _emit_charm_event(self.charm, self.dispatcher.event_name)
  File "/var/lib/juju/agents/unit-postgresql-test-app-0/charm/venv/ops/main.py", line 147, in _emit_charm_event
    event_to_emit.emit(*args, **kwargs)
  File "/var/lib/juju/agents/unit-postgresql-test-app-0/charm/venv/ops/framework.py", line 348, in emit
    framework._emit(event)
  File "/var/lib/juju/agents/unit-postgresql-test-app-0/charm/venv/ops/framework.py", line 860, in _emit
    self._reemit(event_path)
  File "/var/lib/juju/agents/unit-postgresql-test-app-0/charm/venv/ops/framework.py", line 950, in _reemit
    custom_handler(event)
  File "/var/lib/juju/agents/unit-postgresql-test-app-0/charm/./src/charm.py", line 289, in _on_clear_continuous_writes_action
    if self._connection_string is None:
  File "/var/lib/juju/agents/unit-postgresql-test-app-0/charm/./src/charm.py", line 259, in _connection_string
    data = list(self.first_database.fetch_relation_data().values())[0]
AttributeError: 'ApplicationCharm' object has no attribute 'first_database'
unit-postgresql-test-app-0: 02:42:08 ERROR unit.postgresql-test-app/0.juju-log Uncaught exception while in charm code:
Traceback (most recent call last):
  File "/var/lib/juju/agents/unit-postgresql-test-app-0/charm/./src/charm.py", line 538, in <module>
    main(ApplicationCharm)
  File "/var/lib/juju/agents/unit-postgresql-test-app-0/charm/venv/ops/main.py", line 551, in main
    manager.run()
  File "/var/lib/juju/agents/unit-postgresql-test-app-0/charm/venv/ops/main.py", line 530, in run
    self._emit()
  File "/var/lib/juju/agents/unit-postgresql-test-app-0/charm/venv/ops/main.py", line 519, in _emit
    _emit_charm_event(self.charm, self.dispatcher.event_name)
  File "/var/lib/juju/agents/unit-postgresql-test-app-0/charm/venv/ops/main.py", line 147, in _emit_charm_event
    event_to_emit.emit(*args, **kwargs)
  File "/var/lib/juju/agents/unit-postgresql-test-app-0/charm/venv/ops/framework.py", line 348, in emit
    framework._emit(event)
  File "/var/lib/juju/agents/unit-postgresql-test-app-0/charm/venv/ops/framework.py", line 860, in _emit
    self._reemit(event_path)
  File "/var/lib/juju/agents/unit-postgresql-test-app-0/charm/venv/ops/framework.py", line 950, in _reemit
    custom_handler(event)
  File "/var/lib/juju/agents/unit-postgresql-test-app-0/charm/./src/charm.py", line 289, in _on_clear_continuous_writes_action
    if self._connection_string is None:
  File "/var/lib/juju/agents/unit-postgresql-test-app-0/charm/./src/charm.py", line 259, in _connection_string
    data = list(self.first_database.fetch_relation_data().values())[0]
AttributeError: 'ApplicationCharm' object has no attribute 'first_database'
unit-postgresql-test-app-0: 02:42:12 ERROR unit.postgresql-test-app/0.juju-log Uncaught exception while in charm code:
Traceback (most recent call last):
  File "/var/lib/juju/agents/unit-postgresql-test-app-0/charm/./src/charm.py", line 538, in <module>
    main(ApplicationCharm)
  File "/var/lib/juju/agents/unit-postgresql-test-app-0/charm/venv/ops/main.py", line 551, in main
    manager.run()
  File "/var/lib/juju/agents/unit-postgresql-test-app-0/charm/venv/ops/main.py", line 530, in run
    self._emit()
  File "/var/lib/juju/agents/unit-postgresql-test-app-0/charm/venv/ops/main.py", line 519, in _emit
    _emit_charm_event(self.charm, self.dispatcher.event_name)
  File "/var/lib/juju/agents/unit-postgresql-test-app-0/charm/venv/ops/main.py", line 147, in _emit_charm_event
    event_to_emit.emit(*args, **kwargs)
  File "/var/lib/juju/agents/unit-postgresql-test-app-0/charm/venv/ops/framework.py", line 348, in emit
    framework._emit(event)
  File "/var/lib/juju/agents/unit-postgresql-test-app-0/charm/venv/ops/framework.py", line 860, in _emit
    self._reemit(event_path)
  File "/var/lib/juju/agents/unit-postgresql-test-app-0/charm/venv/ops/framework.py", line 950, in _reemit
    custom_handler(event)
  File "/var/lib/juju/agents/unit-postgresql-test-app-0/charm/./src/charm.py", line 289, in _on_clear_continuous_writes_action
    if self._connection_string is None:
  File "/var/lib/juju/agents/unit-postgresql-test-app-0/charm/./src/charm.py", line 259, in _connection_string
    data = list(self.first_database.fetch_relation_data().values())[0]
AttributeError: 'ApplicationCharm' object has no attribute 'first_database'
unit-postgresql-test-app-0: 02:42:16 ERROR unit.postgresql-test-app/0.juju-log Uncaught exception while in charm code:
Traceback (most recent call last):
  File "/var/lib/juju/agents/unit-postgresql-test-app-0/charm/./src/charm.py", line 538, in <module>
    main(ApplicationCharm)
  File "/var/lib/juju/agents/unit-postgresql-test-app-0/charm/venv/ops/main.py", line 551, in main
    manager.run()
  File "/var/lib/juju/agents/unit-postgresql-test-app-0/charm/venv/ops/main.py", line 530, in run
    self._emit()
  File "/var/lib/juju/agents/unit-postgresql-test-app-0/charm/venv/ops/main.py", line 519, in _emit
    _emit_charm_event(self.charm, self.dispatcher.event_name)
  File "/var/lib/juju/agents/unit-postgresql-test-app-0/charm/venv/ops/main.py", line 147, in _emit_charm_event
    event_to_emit.emit(*args, **kwargs)
  File "/var/lib/juju/agents/unit-postgresql-test-app-0/charm/venv/ops/framework.py", line 348, in emit
    framework._emit(event)
  File "/var/lib/juju/agents/unit-postgresql-test-app-0/charm/venv/ops/framework.py", line 860, in _emit
    self._reemit(event_path)
  File "/var/lib/juju/agents/unit-postgresql-test-app-0/charm/venv/ops/framework.py", line 950, in _reemit
    custom_handler(event)
  File "/var/lib/juju/agents/unit-postgresql-test-app-0/charm/./src/charm.py", line 289, in _on_clear_continuous_writes_action
    if self._connection_string is None:
  File "/var/lib/juju/agents/unit-postgresql-test-app-0/charm/./src/charm.py", line 259, in _connection_string
    data = list(self.first_database.fetch_relation_data().values())[0]
AttributeError: 'ApplicationCharm' object has no attribute 'first_database'
unit-postgresql-test-app-0: 02:42:20 ERROR unit.postgresql-test-app/0.juju-log Uncaught exception while in charm code:
Traceback (most recent call last):
  File "/var/lib/juju/agents/unit-postgresql-test-app-0/charm/./src/charm.py", line 538, in <module>
    main(ApplicationCharm)
  File "/var/lib/juju/agents/unit-postgresql-test-app-0/charm/venv/ops/main.py", line 551, in main
    manager.run()
  File "/var/lib/juju/agents/unit-postgresql-test-app-0/charm/venv/ops/main.py", line 530, in run
    self._emit()
  File "/var/lib/juju/agents/unit-postgresql-test-app-0/charm/venv/ops/main.py", line 519, in _emit
    _emit_charm_event(self.charm, self.dispatcher.event_name)
  File "/var/lib/juju/agents/unit-postgresql-test-app-0/charm/venv/ops/main.py", line 147, in _emit_charm_event
    event_to_emit.emit(*args, **kwargs)
  File "/var/lib/juju/agents/unit-postgresql-test-app-0/charm/venv/ops/framework.py", line 348, in emit
    framework._emit(event)
  File "/var/lib/juju/agents/unit-postgresql-test-app-0/charm/venv/ops/framework.py", line 860, in _emit
    self._reemit(event_path)
  File "/var/lib/juju/agents/unit-postgresql-test-app-0/charm/venv/ops/framework.py", line 950, in _reemit
    custom_handler(event)
  File "/var/lib/juju/agents/unit-postgresql-test-app-0/charm/./src/charm.py", line 289, in _on_clear_continuous_writes_action
    if self._connection_string is None:
  File "/var/lib/juju/agents/unit-postgresql-test-app-0/charm/./src/charm.py", line 259, in _connection_string
    data = list(self.first_database.fetch_relation_data().values())[0]
AttributeError: 'ApplicationCharm' object has no attribute 'first_database'
unit-postgresql-test-app-0: 02:42:24 ERROR unit.postgresql-test-app/0.juju-log Uncaught exception while in charm code:
Traceback (most recent call last):
  File "/var/lib/juju/agents/unit-postgresql-test-app-0/charm/./src/charm.py", line 538, in <module>
    main(ApplicationCharm)
  File "/var/lib/juju/agents/unit-postgresql-test-app-0/charm/venv/ops/main.py", line 551, in main
    manager.run()
  File "/var/lib/juju/agents/unit-postgresql-test-app-0/charm/venv/ops/main.py", line 530, in run
    self._emit()
  File "/var/lib/juju/agents/unit-postgresql-test-app-0/charm/venv/ops/main.py", line 519, in _emit
    _emit_charm_event(self.charm, self.dispatcher.event_name)
  File "/var/lib/juju/agents/unit-postgresql-test-app-0/charm/venv/ops/main.py", line 147, in _emit_charm_event
    event_to_emit.emit(*args, **kwargs)
  File "/var/lib/juju/agents/unit-postgresql-test-app-0/charm/venv/ops/framework.py", line 348, in emit
    framework._emit(event)
  File "/var/lib/juju/agents/unit-postgresql-test-app-0/charm/venv/ops/framework.py", line 860, in _emit
    self._reemit(event_path)
  File "/var/lib/juju/agents/unit-postgresql-test-app-0/charm/venv/ops/framework.py", line 950, in _reemit
    custom_handler(event)
  File "/var/lib/juju/agents/unit-postgresql-test-app-0/charm/./src/charm.py", line 289, in _on_clear_continuous_writes_action
    if self._connection_string is None:
  File "/var/lib/juju/agents/unit-postgresql-test-app-0/charm/./src/charm.py", line 259, in _connection_string
    data = list(self.first_database.fetch_relation_data().values())[0]
AttributeError: 'ApplicationCharm' object has no attribute 'first_database'
unit-postgresql-test-app-0: 02:42:28 ERROR unit.postgresql-test-app/0.juju-log Uncaught exception while in charm code:
Traceback (most recent call last):
  File "/var/lib/juju/agents/unit-postgresql-test-app-0/charm/./src/charm.py", line 538, in <module>
    main(ApplicationCharm)
  File "/var/lib/juju/agents/unit-postgresql-test-app-0/charm/venv/ops/main.py", line 551, in main
    manager.run()
  File "/var/lib/juju/agents/unit-postgresql-test-app-0/charm/venv/ops/main.py", line 530, in run
    self._emit()
  File "/var/lib/juju/agents/unit-postgresql-test-app-0/charm/venv/ops/main.py", line 519, in _emit
    _emit_charm_event(self.charm, self.dispatcher.event_name)
  File "/var/lib/juju/agents/unit-postgresql-test-app-0/charm/venv/ops/main.py", line 147, in _emit_charm_event
    event_to_emit.emit(*args, **kwargs)
  File "/var/lib/juju/agents/unit-postgresql-test-app-0/charm/venv/ops/framework.py", line 348, in emit
    framework._emit(event)
  File "/var/lib/juju/agents/unit-postgresql-test-app-0/charm/venv/ops/framework.py", line 860, in _emit
    self._reemit(event_path)
  File "/var/lib/juju/agents/unit-postgresql-test-app-0/charm/venv/ops/framework.py", line 950, in _reemit
    custom_handler(event)
  File "/var/lib/juju/agents/unit-postgresql-test-app-0/charm/./src/charm.py", line 289, in _on_clear_continuous_writes_action
    if self._connection_string is None:
  File "/var/lib/juju/agents/unit-postgresql-test-app-0/charm/./src/charm.py", line 259, in _connection_string
    data = list(self.first_database.fetch_relation_data().values())[0]
AttributeError: 'ApplicationCharm' object has no attribute 'first_database'
unit-postgresql-test-app-0: 02:42:32 ERROR unit.postgresql-test-app/0.juju-log Uncaught exception while in charm code:
Traceback (most recent call last):
  File "/var/lib/juju/agents/unit-postgresql-test-app-0/charm/./src/charm.py", line 538, in <module>
    main(ApplicationCharm)
  File "/var/lib/juju/agents/unit-postgresql-test-app-0/charm/venv/ops/main.py", line 551, in main
    manager.run()
  File "/var/lib/juju/agents/unit-postgresql-test-app-0/charm/venv/ops/main.py", line 530, in run
    self._emit()
  File "/var/lib/juju/agents/unit-postgresql-test-app-0/charm/venv/ops/main.py", line 519, in _emit
    _emit_charm_event(self.charm, self.dispatcher.event_name)
  File "/var/lib/juju/agents/unit-postgresql-test-app-0/charm/venv/ops/main.py", line 147, in _emit_charm_event
    event_to_emit.emit(*args, **kwargs)
  File "/var/lib/juju/agents/unit-postgresql-test-app-0/charm/venv/ops/framework.py", line 348, in emit
    framework._emit(event)
  File "/var/lib/juju/agents/unit-postgresql-test-app-0/charm/venv/ops/framework.py", line 860, in _emit
    self._reemit(event_path)
  File "/var/lib/juju/agents/unit-postgresql-test-app-0/charm/venv/ops/framework.py", line 950, in _reemit
    custom_handler(event)
  File "/var/lib/juju/agents/unit-postgresql-test-app-0/charm/./src/charm.py", line 289, in _on_clear_continuous_writes_action
    if self._connection_string is None:
  File "/var/lib/juju/agents/unit-postgresql-test-app-0/charm/./src/charm.py", line 259, in _connection_string
    data = list(self.first_database.fetch_relation_data().values())[0]
AttributeError: 'ApplicationCharm' object has no attribute 'first_database'
unit-postgresql-test-app-0: 02:42:36 ERROR unit.postgresql-test-app/0.juju-log Uncaught exception while in charm code:
Traceback (most recent call last):
  File "/var/lib/juju/agents/unit-postgresql-test-app-0/charm/./src/charm.py", line 538, in <module>
    main(ApplicationCharm)
  File "/var/lib/juju/agents/unit-postgresql-test-app-0/charm/venv/ops/main.py", line 551, in main
    manager.run()
  File "/var/lib/juju/agents/unit-postgresql-test-app-0/charm/venv/ops/main.py", line 530, in run
    self._emit()
  File "/var/lib/juju/agents/unit-postgresql-test-app-0/charm/venv/ops/main.py", line 519, in _emit
    _emit_charm_event(self.charm, self.dispatcher.event_name)
  File "/var/lib/juju/agents/unit-postgresql-test-app-0/charm/venv/ops/main.py", line 147, in _emit_charm_event
    event_to_emit.emit(*args, **kwargs)
  File "/var/lib/juju/agents/unit-postgresql-test-app-0/charm/venv/ops/framework.py", line 348, in emit
    framework._emit(event)
  File "/var/lib/juju/agents/unit-postgresql-test-app-0/charm/venv/ops/framework.py", line 860, in _emit
    self._reemit(event_path)
  File "/var/lib/juju/agents/unit-postgresql-test-app-0/charm/venv/ops/framework.py", line 950, in _reemit
    custom_handler(event)
  File "/var/lib/juju/agents/unit-postgresql-test-app-0/charm/./src/charm.py", line 289, in _on_clear_continuous_writes_action
    if self._connection_string is None:
  File "/var/lib/juju/agents/unit-postgresql-test-app-0/charm/./src/charm.py", line 259, in _connection_string
    data = list(self.first_database.fetch_relation_data().values())[0]
AttributeError: 'ApplicationCharm' object has no attribute 'first_database'
unit-postgresql-test-app-0: 02:42:40 ERROR unit.postgresql-test-app/0.juju-log Uncaught exception while in charm code:
Traceback (most recent call last):
  File "/var/lib/juju/agents/unit-postgresql-test-app-0/charm/./src/charm.py", line 538, in <module>
    main(ApplicationCharm)
  File "/var/lib/juju/agents/unit-postgresql-test-app-0/charm/venv/ops/main.py", line 551, in main
    manager.run()
  File "/var/lib/juju/agents/unit-postgresql-test-app-0/charm/venv/ops/main.py", line 530, in run
    self._emit()
  File "/var/lib/juju/agents/unit-postgresql-test-app-0/charm/venv/ops/main.py", line 519, in _emit
    _emit_charm_event(self.charm, self.dispatcher.event_name)
  File "/var/lib/juju/agents/unit-postgresql-test-app-0/charm/venv/ops/main.py", line 147, in _emit_charm_event
    event_to_emit.emit(*args, **kwargs)
  File "/var/lib/juju/agents/unit-postgresql-test-app-0/charm/venv/ops/framework.py", line 348, in emit
    framework._emit(event)
  File "/var/lib/juju/agents/unit-postgresql-test-app-0/charm/venv/ops/framework.py", line 860, in _emit
    self._reemit(event_path)
  File "/var/lib/juju/agents/unit-postgresql-test-app-0/charm/venv/ops/framework.py", line 950, in _reemit
    custom_handler(event)
  File "/var/lib/juju/agents/unit-postgresql-test-app-0/charm/./src/charm.py", line 289, in _on_clear_continuous_writes_action
    if self._connection_string is None:
  File "/var/lib/juju/agents/unit-postgresql-test-app-0/charm/./src/charm.py", line 259, in _connection_string
    data = list(self.first_database.fetch_relation_data().values())[0]
AttributeError: 'ApplicationCharm' object has no attribute 'first_database'
unit-postgresql-test-app-0: 02:42:44 ERROR unit.postgresql-test-app/0.juju-log Uncaught exception while in charm code:
Traceback (most recent call last):
  File "/var/lib/juju/agents/unit-postgresql-test-app-0/charm/./src/charm.py", line 538, in <module>
    main(ApplicationCharm)
  File "/var/lib/juju/agents/unit-postgresql-test-app-0/charm/venv/ops/main.py", line 551, in main
    manager.run()
  File "/var/lib/juju/agents/unit-postgresql-test-app-0/charm/venv/ops/main.py", line 530, in run
    self._emit()
  File "/var/lib/juju/agents/unit-postgresql-test-app-0/charm/venv/ops/main.py", line 519, in _emit
    _emit_charm_event(self.charm, self.dispatcher.event_name)
  File "/var/lib/juju/agents/unit-postgresql-test-app-0/charm/venv/ops/main.py", line 147, in _emit_charm_event
    event_to_emit.emit(*args, **kwargs)
  File "/var/lib/juju/agents/unit-postgresql-test-app-0/charm/venv/ops/framework.py", line 348, in emit
    framework._emit(event)
  File "/var/lib/juju/agents/unit-postgresql-test-app-0/charm/venv/ops/framework.py", line 860, in _emit
    self._reemit(event_path)
  File "/var/lib/juju/agents/unit-postgresql-test-app-0/charm/venv/ops/framework.py", line 950, in _reemit
    custom_handler(event)
  File "/var/lib/juju/agents/unit-postgresql-test-app-0/charm/./src/charm.py", line 289, in _on_clear_continuous_writes_action
    if self._connection_string is None:
  File "/var/lib/juju/agents/unit-postgresql-test-app-0/charm/./src/charm.py", line 259, in _connection_string
    data = list(self.first_database.fetch_relation_data().values())[0]
AttributeError: 'ApplicationCharm' object has no attribute 'first_database'
unit-postgresql-test-app-0: 02:42:48 ERROR unit.postgresql-test-app/0.juju-log Uncaught exception while in charm code:
Traceback (most recent call last):
  File "/var/lib/juju/agents/unit-postgresql-test-app-0/charm/./src/charm.py", line 538, in <module>
    main(ApplicationCharm)
  File "/var/lib/juju/agents/unit-postgresql-test-app-0/charm/venv/ops/main.py", line 551, in main
    manager.run()
  File "/var/lib/juju/agents/unit-postgresql-test-app-0/charm/venv/ops/main.py", line 530, in run
    self._emit()
  File "/var/lib/juju/agents/unit-postgresql-test-app-0/charm/venv/ops/main.py", line 519, in _emit
    _emit_charm_event(self.charm, self.dispatcher.event_name)
  File "/var/lib/juju/agents/unit-postgresql-test-app-0/charm/venv/ops/main.py", line 147, in _emit_charm_event
    event_to_emit.emit(*args, **kwargs)
  File "/var/lib/juju/agents/unit-postgresql-test-app-0/charm/venv/ops/framework.py", line 348, in emit
    framework._emit(event)
  File "/var/lib/juju/agents/unit-postgresql-test-app-0/charm/venv/ops/framework.py", line 860, in _emit
    self._reemit(event_path)
  File "/var/lib/juju/agents/unit-postgresql-test-app-0/charm/venv/ops/framework.py", line 950, in _reemit
    custom_handler(event)
  File "/var/lib/juju/agents/unit-postgresql-test-app-0/charm/./src/charm.py", line 289, in _on_clear_continuous_writes_action
    if self._connection_string is None:
  File "/var/lib/juju/agents/unit-postgresql-test-app-0/charm/./src/charm.py", line 259, in _connection_string
    data = list(self.first_database.fetch_relation_data().values())[0]
AttributeError: 'ApplicationCharm' object has no attribute 'first_database'
unit-postgresql-test-app-0: 02:42:52 ERROR unit.postgresql-test-app/0.juju-log Uncaught exception while in charm code:
Traceback (most recent call last):
  File "/var/lib/juju/agents/unit-postgresql-test-app-0/charm/./src/charm.py", line 538, in <module>
    main(ApplicationCharm)
  File "/var/lib/juju/agents/unit-postgresql-test-app-0/charm/venv/ops/main.py", line 551, in main
    manager.run()
  File "/var/lib/juju/agents/unit-postgresql-test-app-0/charm/venv/ops/main.py", line 530, in run
    self._emit()
  File "/var/lib/juju/agents/unit-postgresql-test-app-0/charm/venv/ops/main.py", line 519, in _emit
    _emit_charm_event(self.charm, self.dispatcher.event_name)
  File "/var/lib/juju/agents/unit-postgresql-test-app-0/charm/venv/ops/main.py", line 147, in _emit_charm_event
    event_to_emit.emit(*args, **kwargs)
  File "/var/lib/juju/agents/unit-postgresql-test-app-0/charm/venv/ops/framework.py", line 348, in emit
    framework._emit(event)
  File "/var/lib/juju/agents/unit-postgresql-test-app-0/charm/venv/ops/framework.py", line 860, in _emit
    self._reemit(event_path)
  File "/var/lib/juju/agents/unit-postgresql-test-app-0/charm/venv/ops/framework.py", line 950, in _reemit
    custom_handler(event)
  File "/var/lib/juju/agents/unit-postgresql-test-app-0/charm/./src/charm.py", line 289, in _on_clear_continuous_writes_action
    if self._connection_string is None:
  File "/var/lib/juju/agents/unit-postgresql-test-app-0/charm/./src/charm.py", line 259, in _connection_string
    data = list(self.first_database.fetch_relation_data().values())[0]
AttributeError: 'ApplicationCharm' object has no attribute 'first_database'
unit-postgresql-test-app-0: 02:42:56 ERROR unit.postgresql-test-app/0.juju-log Uncaught exception while in charm code:
Traceback (most recent call last):
  File "/var/lib/juju/agents/unit-postgresql-test-app-0/charm/./src/charm.py", line 538, in <module>
    main(ApplicationCharm)
  File "/var/lib/juju/agents/unit-postgresql-test-app-0/charm/venv/ops/main.py", line 551, in main
    manager.run()
  File "/var/lib/juju/agents/unit-postgresql-test-app-0/charm/venv/ops/main.py", line 530, in run
    self._emit()
  File "/var/lib/juju/agents/unit-postgresql-test-app-0/charm/venv/ops/main.py", line 519, in _emit
    _emit_charm_event(self.charm, self.dispatcher.event_name)
  File "/var/lib/juju/agents/unit-postgresql-test-app-0/charm/venv/ops/main.py", line 147, in _emit_charm_event
    event_to_emit.emit(*args, **kwargs)
  File "/var/lib/juju/agents/unit-postgresql-test-app-0/charm/venv/ops/framework.py", line 348, in emit
    framework._emit(event)
  File "/var/lib/juju/agents/unit-postgresql-test-app-0/charm/venv/ops/framework.py", line 860, in _emit
    self._reemit(event_path)
  File "/var/lib/juju/agents/unit-postgresql-test-app-0/charm/venv/ops/framework.py", line 950, in _reemit
    custom_handler(event)
  File "/var/lib/juju/agents/unit-postgresql-test-app-0/charm/./src/charm.py", line 289, in _on_clear_continuous_writes_action
    if self._connection_string is None:
  File "/var/lib/juju/agents/unit-postgresql-test-app-0/charm/./src/charm.py", line 259, in _connection_string
    data = list(self.first_database.fetch_relation_data().values())[0]
AttributeError: 'ApplicationCharm' object has no attribute 'first_database'
unit-postgresql-test-app-0: 02:43:00 ERROR unit.postgresql-test-app/0.juju-log Uncaught exception while in charm code:
Traceback (most recent call last):
  File "/var/lib/juju/agents/unit-postgresql-test-app-0/charm/./src/charm.py", line 538, in <module>
    main(ApplicationCharm)
  File "/var/lib/juju/agents/unit-postgresql-test-app-0/charm/venv/ops/main.py", line 551, in main
    manager.run()
  File "/var/lib/juju/agents/unit-postgresql-test-app-0/charm/venv/ops/main.py", line 530, in run
    self._emit()
  File "/var/lib/juju/agents/unit-postgresql-test-app-0/charm/venv/ops/main.py", line 519, in _emit
    _emit_charm_event(self.charm, self.dispatcher.event_name)
  File "/var/lib/juju/agents/unit-postgresql-test-app-0/charm/venv/ops/main.py", line 147, in _emit_charm_event
    event_to_emit.emit(*args, **kwargs)
  File "/var/lib/juju/agents/unit-postgresql-test-app-0/charm/venv/ops/framework.py", line 348, in emit
    framework._emit(event)
  File "/var/lib/juju/agents/unit-postgresql-test-app-0/charm/venv/ops/framework.py", line 860, in _emit
    self._reemit(event_path)
  File "/var/lib/juju/agents/unit-postgresql-test-app-0/charm/venv/ops/framework.py", line 950, in _reemit
    custom_handler(event)
  File "/var/lib/juju/agents/unit-postgresql-test-app-0/charm/./src/charm.py", line 289, in _on_clear_continuous_writes_action
    if self._connection_string is None:
  File "/var/lib/juju/agents/unit-postgresql-test-app-0/charm/./src/charm.py", line 259, in _connection_string
    data = list(self.first_database.fetch_relation_data().values())[0]
AttributeError: 'ApplicationCharm' object has no attribute 'first_database'
unit-postgresql-test-app-0: 02:43:04 ERROR unit.postgresql-test-app/0.juju-log Uncaught exception while in charm code:
Traceback (most recent call last):
  File "/var/lib/juju/agents/unit-postgresql-test-app-0/charm/./src/charm.py", line 538, in <module>
    main(ApplicationCharm)
  File "/var/lib/juju/agents/unit-postgresql-test-app-0/charm/venv/ops/main.py", line 551, in main
    manager.run()
  File "/var/lib/juju/agents/unit-postgresql-test-app-0/charm/venv/ops/main.py", line 530, in run
    self._emit()
  File "/var/lib/juju/agents/unit-postgresql-test-app-0/charm/venv/ops/main.py", line 519, in _emit
    _emit_charm_event(self.charm, self.dispatcher.event_name)
  File "/var/lib/juju/agents/unit-postgresql-test-app-0/charm/venv/ops/main.py", line 147, in _emit_charm_event
    event_to_emit.emit(*args, **kwargs)
  File "/var/lib/juju/agents/unit-postgresql-test-app-0/charm/venv/ops/framework.py", line 348, in emit
    framework._emit(event)
  File "/var/lib/juju/agents/unit-postgresql-test-app-0/charm/venv/ops/framework.py", line 860, in _emit
    self._reemit(event_path)
  File "/var/lib/juju/agents/unit-postgresql-test-app-0/charm/venv/ops/framework.py", line 950, in _reemit
    custom_handler(event)
  File "/var/lib/juju/agents/unit-postgresql-test-app-0/charm/./src/charm.py", line 289, in _on_clear_continuous_writes_action
    if self._connection_string is None:
  File "/var/lib/juju/agents/unit-postgresql-test-app-0/charm/./src/charm.py", line 259, in _connection_string
    data = list(self.first_database.fetch_relation_data().values())[0]
AttributeError: 'ApplicationCharm' object has no attribute 'first_database'
unit-postgresql-test-app-0: 02:43:08 ERROR unit.postgresql-test-app/0.juju-log Uncaught exception while in charm code:
Traceback (most recent call last):
  File "/var/lib/juju/agents/unit-postgresql-test-app-0/charm/./src/charm.py", line 538, in <module>
    main(ApplicationCharm)
  File "/var/lib/juju/agents/unit-postgresql-test-app-0/charm/venv/ops/main.py", line 551, in main
    manager.run()
  File "/var/lib/juju/agents/unit-postgresql-test-app-0/charm/venv/ops/main.py", line 530, in run
    self._emit()
  File "/var/lib/juju/agents/unit-postgresql-test-app-0/charm/venv/ops/main.py", line 519, in _emit
    _emit_charm_event(self.charm, self.dispatcher.event_name)
  File "/var/lib/juju/agents/unit-postgresql-test-app-0/charm/venv/ops/main.py", line 147, in _emit_charm_event
    event_to_emit.emit(*args, **kwargs)
  File "/var/lib/juju/agents/unit-postgresql-test-app-0/charm/venv/ops/framework.py", line 348, in emit
    framework._emit(event)
  File "/var/lib/juju/agents/unit-postgresql-test-app-0/charm/venv/ops/framework.py", line 860, in _emit
    self._reemit(event_path)
  File "/var/lib/juju/agents/unit-postgresql-test-app-0/charm/venv/ops/framework.py", line 950, in _reemit
    custom_handler(event)
  File "/var/lib/juju/agents/unit-postgresql-test-app-0/charm/./src/charm.py", line 289, in _on_clear_continuous_writes_action
    if self._connection_string is None:
  File "/var/lib/juju/agents/unit-postgresql-test-app-0/charm/./src/charm.py", line 259, in _connection_string
    data = list(self.first_database.fetch_relation_data().values())[0]
AttributeError: 'ApplicationCharm' object has no attribute 'first_database'
unit-postgresql-test-app-0: 02:43:12 ERROR unit.postgresql-test-app/0.juju-log Uncaught exception while in charm code:
Traceback (most recent call last):
  File "/var/lib/juju/agents/unit-postgresql-test-app-0/charm/./src/charm.py", line 538, in <module>
    main(ApplicationCharm)
  File "/var/lib/juju/agents/unit-postgresql-test-app-0/charm/venv/ops/main.py", line 551, in main
    manager.run()
  File "/var/lib/juju/agents/unit-postgresql-test-app-0/charm/venv/ops/main.py", line 530, in run
    self._emit()
  File "/var/lib/juju/agents/unit-postgresql-test-app-0/charm/venv/ops/main.py", line 519, in _emit
    _emit_charm_event(self.charm, self.dispatcher.event_name)
  File "/var/lib/juju/agents/unit-postgresql-test-app-0/charm/venv/ops/main.py", line 147, in _emit_charm_event
    event_to_emit.emit(*args, **kwargs)
  File "/var/lib/juju/agents/unit-postgresql-test-app-0/charm/venv/ops/framework.py", line 348, in emit
    framework._emit(event)
  File "/var/lib/juju/agents/unit-postgresql-test-app-0/charm/venv/ops/framework.py", line 860, in _emit
    self._reemit(event_path)
  File "/var/lib/juju/agents/unit-postgresql-test-app-0/charm/venv/ops/framework.py", line 950, in _reemit
    custom_handler(event)
  File "/var/lib/juju/agents/unit-postgresql-test-app-0/charm/./src/charm.py", line 289, in _on_clear_continuous_writes_action
    if self._connection_string is None:
  File "/var/lib/juju/agents/unit-postgresql-test-app-0/charm/./src/charm.py", line 259, in _connection_string
    data = list(self.first_database.fetch_relation_data().values())[0]
AttributeError: 'ApplicationCharm' object has no attribute 'first_database'
unit-postgresql-test-app-0: 02:43:16 ERROR unit.postgresql-test-app/0.juju-log Uncaught exception while in charm code:
Traceback (most recent call last):
  File "/var/lib/juju/agents/unit-postgresql-test-app-0/charm/./src/charm.py", line 538, in <module>
    main(ApplicationCharm)
  File "/var/lib/juju/agents/unit-postgresql-test-app-0/charm/venv/ops/main.py", line 551, in main
    manager.run()
  File "/var/lib/juju/agents/unit-postgresql-test-app-0/charm/venv/ops/main.py", line 530, in run
    self._emit()
  File "/var/lib/juju/agents/unit-postgresql-test-app-0/charm/venv/ops/main.py", line 519, in _emit
    _emit_charm_event(self.charm, self.dispatcher.event_name)
  File "/var/lib/juju/agents/unit-postgresql-test-app-0/charm/venv/ops/main.py", line 147, in _emit_charm_event
    event_to_emit.emit(*args, **kwargs)
  File "/var/lib/juju/agents/unit-postgresql-test-app-0/charm/venv/ops/framework.py", line 348, in emit
    framework._emit(event)
  File "/var/lib/juju/agents/unit-postgresql-test-app-0/charm/venv/ops/framework.py", line 860, in _emit
    self._reemit(event_path)
  File "/var/lib/juju/agents/unit-postgresql-test-app-0/charm/venv/ops/framework.py", line 950, in _reemit
    custom_handler(event)
  File "/var/lib/juju/agents/unit-postgresql-test-app-0/charm/./src/charm.py", line 289, in _on_clear_continuous_writes_action
    if self._connection_string is None:
  File "/var/lib/juju/agents/unit-postgresql-test-app-0/charm/./src/charm.py", line 259, in _connection_string
    data = list(self.first_database.fetch_relation_data().values())[0]
AttributeError: 'ApplicationCharm' object has no attribute 'first_database'
unit-postgresql-test-app-0: 02:43:20 ERROR unit.postgresql-test-app/0.juju-log Uncaught exception while in charm code:
Traceback (most recent call last):
  File "/var/lib/juju/agents/unit-postgresql-test-app-0/charm/./src/charm.py", line 538, in <module>
    main(ApplicationCharm)
  File "/var/lib/juju/agents/unit-postgresql-test-app-0/charm/venv/ops/main.py", line 551, in main
    manager.run()
  File "/var/lib/juju/agents/unit-postgresql-test-app-0/charm/venv/ops/main.py", line 530, in run
    self._emit()
  File "/var/lib/juju/agents/unit-postgresql-test-app-0/charm/venv/ops/main.py", line 519, in _emit
    _emit_charm_event(self.charm, self.dispatcher.event_name)
  File "/var/lib/juju/agents/unit-postgresql-test-app-0/charm/venv/ops/main.py", line 147, in _emit_charm_event
    event_to_emit.emit(*args, **kwargs)
  File "/var/lib/juju/agents/unit-postgresql-test-app-0/charm/venv/ops/framework.py", line 348, in emit
    framework._emit(event)
  File "/var/lib/juju/agents/unit-postgresql-test-app-0/charm/venv/ops/framework.py", line 860, in _emit
    self._reemit(event_path)
  File "/var/lib/juju/agents/unit-postgresql-test-app-0/charm/venv/ops/framework.py", line 950, in _reemit
    custom_handler(event)
  File "/var/lib/juju/agents/unit-postgresql-test-app-0/charm/./src/charm.py", line 289, in _on_clear_continuous_writes_action
    if self._connection_string is None:
  File "/var/lib/juju/agents/unit-postgresql-test-app-0/charm/./src/charm.py", line 259, in _connection_string
    data = list(self.first_database.fetch_relation_data().values())[0]
AttributeError: 'ApplicationCharm' object has no attribute 'first_database'
unit-postgresql-test-app-0: 02:43:24 ERROR unit.postgresql-test-app/0.juju-log Uncaught exception while in charm code:
Traceback (most recent call last):
  File "/var/lib/juju/agents/unit-postgresql-test-app-0/charm/./src/charm.py", line 538, in <module>
    main(ApplicationCharm)
  File "/var/lib/juju/agents/unit-postgresql-test-app-0/charm/venv/ops/main.py", line 551, in main
    manager.run()
  File "/var/lib/juju/agents/unit-postgresql-test-app-0/charm/venv/ops/main.py", line 530, in run
    self._emit()
  File "/var/lib/juju/agents/unit-postgresql-test-app-0/charm/venv/ops/main.py", line 519, in _emit
    _emit_charm_event(self.charm, self.dispatcher.event_name)
  File "/var/lib/juju/agents/unit-postgresql-test-app-0/charm/venv/ops/main.py", line 147, in _emit_charm_event
    event_to_emit.emit(*args, **kwargs)
  File "/var/lib/juju/agents/unit-postgresql-test-app-0/charm/venv/ops/framework.py", line 348, in emit
    framework._emit(event)
  File "/var/lib/juju/agents/unit-postgresql-test-app-0/charm/venv/ops/framework.py", line 860, in _emit
    self._reemit(event_path)
  File "/var/lib/juju/agents/unit-postgresql-test-app-0/charm/venv/ops/framework.py", line 950, in _reemit
    custom_handler(event)
  File "/var/lib/juju/agents/unit-postgresql-test-app-0/charm/./src/charm.py", line 289, in _on_clear_continuous_writes_action
    if self._connection_string is None:
  File "/var/lib/juju/agents/unit-postgresql-test-app-0/charm/./src/charm.py", line 259, in _connection_string
    data = list(self.first_database.fetch_relation_data().values())[0]
AttributeError: 'ApplicationCharm' object has no attribute 'first_database'
unit-postgresql-test-app-0: 02:43:28 ERROR unit.postgresql-test-app/0.juju-log Uncaught exception while in charm code:
Traceback (most recent call last):
  File "/var/lib/juju/agents/unit-postgresql-test-app-0/charm/./src/charm.py", line 538, in <module>
    main(ApplicationCharm)
  File "/var/lib/juju/agents/unit-postgresql-test-app-0/charm/venv/ops/main.py", line 551, in main
    manager.run()
  File "/var/lib/juju/agents/unit-postgresql-test-app-0/charm/venv/ops/main.py", line 530, in run
    self._emit()
  File "/var/lib/juju/agents/unit-postgresql-test-app-0/charm/venv/ops/main.py", line 519, in _emit
    _emit_charm_event(self.charm, self.dispatcher.event_name)
  File "/var/lib/juju/agents/unit-postgresql-test-app-0/charm/venv/ops/main.py", line 147, in _emit_charm_event
    event_to_emit.emit(*args, **kwargs)
  File "/var/lib/juju/agents/unit-postgresql-test-app-0/charm/venv/ops/framework.py", line 348, in emit
    framework._emit(event)
  File "/var/lib/juju/agents/unit-postgresql-test-app-0/charm/venv/ops/framework.py", line 860, in _emit
    self._reemit(event_path)
  File "/var/lib/juju/agents/unit-postgresql-test-app-0/charm/venv/ops/framework.py", line 950, in _reemit
    custom_handler(event)
  File "/var/lib/juju/agents/unit-postgresql-test-app-0/charm/./src/charm.py", line 289, in _on_clear_continuous_writes_action
    if self._connection_string is None:
  File "/var/lib/juju/agents/unit-postgresql-test-app-0/charm/./src/charm.py", line 259, in _connection_string
    data = list(self.first_database.fetch_relation_data().values())[0]
AttributeError: 'ApplicationCharm' object has no attribute 'first_database'
unit-postgresql-test-app-0: 02:43:32 ERROR unit.postgresql-test-app/0.juju-log Uncaught exception while in charm code:
Traceback (most recent call last):
  File "/var/lib/juju/agents/unit-postgresql-test-app-0/charm/./src/charm.py", line 538, in <module>
    main(ApplicationCharm)
  File "/var/lib/juju/agents/unit-postgresql-test-app-0/charm/venv/ops/main.py", line 551, in main
    manager.run()
  File "/var/lib/juju/agents/unit-postgresql-test-app-0/charm/venv/ops/main.py", line 530, in run
    self._emit()
  File "/var/lib/juju/agents/unit-postgresql-test-app-0/charm/venv/ops/main.py", line 519, in _emit
    _emit_charm_event(self.charm, self.dispatcher.event_name)
  File "/var/lib/juju/agents/unit-postgresql-test-app-0/charm/venv/ops/main.py", line 147, in _emit_charm_event
    event_to_emit.emit(*args, **kwargs)
  File "/var/lib/juju/agents/unit-postgresql-test-app-0/charm/venv/ops/framework.py", line 348, in emit
    framework._emit(event)
  File "/var/lib/juju/agents/unit-postgresql-test-app-0/charm/venv/ops/framework.py", line 860, in _emit
    self._reemit(event_path)
  File "/var/lib/juju/agents/unit-postgresql-test-app-0/charm/venv/ops/framework.py", line 950, in _reemit
    custom_handler(event)
  File "/var/lib/juju/agents/unit-postgresql-test-app-0/charm/./src/charm.py", line 289, in _on_clear_continuous_writes_action
    if self._connection_string is None:
  File "/var/lib/juju/agents/unit-postgresql-test-app-0/charm/./src/charm.py", line 259, in _connection_string
    data = list(self.first_database.fetch_relation_data().values())[0]
AttributeError: 'ApplicationCharm' object has no attribute 'first_database'
unit-postgresql-test-app-0: 02:43:36 ERROR unit.postgresql-test-app/0.juju-log Uncaught exception while in charm code:
Traceback (most recent call last):
  File "/var/lib/juju/agents/unit-postgresql-test-app-0/charm/./src/charm.py", line 538, in <module>
    main(ApplicationCharm)
  File "/var/lib/juju/agents/unit-postgresql-test-app-0/charm/venv/ops/main.py", line 551, in main
    manager.run()
  File "/var/lib/juju/agents/unit-postgresql-test-app-0/charm/venv/ops/main.py", line 530, in run
    self._emit()
  File "/var/lib/juju/agents/unit-postgresql-test-app-0/charm/venv/ops/main.py", line 519, in _emit
    _emit_charm_event(self.charm, self.dispatcher.event_name)
  File "/var/lib/juju/agents/unit-postgresql-test-app-0/charm/venv/ops/main.py", line 147, in _emit_charm_event
    event_to_emit.emit(*args, **kwargs)
  File "/var/lib/juju/agents/unit-postgresql-test-app-0/charm/venv/ops/framework.py", line 348, in emit
    framework._emit(event)
  File "/var/lib/juju/agents/unit-postgresql-test-app-0/charm/venv/ops/framework.py", line 860, in _emit
    self._reemit(event_path)
  File "/var/lib/juju/agents/unit-postgresql-test-app-0/charm/venv/ops/framework.py", line 950, in _reemit
    custom_handler(event)
  File "/var/lib/juju/agents/unit-postgresql-test-app-0/charm/./src/charm.py", line 289, in _on_clear_continuous_writes_action
    if self._connection_string is None:
  File "/var/lib/juju/agents/unit-postgresql-test-app-0/charm/./src/charm.py", line 259, in _connection_string
    data = list(self.first_database.fetch_relation_data().values())[0]
AttributeError: 'ApplicationCharm' object has no attribute 'first_database'
unit-postgresql-test-app-0: 02:43:40 ERROR unit.postgresql-test-app/0.juju-log Uncaught exception while in charm code:
Traceback (most recent call last):
  File "/var/lib/juju/agents/unit-postgresql-test-app-0/charm/./src/charm.py", line 538, in <module>
    main(ApplicationCharm)
  File "/var/lib/juju/agents/unit-postgresql-test-app-0/charm/venv/ops/main.py", line 551, in main
    manager.run()
  File "/var/lib/juju/agents/unit-postgresql-test-app-0/charm/venv/ops/main.py", line 530, in run
    self._emit()
  File "/var/lib/juju/agents/unit-postgresql-test-app-0/charm/venv/ops/main.py", line 519, in _emit
    _emit_charm_event(self.charm, self.dispatcher.event_name)
  File "/var/lib/juju/agents/unit-postgresql-test-app-0/charm/venv/ops/main.py", line 147, in _emit_charm_event
    event_to_emit.emit(*args, **kwargs)
  File "/var/lib/juju/agents/unit-postgresql-test-app-0/charm/venv/ops/framework.py", line 348, in emit
    framework._emit(event)
  File "/var/lib/juju/agents/unit-postgresql-test-app-0/charm/venv/ops/framework.py", line 860, in _emit
    self._reemit(event_path)
  File "/var/lib/juju/agents/unit-postgresql-test-app-0/charm/venv/ops/framework.py", line 950, in _reemit
    custom_handler(event)
  File "/var/lib/juju/agents/unit-postgresql-test-app-0/charm/./src/charm.py", line 289, in _on_clear_continuous_writes_action
    if self._connection_string is None:
  File "/var/lib/juju/agents/unit-postgresql-test-app-0/charm/./src/charm.py", line 259, in _connection_string
    data = list(self.first_database.fetch_relation_data().values())[0]
AttributeError: 'ApplicationCharm' object has no attribute 'first_database'
unit-postgresql-test-app-0: 02:43:44 ERROR unit.postgresql-test-app/0.juju-log Uncaught exception while in charm code:
Traceback (most recent call last):
  File "/var/lib/juju/agents/unit-postgresql-test-app-0/charm/./src/charm.py", line 538, in <module>
    main(ApplicationCharm)
  File "/var/lib/juju/agents/unit-postgresql-test-app-0/charm/venv/ops/main.py", line 551, in main
    manager.run()
  File "/var/lib/juju/agents/unit-postgresql-test-app-0/charm/venv/ops/main.py", line 530, in run
    self._emit()
  File "/var/lib/juju/agents/unit-postgresql-test-app-0/charm/venv/ops/main.py", line 519, in _emit
    _emit_charm_event(self.charm, self.dispatcher.event_name)
  File "/var/lib/juju/agents/unit-postgresql-test-app-0/charm/venv/ops/main.py", line 147, in _emit_charm_event
    event_to_emit.emit(*args, **kwargs)
  File "/var/lib/juju/agents/unit-postgresql-test-app-0/charm/venv/ops/framework.py", line 348, in emit
    framework._emit(event)
  File "/var/lib/juju/agents/unit-postgresql-test-app-0/charm/venv/ops/framework.py", line 860, in _emit
    self._reemit(event_path)
  File "/var/lib/juju/agents/unit-postgresql-test-app-0/charm/venv/ops/framework.py", line 950, in _reemit
    custom_handler(event)
  File "/var/lib/juju/agents/unit-postgresql-test-app-0/charm/./src/charm.py", line 289, in _on_clear_continuous_writes_action
    if self._connection_string is None:
  File "/var/lib/juju/agents/unit-postgresql-test-app-0/charm/./src/charm.py", line 259, in _connection_string
    data = list(self.first_database.fetch_relation_data().values())[0]
AttributeError: 'ApplicationCharm' object has no attribute 'first_database'
unit-postgresql-test-app-0: 02:43:49 ERROR unit.postgresql-test-app/0.juju-log Uncaught exception while in charm code:
Traceback (most recent call last):
  File "/var/lib/juju/agents/unit-postgresql-test-app-0/charm/./src/charm.py", line 538, in <module>
    main(ApplicationCharm)
  File "/var/lib/juju/agents/unit-postgresql-test-app-0/charm/venv/ops/main.py", line 551, in main
    manager.run()
  File "/var/lib/juju/agents/unit-postgresql-test-app-0/charm/venv/ops/main.py", line 530, in run
    self._emit()
  File "/var/lib/juju/agents/unit-postgresql-test-app-0/charm/venv/ops/main.py", line 519, in _emit
    _emit_charm_event(self.charm, self.dispatcher.event_name)
  File "/var/lib/juju/agents/unit-postgresql-test-app-0/charm/venv/ops/main.py", line 147, in _emit_charm_event
    event_to_emit.emit(*args, **kwargs)
  File "/var/lib/juju/agents/unit-postgresql-test-app-0/charm/venv/ops/framework.py", line 348, in emit
    framework._emit(event)
  File "/var/lib/juju/agents/unit-postgresql-test-app-0/charm/venv/ops/framework.py", line 860, in _emit
    self._reemit(event_path)
  File "/var/lib/juju/agents/unit-postgresql-test-app-0/charm/venv/ops/framework.py", line 950, in _reemit
    custom_handler(event)
  File "/var/lib/juju/agents/unit-postgresql-test-app-0/charm/./src/charm.py", line 289, in _on_clear_continuous_writes_action
    if self._connection_string is None:
  File "/var/lib/juju/agents/unit-postgresql-test-app-0/charm/./src/charm.py", line 259, in _connection_string
    data = list(self.first_database.fetch_relation_data().values())[0]
AttributeError: 'ApplicationCharm' object has no attribute 'first_database'
unit-postgresql-test-app-0: 02:43:53 ERROR unit.postgresql-test-app/0.juju-log Uncaught exception while in charm code:
Traceback (most recent call last):
  File "/var/lib/juju/agents/unit-postgresql-test-app-0/charm/./src/charm.py", line 538, in <module>
    main(ApplicationCharm)
  File "/var/lib/juju/agents/unit-postgresql-test-app-0/charm/venv/ops/main.py", line 551, in main
    manager.run()
  File "/var/lib/juju/agents/unit-postgresql-test-app-0/charm/venv/ops/main.py", line 530, in run
    self._emit()
  File "/var/lib/juju/agents/unit-postgresql-test-app-0/charm/venv/ops/main.py", line 519, in _emit
    _emit_charm_event(self.charm, self.dispatcher.event_name)
  File "/var/lib/juju/agents/unit-postgresql-test-app-0/charm/venv/ops/main.py", line 147, in _emit_charm_event
    event_to_emit.emit(*args, **kwargs)
  File "/var/lib/juju/agents/unit-postgresql-test-app-0/charm/venv/ops/framework.py", line 348, in emit
    framework._emit(event)
  File "/var/lib/juju/agents/unit-postgresql-test-app-0/charm/venv/ops/framework.py", line 860, in _emit
    self._reemit(event_path)
  File "/var/lib/juju/agents/unit-postgresql-test-app-0/charm/venv/ops/framework.py", line 950, in _reemit
    custom_handler(event)
  File "/var/lib/juju/agents/unit-postgresql-test-app-0/charm/./src/charm.py", line 289, in _on_clear_continuous_writes_action
    if self._connection_string is None:
  File "/var/lib/juju/agents/unit-postgresql-test-app-0/charm/./src/charm.py", line 259, in _connection_string
    data = list(self.first_database.fetch_relation_data().values())[0]
AttributeError: 'ApplicationCharm' object has no attribute 'first_database'
unit-postgresql-test-app-0: 02:43:57 ERROR unit.postgresql-test-app/0.juju-log Uncaught exception while in charm code:
Traceback (most recent call last):
  File "/var/lib/juju/agents/unit-postgresql-test-app-0/charm/./src/charm.py", line 538, in <module>
    main(ApplicationCharm)
  File "/var/lib/juju/agents/unit-postgresql-test-app-0/charm/venv/ops/main.py", line 551, in main
    manager.run()
  File "/var/lib/juju/agents/unit-postgresql-test-app-0/charm/venv/ops/main.py", line 530, in run
    self._emit()
  File "/var/lib/juju/agents/unit-postgresql-test-app-0/charm/venv/ops/main.py", line 519, in _emit
    _emit_charm_event(self.charm, self.dispatcher.event_name)
  File "/var/lib/juju/agents/unit-postgresql-test-app-0/charm/venv/ops/main.py", line 147, in _emit_charm_event
    event_to_emit.emit(*args, **kwargs)
  File "/var/lib/juju/agents/unit-postgresql-test-app-0/charm/venv/ops/framework.py", line 348, in emit
    framework._emit(event)
  File "/var/lib/juju/agents/unit-postgresql-test-app-0/charm/venv/ops/framework.py", line 860, in _emit
    self._reemit(event_path)
  File "/var/lib/juju/agents/unit-postgresql-test-app-0/charm/venv/ops/framework.py", line 950, in _reemit
    custom_handler(event)
  File "/var/lib/juju/agents/unit-postgresql-test-app-0/charm/./src/charm.py", line 289, in _on_clear_continuous_writes_action
    if self._connection_string is None:
  File "/var/lib/juju/agents/unit-postgresql-test-app-0/charm/./src/charm.py", line 259, in _connection_string
    data = list(self.first_database.fetch_relation_data().values())[0]
AttributeError: 'ApplicationCharm' object has no attribute 'first_database'
unit-postgresql-test-app-0: 02:44:01 ERROR unit.postgresql-test-app/0.juju-log Uncaught exception while in charm code:
Traceback (most recent call last):
  File "/var/lib/juju/agents/unit-postgresql-test-app-0/charm/./src/charm.py", line 538, in <module>
    main(ApplicationCharm)
  File "/var/lib/juju/agents/unit-postgresql-test-app-0/charm/venv/ops/main.py", line 551, in main
    manager.run()
  File "/var/lib/juju/agents/unit-postgresql-test-app-0/charm/venv/ops/main.py", line 530, in run
    self._emit()
  File "/var/lib/juju/agents/unit-postgresql-test-app-0/charm/venv/ops/main.py", line 519, in _emit
    _emit_charm_event(self.charm, self.dispatcher.event_name)
  File "/var/lib/juju/agents/unit-postgresql-test-app-0/charm/venv/ops/main.py", line 147, in _emit_charm_event
    event_to_emit.emit(*args, **kwargs)
  File "/var/lib/juju/agents/unit-postgresql-test-app-0/charm/venv/ops/framework.py", line 348, in emit
    framework._emit(event)
  File "/var/lib/juju/agents/unit-postgresql-test-app-0/charm/venv/ops/framework.py", line 860, in _emit
    self._reemit(event_path)
  File "/var/lib/juju/agents/unit-postgresql-test-app-0/charm/venv/ops/framework.py", line 950, in _reemit
    custom_handler(event)
  File "/var/lib/juju/agents/unit-postgresql-test-app-0/charm/./src/charm.py", line 289, in _on_clear_continuous_writes_action
    if self._connection_string is None:
  File "/var/lib/juju/agents/unit-postgresql-test-app-0/charm/./src/charm.py", line 259, in _connection_string
    data = list(self.first_database.fetch_relation_data().values())[0]
AttributeError: 'ApplicationCharm' object has no attribute 'first_database'
unit-postgresql-test-app-0: 02:44:05 ERROR unit.postgresql-test-app/0.juju-log Uncaught exception while in charm code:
Traceback (most recent call last):
  File "/var/lib/juju/agents/unit-postgresql-test-app-0/charm/./src/charm.py", line 538, in <module>
    main(ApplicationCharm)
  File "/var/lib/juju/agents/unit-postgresql-test-app-0/charm/venv/ops/main.py", line 551, in main
    manager.run()
  File "/var/lib/juju/agents/unit-postgresql-test-app-0/charm/venv/ops/main.py", line 530, in run
    self._emit()
  File "/var/lib/juju/agents/unit-postgresql-test-app-0/charm/venv/ops/main.py", line 519, in _emit
    _emit_charm_event(self.charm, self.dispatcher.event_name)
  File "/var/lib/juju/agents/unit-postgresql-test-app-0/charm/venv/ops/main.py", line 147, in _emit_charm_event
    event_to_emit.emit(*args, **kwargs)
  File "/var/lib/juju/agents/unit-postgresql-test-app-0/charm/venv/ops/framework.py", line 348, in emit
    framework._emit(event)
  File "/var/lib/juju/agents/unit-postgresql-test-app-0/charm/venv/ops/framework.py", line 860, in _emit
    self._reemit(event_path)
  File "/var/lib/juju/agents/unit-postgresql-test-app-0/charm/venv/ops/framework.py", line 950, in _reemit
    custom_handler(event)
  File "/var/lib/juju/agents/unit-postgresql-test-app-0/charm/./src/charm.py", line 289, in _on_clear_continuous_writes_action
    if self._connection_string is None:
  File "/var/lib/juju/agents/unit-postgresql-test-app-0/charm/./src/charm.py", line 259, in _connection_string
    data = list(self.first_database.fetch_relation_data().values())[0]
AttributeError: 'ApplicationCharm' object has no attribute 'first_database'
unit-postgresql-test-app-0: 02:44:09 ERROR unit.postgresql-test-app/0.juju-log Uncaught exception while in charm code:
Traceback (most recent call last):
  File "/var/lib/juju/agents/unit-postgresql-test-app-0/charm/./src/charm.py", line 538, in <module>
    main(ApplicationCharm)
  File "/var/lib/juju/agents/unit-postgresql-test-app-0/charm/venv/ops/main.py", line 551, in main
    manager.run()
  File "/var/lib/juju/agents/unit-postgresql-test-app-0/charm/venv/ops/main.py", line 530, in run
    self._emit()
  File "/var/lib/juju/agents/unit-postgresql-test-app-0/charm/venv/ops/main.py", line 519, in _emit
    _emit_charm_event(self.charm, self.dispatcher.event_name)
  File "/var/lib/juju/agents/unit-postgresql-test-app-0/charm/venv/ops/main.py", line 147, in _emit_charm_event
    event_to_emit.emit(*args, **kwargs)
  File "/var/lib/juju/agents/unit-postgresql-test-app-0/charm/venv/ops/framework.py", line 348, in emit
    framework._emit(event)
  File "/var/lib/juju/agents/unit-postgresql-test-app-0/charm/venv/ops/framework.py", line 860, in _emit
    self._reemit(event_path)
  File "/var/lib/juju/agents/unit-postgresql-test-app-0/charm/venv/ops/framework.py", line 950, in _reemit
    custom_handler(event)
  File "/var/lib/juju/agents/unit-postgresql-test-app-0/charm/./src/charm.py", line 289, in _on_clear_continuous_writes_action
    if self._connection_string is None:
  File "/var/lib/juju/agents/unit-postgresql-test-app-0/charm/./src/charm.py", line 259, in _connection_string
    data = list(self.first_database.fetch_relation_data().values())[0]
AttributeError: 'ApplicationCharm' object has no attribute 'first_database'
unit-postgresql-test-app-0: 02:44:13 ERROR unit.postgresql-test-app/0.juju-log Uncaught exception while in charm code:
Traceback (most recent call last):
  File "/var/lib/juju/agents/unit-postgresql-test-app-0/charm/./src/charm.py", line 538, in <module>
    main(ApplicationCharm)
  File "/var/lib/juju/agents/unit-postgresql-test-app-0/charm/venv/ops/main.py", line 551, in main
    manager.run()
  File "/var/lib/juju/agents/unit-postgresql-test-app-0/charm/venv/ops/main.py", line 530, in run
    self._emit()
  File "/var/lib/juju/agents/unit-postgresql-test-app-0/charm/venv/ops/main.py", line 519, in _emit
    _emit_charm_event(self.charm, self.dispatcher.event_name)
  File "/var/lib/juju/agents/unit-postgresql-test-app-0/charm/venv/ops/main.py", line 147, in _emit_charm_event
    event_to_emit.emit(*args, **kwargs)
  File "/var/lib/juju/agents/unit-postgresql-test-app-0/charm/venv/ops/framework.py", line 348, in emit
    framework._emit(event)
  File "/var/lib/juju/agents/unit-postgresql-test-app-0/charm/venv/ops/framework.py", line 860, in _emit
    self._reemit(event_path)
  File "/var/lib/juju/agents/unit-postgresql-test-app-0/charm/venv/ops/framework.py", line 950, in _reemit
    custom_handler(event)
  File "/var/lib/juju/agents/unit-postgresql-test-app-0/charm/./src/charm.py", line 289, in _on_clear_continuous_writes_action
    if self._connection_string is None:
  File "/var/lib/juju/agents/unit-postgresql-test-app-0/charm/./src/charm.py", line 259, in _connection_string
    data = list(self.first_database.fetch_relation_data().values())[0]
AttributeError: 'ApplicationCharm' object has no attribute 'first_database'
unit-postgresql-test-app-0: 02:44:17 ERROR unit.postgresql-test-app/0.juju-log Uncaught exception while in charm code:
Traceback (most recent call last):
  File "/var/lib/juju/agents/unit-postgresql-test-app-0/charm/./src/charm.py", line 538, in <module>
    main(ApplicationCharm)
  File "/var/lib/juju/agents/unit-postgresql-test-app-0/charm/venv/ops/main.py", line 551, in main
    manager.run()
  File "/var/lib/juju/agents/unit-postgresql-test-app-0/charm/venv/ops/main.py", line 530, in run
    self._emit()
  File "/var/lib/juju/agents/unit-postgresql-test-app-0/charm/venv/ops/main.py", line 519, in _emit
    _emit_charm_event(self.charm, self.dispatcher.event_name)
  File "/var/lib/juju/agents/unit-postgresql-test-app-0/charm/venv/ops/main.py", line 147, in _emit_charm_event
    event_to_emit.emit(*args, **kwargs)
  File "/var/lib/juju/agents/unit-postgresql-test-app-0/charm/venv/ops/framework.py", line 348, in emit
    framework._emit(event)
  File "/var/lib/juju/agents/unit-postgresql-test-app-0/charm/venv/ops/framework.py", line 860, in _emit
    self._reemit(event_path)
  File "/var/lib/juju/agents/unit-postgresql-test-app-0/charm/venv/ops/framework.py", line 950, in _reemit
    custom_handler(event)
  File "/var/lib/juju/agents/unit-postgresql-test-app-0/charm/./src/charm.py", line 289, in _on_clear_continuous_writes_action
    if self._connection_string is None:
  File "/var/lib/juju/agents/unit-postgresql-test-app-0/charm/./src/charm.py", line 259, in _connection_string
    data = list(self.first_database.fetch_relation_data().values())[0]
AttributeError: 'ApplicationCharm' object has no attribute 'first_database'
unit-postgresql-test-app-0: 02:44:21 ERROR unit.postgresql-test-app/0.juju-log Uncaught exception while in charm code:
Traceback (most recent call last):
  File "/var/lib/juju/agents/unit-postgresql-test-app-0/charm/./src/charm.py", line 538, in <module>
    main(ApplicationCharm)
  File "/var/lib/juju/agents/unit-postgresql-test-app-0/charm/venv/ops/main.py", line 551, in main
    manager.run()
  File "/var/lib/juju/agents/unit-postgresql-test-app-0/charm/venv/ops/main.py", line 530, in run
    self._emit()
  File "/var/lib/juju/agents/unit-postgresql-test-app-0/charm/venv/ops/main.py", line 519, in _emit
    _emit_charm_event(self.charm, self.dispatcher.event_name)
  File "/var/lib/juju/agents/unit-postgresql-test-app-0/charm/venv/ops/main.py", line 147, in _emit_charm_event
    event_to_emit.emit(*args, **kwargs)
  File "/var/lib/juju/agents/unit-postgresql-test-app-0/charm/venv/ops/framework.py", line 348, in emit
    framework._emit(event)
  File "/var/lib/juju/agents/unit-postgresql-test-app-0/charm/venv/ops/framework.py", line 860, in _emit
    self._reemit(event_path)
  File "/var/lib/juju/agents/unit-postgresql-test-app-0/charm/venv/ops/framework.py", line 950, in _reemit
    custom_handler(event)
  File "/var/lib/juju/agents/unit-postgresql-test-app-0/charm/./src/charm.py", line 289, in _on_clear_continuous_writes_action
    if self._connection_string is None:
  File "/var/lib/juju/agents/unit-postgresql-test-app-0/charm/./src/charm.py", line 259, in _connection_string
    data = list(self.first_database.fetch_relation_data().values())[0]
AttributeError: 'ApplicationCharm' object has no attribute 'first_database'
unit-postgresql-test-app-0: 02:44:25 ERROR unit.postgresql-test-app/0.juju-log Uncaught exception while in charm code:
Traceback (most recent call last):
  File "/var/lib/juju/agents/unit-postgresql-test-app-0/charm/./src/charm.py", line 538, in <module>
    main(ApplicationCharm)
  File "/var/lib/juju/agents/unit-postgresql-test-app-0/charm/venv/ops/main.py", line 551, in main
    manager.run()
  File "/var/lib/juju/agents/unit-postgresql-test-app-0/charm/venv/ops/main.py", line 530, in run
    self._emit()
  File "/var/lib/juju/agents/unit-postgresql-test-app-0/charm/venv/ops/main.py", line 519, in _emit
    _emit_charm_event(self.charm, self.dispatcher.event_name)
  File "/var/lib/juju/agents/unit-postgresql-test-app-0/charm/venv/ops/main.py", line 147, in _emit_charm_event
    event_to_emit.emit(*args, **kwargs)
  File "/var/lib/juju/agents/unit-postgresql-test-app-0/charm/venv/ops/framework.py", line 348, in emit
    framework._emit(event)
  File "/var/lib/juju/agents/unit-postgresql-test-app-0/charm/venv/ops/framework.py", line 860, in _emit
    self._reemit(event_path)
  File "/var/lib/juju/agents/unit-postgresql-test-app-0/charm/venv/ops/framework.py", line 950, in _reemit
    custom_handler(event)
  File "/var/lib/juju/agents/unit-postgresql-test-app-0/charm/./src/charm.py", line 289, in _on_clear_continuous_writes_action
    if self._connection_string is None:
  File "/var/lib/juju/agents/unit-postgresql-test-app-0/charm/./src/charm.py", line 259, in _connection_string
    data = list(self.first_database.fetch_relation_data().values())[0]
AttributeError: 'ApplicationCharm' object has no attribute 'first_database'
unit-postgresql-test-app-0: 02:44:29 ERROR unit.postgresql-test-app/0.juju-log Uncaught exception while in charm code:
Traceback (most recent call last):
  File "/var/lib/juju/agents/unit-postgresql-test-app-0/charm/./src/charm.py", line 538, in <module>
    main(ApplicationCharm)
  File "/var/lib/juju/agents/unit-postgresql-test-app-0/charm/venv/ops/main.py", line 551, in main
    manager.run()
  File "/var/lib/juju/agents/unit-postgresql-test-app-0/charm/venv/ops/main.py", line 530, in run
    self._emit()
  File "/var/lib/juju/agents/unit-postgresql-test-app-0/charm/venv/ops/main.py", line 519, in _emit
    _emit_charm_event(self.charm, self.dispatcher.event_name)
  File "/var/lib/juju/agents/unit-postgresql-test-app-0/charm/venv/ops/main.py", line 147, in _emit_charm_event
    event_to_emit.emit(*args, **kwargs)
  File "/var/lib/juju/agents/unit-postgresql-test-app-0/charm/venv/ops/framework.py", line 348, in emit
    framework._emit(event)
  File "/var/lib/juju/agents/unit-postgresql-test-app-0/charm/venv/ops/framework.py", line 860, in _emit
    self._reemit(event_path)
  File "/var/lib/juju/agents/unit-postgresql-test-app-0/charm/venv/ops/framework.py", line 950, in _reemit
    custom_handler(event)
  File "/var/lib/juju/agents/unit-postgresql-test-app-0/charm/./src/charm.py", line 289, in _on_clear_continuous_writes_action
    if self._connection_string is None:
  File "/var/lib/juju/agents/unit-postgresql-test-app-0/charm/./src/charm.py", line 259, in _connection_string
    data = list(self.first_database.fetch_relation_data().values())[0]
AttributeError: 'ApplicationCharm' object has no attribute 'first_database'
unit-postgresql-test-app-0: 02:44:33 ERROR unit.postgresql-test-app/0.juju-log Uncaught exception while in charm code:
Traceback (most recent call last):
  File "/var/lib/juju/agents/unit-postgresql-test-app-0/charm/./src/charm.py", line 538, in <module>
    main(ApplicationCharm)
  File "/var/lib/juju/agents/unit-postgresql-test-app-0/charm/venv/ops/main.py", line 551, in main
    manager.run()
  File "/var/lib/juju/agents/unit-postgresql-test-app-0/charm/venv/ops/main.py", line 530, in run
    self._emit()
  File "/var/lib/juju/agents/unit-postgresql-test-app-0/charm/venv/ops/main.py", line 519, in _emit
    _emit_charm_event(self.charm, self.dispatcher.event_name)
  File "/var/lib/juju/agents/unit-postgresql-test-app-0/charm/venv/ops/main.py", line 147, in _emit_charm_event
    event_to_emit.emit(*args, **kwargs)
  File "/var/lib/juju/agents/unit-postgresql-test-app-0/charm/venv/ops/framework.py", line 348, in emit
    framework._emit(event)
  File "/var/lib/juju/agents/unit-postgresql-test-app-0/charm/venv/ops/framework.py", line 860, in _emit
    self._reemit(event_path)
  File "/var/lib/juju/agents/unit-postgresql-test-app-0/charm/venv/ops/framework.py", line 950, in _reemit
    custom_handler(event)
  File "/var/lib/juju/agents/unit-postgresql-test-app-0/charm/./src/charm.py", line 289, in _on_clear_continuous_writes_action
    if self._connection_string is None:
  File "/var/lib/juju/agents/unit-postgresql-test-app-0/charm/./src/charm.py", line 259, in _connection_string
    data = list(self.first_database.fetch_relation_data().values())[0]
AttributeError: 'ApplicationCharm' object has no attribute 'first_database'
unit-postgresql-test-app-0: 02:44:37 ERROR unit.postgresql-test-app/0.juju-log Uncaught exception while in charm code:
Traceback (most recent call last):
  File "/var/lib/juju/agents/unit-postgresql-test-app-0/charm/./src/charm.py", line 538, in <module>
    main(ApplicationCharm)
  File "/var/lib/juju/agents/unit-postgresql-test-app-0/charm/venv/ops/main.py", line 551, in main
    manager.run()
  File "/var/lib/juju/agents/unit-postgresql-test-app-0/charm/venv/ops/main.py", line 530, in run
    self._emit()
  File "/var/lib/juju/agents/unit-postgresql-test-app-0/charm/venv/ops/main.py", line 519, in _emit
    _emit_charm_event(self.charm, self.dispatcher.event_name)
  File "/var/lib/juju/agents/unit-postgresql-test-app-0/charm/venv/ops/main.py", line 147, in _emit_charm_event
    event_to_emit.emit(*args, **kwargs)
  File "/var/lib/juju/agents/unit-postgresql-test-app-0/charm/venv/ops/framework.py", line 348, in emit
    framework._emit(event)
  File "/var/lib/juju/agents/unit-postgresql-test-app-0/charm/venv/ops/framework.py", line 860, in _emit
    self._reemit(event_path)
  File "/var/lib/juju/agents/unit-postgresql-test-app-0/charm/venv/ops/framework.py", line 950, in _reemit
    custom_handler(event)
  File "/var/lib/juju/agents/unit-postgresql-test-app-0/charm/./src/charm.py", line 289, in _on_clear_continuous_writes_action
    if self._connection_string is None:
  File "/var/lib/juju/agents/unit-postgresql-test-app-0/charm/./src/charm.py", line 259, in _connection_string
    data = list(self.first_database.fetch_relation_data().values())[0]
AttributeError: 'ApplicationCharm' object has no attribute 'first_database'
unit-postgresql-test-app-0: 02:44:41 ERROR unit.postgresql-test-app/0.juju-log Uncaught exception while in charm code:
Traceback (most recent call last):
  File "/var/lib/juju/agents/unit-postgresql-test-app-0/charm/./src/charm.py", line 538, in <module>
    main(ApplicationCharm)
  File "/var/lib/juju/agents/unit-postgresql-test-app-0/charm/venv/ops/main.py", line 551, in main
    manager.run()
  File "/var/lib/juju/agents/unit-postgresql-test-app-0/charm/venv/ops/main.py", line 530, in run
    self._emit()
  File "/var/lib/juju/agents/unit-postgresql-test-app-0/charm/venv/ops/main.py", line 519, in _emit
    _emit_charm_event(self.charm, self.dispatcher.event_name)
  File "/var/lib/juju/agents/unit-postgresql-test-app-0/charm/venv/ops/main.py", line 147, in _emit_charm_event
    event_to_emit.emit(*args, **kwargs)
  File "/var/lib/juju/agents/unit-postgresql-test-app-0/charm/venv/ops/framework.py", line 348, in emit
    framework._emit(event)
  File "/var/lib/juju/agents/unit-postgresql-test-app-0/charm/venv/ops/framework.py", line 860, in _emit
    self._reemit(event_path)
  File "/var/lib/juju/agents/unit-postgresql-test-app-0/charm/venv/ops/framework.py", line 950, in _reemit
    custom_handler(event)
  File "/var/lib/juju/agents/unit-postgresql-test-app-0/charm/./src/charm.py", line 289, in _on_clear_continuous_writes_action
    if self._connection_string is None:
  File "/var/lib/juju/agents/unit-postgresql-test-app-0/charm/./src/charm.py", line 259, in _connection_string
    data = list(self.first_database.fetch_relation_data().values())[0]
AttributeError: 'ApplicationCharm' object has no attribute 'first_database'

[32mINFO    [0m pytest_operator.plugin:plugin.py:947 Forgetting model main...